2019/05/30 14:34:00 [Info] msg: {"sequence":"1556329020432","symbol":"BTC-USDT","reason":"canceled","side":"sell","size":"0.0917","orderId":"5cefcda90bad452af7db22f6","price":"8729.10000000000000000000","time":"1559219639797859934","type":"done"}
2019/05/30 14:34:00 [Info] msg: {"sequence":"1556329020437","symbol":"BTC-USDT","reason":"canceled","side":"buy","size":"0.039","orderId":"5cefcdb44c06872c53322748","price":"8712.60000000000000000000","time":"1559219639913313990","type":"done"}
2019/05/30 14:34:00 [Info] msg: {"sequence":"1556329020438","symbol":"BTC-USDT","reason":"canceled","side":"sell","size":"0.148744","orderId":"5cefcda84c06872c1359ce30","price":"8730.60000000000000000000","time":"1559219639934183003","type":"done"}
2019/05/30 14:34:00 [Info] msg: {"sequence":"1556329020441","symbol":"BTC-USDT","reason":"canceled","side":"sell","size":"0.045857","orderId":"5cefcdb64c06872c1359d14a","price":"8724.10000000000000000000","time":"1559219640037890424","type":"done"}
2019/05/30 14:34:00 [Info] msg: {"sequence":"1556329020442","symbol":"BTC-USDT","reason":"canceled","side":"sell","size":"0.00059399","orderId":"5cefcd790bad452ac338beb1","price":"8743.90000000000000000000","time":"1559219640132141669","type":"done"}
2019/05/30 14:34:00 [Info] msg: {"sequence":"1556329020443","symbol":"BTC-USDT","reason":"canceled","side":"sell","size":"0.02083041","orderId":"5cefcdb15137b96bcaf937ca","price":"8725.90000000000000000000","time":"1559219640142700106","type":"done"}
2019/05/30 14:34:00 [Info] msg: {"sequence":"1556329020444","symbol":"BTC-USDT","reason":"canceled","side":"sell","size":"0.2653443","orderId":"5cefcdb6054b463a72e7a8fc","price":"8732.50000000000000000000","time":"1559219640194153080","type":"done"}
2019/05/30 14:34:00 [Info] msg: {"sequence":"1556329020445","symbol":"BTC-USDT","reason":"canceled","side":"sell","size":"0.4803219","orderId":"5cefcdb6054b463a72e7a8f9","price":"8732.40000000000000000000","time":"1559219640194238365","type":"done"}
2019/05/30 14:34:00 [Info] msg: {"sequence":"1556329020446","symbol":"BTC-USDT","reason":"canceled","side":"buy","size":"0.0054622","orderId":"5cefcdb589fc846350898fea","price":"8714.50000000000000000000","time":"1559219640204902396","type":"done"}
2019/05/30 14:34:00 [Info] msg: {"sequence":"1556329020461","symbol":"BTC-USDT","reason":"canceled","side":"buy","size":"0.45","orderId":"5cefcdb75137b96bcaf9390f","price":"8713.40000000000000000000","time":"1559219640341787344","type":"done"}
2019/05/30 14:34:00 [Info] msg: {"sequence":"1556329020462","symbol":"BTC-USDT","reason":"canceled","side":"buy","size":"0.2332143","orderId":"5cefcdb55137b96bcaf938b7","price":"8713.20000000000000000000","time":"1559219640341882459","type":"done"}
2019/05/30 14:34:00 [Info] msg: {"sequence":"1556329020463","symbol":"BTC-USDT","reason":"canceled","side":"buy","size":"0.0515808","orderId":"5cefcdb55137b96bcaf938a3","price":"8713.60000000000000000000","time":"1559219640392974914","type":"done"}
2019/05/30 14:34:00 [Info] msg: {"sequence":"1556329020464","symbol":"BTC-USDT","reason":"canceled","side":"buy","size":"0.0252432","orderId":"5cefcdb789fc846350899053","price":"8713.30000000000000000000","time":"1559219640413421037","type":"done"}
2019/05/30 14:34:00 [Info] msg: {"sequence":"1556329020465","symbol":"BTC-USDT","reason":"canceled","side":"buy","size":"0.0185733","orderId":"5cefcdb70bad452ac338cded","price":"8713.50000000000000000000","time":"1559219640434867435","type":"done"}
2019/05/30 14:34:00 [Info] msg: {"sequence":"1556329020468","symbol":"BTC-USDT","reason":"canceled","side":"sell","size":"0.00059399","orderId":"5cefcd785137b96bcaf92a27","price":"8739.60000000000000000000","time":"1559219640487318530","type":"done"}
2019/05/30 14:34:00 [Info] msg: {"sequence":"1556329020469","symbol":"BTC-USDT","reason":"canceled","side":"buy","size":"0.00057406","orderId":"5cefcd790bad452af7db16dd","price":"8709.90000000000000000000","time":"1559219640550402791","type":"done"}
2019/05/30 14:34:00 [Info] msg: {"sequence":"1556329020470","symbol":"BTC-USDT","reason":"canceled","side":"buy","size":"0.00057435","orderId":"5cefcd790bad452af7db16f2","price":"8705.50000000000000000000","time":"1559219640623478589","type":"done"}
2019/05/30 14:34:01 [Info] msg: {"sequence":"1556329020473","symbol":"BTC-USDT","reason":"canceled","side":"buy","size":"0.1125","orderId":"5cefcdb40bad452af7db25aa","price":"8717.00000000000000000000","time":"1559219640882641605","type":"done"}
2019/05/30 14:34:01 [Info] msg: {"sequence":"1556329020474","symbol":"BTC-USDT","reason":"canceled","side":"sell","size":"0.100005","orderId":"5cefcda8c788c671b05cff2b","price":"8731.70000000000000000000","time":"1559219640935088456","type":"done"}
2019/05/30 14:34:01 [Info] msg: {"sequence":"1556329020479","symbol":"BTC-USDT","reason":"canceled","side":"sell","size":"0.05","orderId":"5cefcdb75137b96bcaf9391f","price":"8724.70000000000000000000","time":"1559219641143599169","type":"done"}
2019/05/30 14:34:01 [Info] msg: {"sequence":"1556329020484","symbol":"BTC-USDT","reason":"canceled","side":"sell","size":"0.2653443","orderId":"5cefcdb54c06872c53322768","price":"8732.00000000000000000000","time":"1559219641290596471","type":"done"}
2019/05/30 14:34:01 [Info] msg: {"sequence":"1556329020485","symbol":"BTC-USDT","reason":"canceled","side":"sell","size":"0.4518","orderId":"5cefcdb85137b96bcaf93943","price":"8732.10000000000000000000","time":"1559219641301352450","type":"done"}
2019/05/30 14:34:01 [Info] msg: {"sequence":"1556329020486","symbol":"BTC-USDT","reason":"canceled","side":"sell","size":"0.0764532","orderId":"5cefcdb55137b96b7e1e2425","price":"8732.30000000000000000000","time":"1559219641301456285","type":"done"}
2019/05/30 14:34:01 [Info] msg: {"sequence":"1556329020487","symbol":"BTC-USDT","reason":"canceled","side":"buy","size":"1.0263852","orderId":"5cefcdb85137b96b7e1e24b6","price":"8715.00000000000000000000","time":"1559219641312094449","type":"done"}
2019/05/30 14:34:02 [Info] msg: {"sequence":"1556329020504","symbol":"BTC-USDT","reason":"canceled","side":"sell","size":"0.0154161","orderId":"5cefcdb9054b463a72e7a9b5","price":"8732.00000000000000000000","time":"1559219642282229499","type":"done"}
2019/05/30 14:34:02 [Info] msg: {"sequence":"1556329020505","symbol":"BTC-USDT","reason":"canceled","side":"buy","size":"0.1908261","orderId":"5cefcdb889fc846350899082","price":"8715.10000000000000000000","time":"1559219642282327663","type":"done"}
2019/05/30 14:34:02 [Info] msg: {"sequence":"1556329020506","symbol":"BTC-USDT","reason":"canceled","side":"sell","size":"0.0705744","orderId":"5cefcdb95137b96bcaf93999","price":"8732.70000000000000000000","time":"1559219642292909636","type":"done"}
2019/05/30 14:34:02 [Info] msg: {"sequence":"1556329020507","symbol":"BTC-USDT","reason":"canceled","side":"sell","size":"0.5565906","orderId":"5cefcdb95137b96b7e1e24f0","price":"8732.50000000000000000000","time":"1559219642303615384","type":"done"}
2019/05/30 14:34:02 [Info] msg: {"sequence":"1556329020508","symbol":"BTC-USDT","reason":"canceled","side":"sell","size":"0.00995346","orderId":"5cefcdb54c06872c5332276b","price":"8731.10000000000000000000","time":"1559219642334733250","type":"done"}
2019/05/30 14:34:02 [Info] msg: {"sequence":"1556329020509","symbol":"BTC-USDT","reason":"canceled","side":"sell","size":"0.0796437","orderId":"5cefcdb6cdaba439e54e7e11","price":"8732.20000000000000000000","time":"1559219642345483407","type":"done"}
2019/05/30 14:34:02 [Info] msg: {"sequence":"1556329020512","symbol":"BTC-USDT","reason":"canceled","side":"buy","size":"0.04059","orderId":"5cefcdb85137b96bcaf9396a","price":"8715.20000000000000000000","time":"1559219642355143008","type":"done"}
2019/05/30 14:34:02 [Info] msg: {"sequence":"1556329020513","symbol":"BTC-USDT","reason":"canceled","side":"buy","size":"0.00676286","orderId":"5cefcdb889fc846389b10729","price":"8716.10000000000000000000","time":"1559219642355222975","type":"done"}
2019/05/30 14:34:02 [Info] msg: {"sequence":"1556329020516","symbol":"BTC-USDT","reason":"canceled","side":"buy","size":"0.0899","orderId":"5cefcdb6cdaba43a1e1486a9","price":"8710.30000000000000000000","time":"1559219642377055411","type":"done"}
2019/05/30 14:34:02 [Info] msg: {"sequence":"1556329020523","symbol":"BTC-USDT","reason":"canceled","side":"sell","size":"0.0705744","orderId":"5cefcdb889fc846389b10726","price":"8732.40000000000000000000","time":"1559219642469423540","type":"done"}
2019/05/30 14:34:02 [Info] msg: {"sequence":"1556329020524","symbol":"BTC-USDT","reason":"canceled","side":"buy","size":"0.234","orderId":"5cefcdb9cdaba43a1e14874e","price":"8715.00000000000000000000","time":"1559219642469508585","type":"done"}
2019/05/30 14:34:02 [Info] msg: {"sequence":"1556329020527","symbol":"BTC-USDT","reason":"canceled","side":"buy","size":"0.2637","orderId":"5cefcdb85137b96b7e1e24b5","price":"8714.80000000000000000000","time":"1559219642562821391","type":"done"}
2019/05/30 14:34:02 [Info] msg: {"sequence":"1556329020536","symbol":"BTC-USDT","reason":"canceled","side":"buy","size":"0.2338146","orderId":"5cefcdb8c788c671eab3c755","price":"8714.90000000000000000000","time":"1559219642625010809","type":"done"}
2019/05/30 14:34:03 [Info] msg: {"sequence":"1556329020549","symbol":"BTC-USDT","reason":"canceled","side":"sell","size":"0.5565906","orderId":"5cefcdbac788c671eab3c7cb","price":"8732.90000000000000000000","time":"1559219643210427293","type":"done"}
2019/05/30 14:34:03 [Info] msg: {"sequence":"1556329020550","symbol":"BTC-USDT","reason":"canceled","side":"sell","size":"0.0705744","orderId":"5cefcdbac788c671b05d0304","price":"8733.10000000000000000000","time":"1559219643230669045","type":"done"}
2019/05/30 14:34:03 [Info] msg: {"sequence":"1556329020551","symbol":"BTC-USDT","reason":"canceled","side":"buy","size":"0.225","orderId":"5cefcdbacdaba439e54e7f13","price":"8715.70000000000000000000","time":"1559219643230753709","type":"done"}
2019/05/30 14:34:03 [Info] msg: {"sequence":"1556329020552","symbol":"BTC-USDT","reason":"canceled","side":"sell","size":"0.2653443","orderId":"5cefcdbacdaba439e54e7efb","price":"8733.20000000000000000000","time":"1559219643241352282","type":"done"}
2019/05/30 14:34:03 [Info] msg: {"sequence":"1556329020553","symbol":"BTC-USDT","reason":"canceled","side":"buy","size":"1.25901","orderId":"5cefcdba5137b96bcaf939e1","price":"8715.50000000000000000000","time":"1559219643241441927","type":"done"}
2019/05/30 14:34:03 [Info] msg: {"sequence":"1556329020564","symbol":"BTC-USDT","reason":"canceled","side":"sell","size":"0.228733","orderId":"5cefcda80bad452af7db22a4","price":"8733.40000000000000000000","time":"1559219643386851313","type":"done"}
2019/05/30 14:34:03 [Info] msg: {"sequence":"1556329020565","symbol":"BTC-USDT","reason":"canceled","side":"sell","size":"0.148749","orderId":"5cefcdb90bad452ac338ce74","price":"8730.20000000000000000000","time":"1559219643542984712","type":"done"}
2019/05/30 14:34:04 [Info] msg: {"sequence":"1556329020566","symbol":"BTC-USDT","reason":"canceled","side":"sell","size":"0.0001","orderId":"5cefcdb50bad452af7db25c8","price":"8720.00000000000000000000","time":"1559219643936745230","type":"done"}
2019/05/30 14:34:04 [Info] msg: {"sequence":"1556329020567","symbol":"BTC-USDT","reason":"canceled","side":"sell","size":"0.0001","orderId":"5cefcdb6054b463aaf909a49","price":"8719.90000000000000000000","time":"1559219643936853855","type":"done"}
2019/05/30 14:34:04 [Info] msg: {"sequence":"1556329020568","symbol":"BTC-USDT","reason":"canceled","side":"buy","size":"0.0801","orderId":"5cefcdba054b463aaf909b32","price":"8715.60000000000000000000","time":"1559219644129935156","type":"done"}
2019/05/30 14:34:04 [Info] msg: {"sequence":"1556329020569","symbol":"BTC-USDT","reason":"canceled","side":"buy","size":"0.1681272","orderId":"5cefcdbbcdaba43a1e1487bb","price":"8715.70000000000000000000","time":"1559219644130045503","type":"done"}
2019/05/30 14:34:04 [Info] msg: {"sequence":"1556329020574","symbol":"BTC-USDT","reason":"canceled","side":"sell","size":"0.02083041","orderId":"5cefcdb789fc846389b106ed","price":"8725.70000000000000000000","time":"1559219644192103863","type":"done"}
2019/05/30 14:34:05 [Info] msg: {"sequence":"1556329020579","symbol":"BTC-USDT","reason":"canceled","side":"buy","size":"0.039","orderId":"5cefcdb74c06872c1359d187","price":"8713.60000000000000000000","time":"1559219645004009724","type":"done"}
2019/05/30 14:34:05 [Info] msg: {"sequence":"1556329020580","symbol":"BTC-USDT","reason":"canceled","side":"buy","size":"0.078719","orderId":"5cefcdb74c06872c1359d182","price":"8717.50000000000000000000","time":"1559219645035145741","type":"done"}
2019/05/30 14:34:05 [Info] msg: {"sequence":"1556329020581","symbol":"BTC-USDT","reason":"canceled","side":"sell","size":"0.2653443","orderId":"5cefcdbb5137b96bcaf93a13","price":"8732.60000000000000000000","time":"1559219645035228598","type":"done"}
2019/05/30 14:34:05 [Info] msg: {"sequence":"1556329020582","symbol":"BTC-USDT","reason":"canceled","side":"sell","size":"0.00718795","orderId":"5cefcdba89fc846389b10798","price":"8731.60000000000000000000","time":"1559219645035252560","type":"done"}
2019/05/30 14:34:05 [Info] msg: {"sequence":"1556329020583","symbol":"BTC-USDT","reason":"canceled","side":"sell","size":"0.0796437","orderId":"5cefcdba054b463a72e7a9e8","price":"8732.80000000000000000000","time":"1559219645045581185","type":"done"}
2019/05/30 14:34:05 [Info] msg: {"sequence":"1556329020584","symbol":"BTC-USDT","reason":"canceled","side":"sell","size":"0.0675","orderId":"5cefcdbbc788c671b05d0342","price":"8732.90000000000000000000","time":"1559219645045650086","type":"done"}
2019/05/30 14:34:05 [Info] msg: {"sequence":"1556329020585","symbol":"BTC-USDT","reason":"canceled","side":"sell","size":"0.0154161","orderId":"5cefcdbacdaba439e54e7f0c","price":"8732.50000000000000000000","time":"1559219645045666059","type":"done"}
2019/05/30 14:34:05 [Info] msg: {"sequence":"1556329020586","symbol":"BTC-USDT","reason":"canceled","side":"sell","size":"0.6190785","orderId":"5cefcdbb4c06872c533228b6","price":"8732.70000000000000000000","time":"1559219645045681088","type":"done"}
2019/05/30 14:34:05 [Info] msg: {"sequence":"1556329020587","symbol":"BTC-USDT","reason":"canceled","side":"buy","size":"0.00501293","orderId":"5cefcdba0bad452af7db26fa","price":"8716.80000000000000000000","time":"1559219645045693227","type":"done"}
2019/05/30 14:34:05 [Info] msg: {"sequence":"1556329020588","symbol":"BTC-USDT","reason":"canceled","side":"buy","size":"0.0443592","orderId":"5cefcdbb054b463a72e7aa22","price":"8715.50000000000000000000","time":"1559219645056005696","type":"done"}
2019/05/30 14:34:05 [Info] msg: {"sequence":"1556329020589","symbol":"BTC-USDT","reason":"canceled","side":"buy","size":"0.0252432","orderId":"5cefcdbc5137b96b7e1e2599","price":"8715.60000000000000000000","time":"1559219645056071512","type":"done"}
2019/05/30 14:34:05 [Info] msg: {"sequence":"1556329020598","symbol":"BTC-USDT","reason":"canceled","side":"sell","size":"0.05","orderId":"5cefcdb9c788c671eab3c7a2","price":"8725.60000000000000000000","time":"1559219645123711899","type":"done"}
2019/05/30 14:34:05 [Info] msg: {"sequence":"1556329020607","symbol":"BTC-USDT","reason":"canceled","side":"buy","size":"0.206355","orderId":"5cefcdb7cdaba439e54e7e7e","price":"8717.30000000000000000000","time":"1559219645186294831","type":"done"}
2019/05/30 14:34:05 [Info] msg: {"sequence":"1556329020614","symbol":"BTC-USDT","reason":"canceled","side":"buy","size":"0.1228","orderId":"5cefcdb40bad452ac338cd6e","price":"8717.00000000000000000000","time":"1559219645541139455","type":"done"}
2019/05/30 14:34:05 [Info] msg: {"sequence":"1556329020619","symbol":"BTC-USDT","reason":"canceled","side":"buy","size":"0.039","orderId":"5cefcdbc4c06872c1359d2c1","price":"8714.90000000000000000000","time":"1559219645656000772","type":"done"}
2019/05/30 14:34:06 [Info] msg: {"sequence":"1556329020620","symbol":"BTC-USDT","reason":"canceled","side":"buy","size":"1.1134863","orderId":"5cefcdba5137b96bcaf939d5","price":"8715.90000000000000000000","time":"1559219645965744520","type":"done"}
2019/05/30 14:34:06 [Info] msg: {"sequence":"1556329020621","symbol":"BTC-USDT","reason":"canceled","side":"buy","size":"0.00809679","orderId":"5cefcdbd89fc84635089919f","price":"8717.00000000000000000000","time":"1559219645965856206","type":"done"}
2019/05/30 14:34:06 [Info] msg: {"sequence":"1556329020622","symbol":"BTC-USDT","reason":"canceled","side":"buy","size":"0.0185733","orderId":"5cefcdbc0bad452ac338cf01","price":"8715.70000000000000000000","time":"1559219645965878119","type":"done"}
2019/05/30 14:34:06 [Info] msg: {"sequence":"1556329020623","symbol":"BTC-USDT","reason":"canceled","side":"sell","size":"0.1415682","orderId":"5cefcdbdc788c671b05d03bf","price":"8735.30000000000000000000","time":"1559219645976373004","type":"done"}
2019/05/30 14:34:06 [Info] msg: {"sequence":"1556329020624","symbol":"BTC-USDT","reason":"canceled","side":"sell","size":"0.2298744","orderId":"5cefcdbd5137b96bcaf93a92","price":"8735.40000000000000000000","time":"1559219645976457684","type":"done"}
2019/05/30 14:34:06 [Info] msg: {"sequence":"1556329020625","symbol":"BTC-USDT","reason":"canceled","side":"sell","size":"3.2801418","orderId":"5cefcdbdc788c671b05d03b8","price":"8735.00000000000000000000","time":"1559219645986097715","type":"done"}
2019/05/30 14:34:06 [Info] msg: {"sequence":"1556329020628","symbol":"BTC-USDT","reason":"canceled","side":"buy","size":"0.229263","orderId":"5cefcdb8c788c671eab3c78d","price":"8718.20000000000000000000","time":"1559219646031691761","type":"done"}
2019/05/30 14:34:06 [Info] msg: {"sequence":"1556329020633","symbol":"BTC-USDT","reason":"canceled","side":"buy","size":"0.0899","orderId":"5cefcdbacdaba43a1e148778","price":"8709.60000000000000000000","time":"1559219646076116761","type":"done"}
2019/05/30 14:34:06 [Info] msg: {"sequence":"1556329020636","symbol":"BTC-USDT","reason":"canceled","side":"sell","size":"0.0001","orderId":"5cefcdbc4c06872c53322900","price":"8722.00000000000000000000","time":"1559219646076202633","type":"done"}
2019/05/30 14:34:06 [Info] msg: {"sequence":"1556329020641","symbol":"BTC-USDT","reason":"canceled","side":"sell","size":"0.05","orderId":"5cefcdbdc788c671eab3c89e","price":"8727.10000000000000000000","time":"1559219646117536283","type":"done"}
2019/05/30 14:34:06 [Info] msg: {"sequence":"1556329020644","symbol":"BTC-USDT","reason":"canceled","side":"sell","size":"0.02083041","orderId":"5cefcd825137b96bcaf92c48","price":"8727.20000000000000000000","time":"1559219646254135019","type":"done"}
2019/05/30 14:34:06 [Info] msg: {"sequence":"1556329020653","symbol":"BTC-USDT","reason":"canceled","side":"buy","size":"0.229283","orderId":"5cefcdb8c788c671b05d02c1","price":"8713.60000000000000000000","time":"1559219646564399995","type":"done"}
2019/05/30 14:34:07 [Info] msg: {"sequence":"1556329020656","symbol":"BTC-USDT","reason":"canceled","side":"sell","size":"0.45","orderId":"5cefcdbd0bad452ac338cf48","price":"8735.10000000000000000000","time":"1559219646889456328","type":"done"}
2019/05/30 14:34:07 [Info] msg: {"sequence":"1556329020657","symbol":"BTC-USDT","reason":"canceled","side":"sell","size":"0.6190785","orderId":"5cefcdbe5137b96bcaf93ae1","price":"8735.00000000000000000000","time":"1559219646889557411","type":"done"}
2019/05/30 14:34:07 [Info] msg: {"sequence":"1556329020658","symbol":"BTC-USDT","reason":"canceled","side":"buy","size":"0.0050191","orderId":"5cefcdbe89fc8463508991e3","price":"8717.10000000000000000000","time":"1559219646889576402","type":"done"}
2019/05/30 14:34:07 [Info] msg: {"sequence":"1556329020659","symbol":"BTC-USDT","reason":"canceled","side":"buy","size":"1.103841","orderId":"5cefcdbdc788c671eab3c890","price":"8716.00000000000000000000","time":"1559219646889598668","type":"done"}
2019/05/30 14:34:07 [Info] msg: {"sequence":"1556329020668","symbol":"BTC-USDT","reason":"canceled","side":"sell","size":"0.0001","orderId":"5cefcdbd5137b96bcaf93abb","price":"8721.90000000000000000000","time":"1559219647128062095","type":"done"}
2019/05/30 14:34:07 [Info] msg: {"sequence":"1556329020671","symbol":"BTC-USDT","reason":"canceled","side":"sell","size":"0.05","orderId":"5cefcdbe0bad452af7db27fa","price":"8727.10000000000000000000","time":"1559219647161483411","type":"done"}
2019/05/30 14:34:07 [Info] msg: {"sequence":"1556329020674","symbol":"BTC-USDT","reason":"canceled","side":"sell","size":"0.0001","orderId":"5cefcdbe0bad452ac338cf96","price":"8721.70000000000000000000","time":"1559219647672659111","type":"done"}
2019/05/30 14:34:08 [Info] msg: {"sequence":"1556329020677","symbol":"BTC-USDT","reason":"canceled","side":"sell","size":"0.134595","orderId":"5cefcdbd4c06872c1359d2ca","price":"8734.80000000000000000000","time":"1559219647887371396","type":"done"}
2019/05/30 14:34:08 [Info] msg: {"sequence":"1556329020686","symbol":"BTC-USDT","reason":"canceled","side":"buy","size":"1.1202012","orderId":"5cefcdbd5137b96bcaf93add","price":"8716.20000000000000000000","time":"1559219647949500703","type":"done"}
2019/05/30 14:34:08 [Info] msg: {"sequence":"1556329020687","symbol":"BTC-USDT","reason":"canceled","side":"buy","size":"0.0443457","orderId":"5cefcdbd89fc846389b10819","price":"8716.10000000000000000000","time":"1559219647958986850","type":"done"}
2019/05/30 14:34:08 [Info] msg: {"sequence":"1556329020688","symbol":"BTC-USDT","reason":"canceled","side":"buy","size":"0.9343386","orderId":"5cefcdbe4c06872c1359d34b","price":"8715.70000000000000000000","time":"1559219647959062995","type":"done"}
2019/05/30 14:34:08 [Info] msg: {"sequence":"1556329020695","symbol":"BTC-USDT","reason":"canceled","side":"sell","size":"0.00059399","orderId":"5cefcdbac788c671eab3c7c0","price":"8743.40000000000000000000","time":"1559219648606849002","type":"done"}
2019/05/30 14:34:08 [Info] msg: {"sequence":"1556329020696","symbol":"BTC-USDT","reason":"canceled","side":"buy","size":"0.00057438","orderId":"5cefcdba5137b96bcaf939c7","price":"8705.00000000000000000000","time":"1559219648670207819","type":"done"}
2019/05/30 14:34:08 [Info] msg: {"sequence":"1556329020699","symbol":"BTC-USDT","reason":"canceled","side":"buy","size":"0.039","orderId":"5cefcdbd054b463aaf909bf5","price":"8715.50000000000000000000","time":"1559219648836191873","type":"done"}
2019/05/30 14:34:09 [Info] msg: {"sequence":"1556329020700","symbol":"BTC-USDT","reason":"canceled","side":"sell","size":"0.00059399","orderId":"5cefcdbac788c671b05d030b","price":"8739.00000000000000000000","time":"1559219648877954528","type":"done"}
2019/05/30 14:34:09 [Info] msg: {"sequence":"1556329020701","symbol":"BTC-USDT","reason":"canceled","side":"buy","size":"0.00057409","orderId":"5cefcdba89fc846389b1079c","price":"8709.40000000000000000000","time":"1559219648951637041","type":"done"}
2019/05/30 14:34:09 [Info] msg: {"sequence":"1556329020702","symbol":"BTC-USDT","reason":"canceled","side":"sell","size":"0.05","orderId":"5cefcdbf0bad452af7db282c","price":"8726.90000000000000000000","time":"1559219649090749570","type":"done"}
2019/05/30 14:34:09 [Info] msg: {"sequence":"1556329020703","symbol":"BTC-USDT","reason":"canceled","side":"buy","size":"0.206292","orderId":"5cefcdbe4c06872c1359d322","price":"8720.00000000000000000000","time":"1559219649185059122","type":"done"}
2019/05/30 14:34:09 [Info] msg: {"sequence":"1556329020704","symbol":"BTC-USDT","reason":"canceled","side":"sell","size":"0.0001","orderId":"5cefcdc00bad452ac338cfe4","price":"8721.40000000000000000000","time":"1559219649228583257","type":"done"}
2019/05/30 14:34:09 [Info] msg: {"sequence":"1556329020705","symbol":"BTC-USDT","reason":"canceled","side":"sell","size":"0.0001","orderId":"5cefcdbf5137b96b7e1e264f","price":"8721.60000000000000000000","time":"1559219649228681856","type":"done"}
2019/05/30 14:34:09 [Info] msg: {"sequence":"1556329020710","symbol":"BTC-USDT","reason":"canceled","side":"buy","size":"0.039","orderId":"5cefcdc0054b463aaf909cad","price":"8717.20000000000000000000","time":"1559219649474141164","type":"done"}
2019/05/30 14:34:09 [Info] msg: {"sequence":"1556329020711","symbol":"BTC-USDT","reason":"canceled","side":"buy","size":"0.078695","orderId":"5cefcdbe4c06872c1359d33c","price":"8720.20000000000000000000","time":"1559219649632206912","type":"done"}
2019/05/30 14:34:09 [Info] msg: {"sequence":"1556329020718","symbol":"BTC-USDT","reason":"canceled","side":"buy","size":"0.229213","orderId":"5cefcdbf89fc846389b10886","price":"8720.10000000000000000000","time":"1559219649778729779","type":"done"}
2019/05/30 14:34:09 [Info] msg: {"sequence":"1556329020719","symbol":"BTC-USDT","reason":"canceled","side":"sell","size":"0.00994641","orderId":"5cefcdbd4c06872c5332291d","price":"8733.90000000000000000000","time":"1559219649778820691","type":"done"}
2019/05/30 14:34:09 [Info] msg: {"sequence":"1556329020720","symbol":"BTC-USDT","reason":"canceled","side":"sell","size":"0.0479331","orderId":"5cefcdbfc788c671eab3c932","price":"8734.80000000000000000000","time":"1559219649789889204","type":"done"}
2019/05/30 14:34:09 [Info] msg: {"sequence":"1556329020721","symbol":"BTC-USDT","reason":"canceled","side":"sell","size":"0.0479331","orderId":"5cefcdbd054b463aaf909c0e","price":"8734.90000000000000000000","time":"1559219649789963900","type":"done"}
2019/05/30 14:34:09 [Info] msg: {"sequence":"1556329020722","symbol":"BTC-USDT","reason":"canceled","side":"sell","size":"0.0675","orderId":"5cefcdbec788c671b05d0420","price":"8735.00000000000000000000","time":"1559219649789981568","type":"done"}
2019/05/30 14:34:09 [Info] msg: {"sequence":"1556329020723","symbol":"BTC-USDT","reason":"canceled","side":"sell","size":"0.2307006","orderId":"5cefcdbec788c671b05d0423","price":"8735.10000000000000000000","time":"1559219649789996121","type":"done"}
2019/05/30 14:34:09 [Info] msg: {"sequence":"1556329020724","symbol":"BTC-USDT","reason":"canceled","side":"buy","size":"0.00686817","orderId":"5cefcdbe5137b96b7e1e2630","price":"8717.10000000000000000000","time":"1559219649790008227","type":"done"}
2019/05/30 14:34:09 [Info] msg: {"sequence":"1556329020725","symbol":"BTC-USDT","reason":"canceled","side":"buy","size":"0.0185733","orderId":"5cefcdbf5137b96bcaf93b3c","price":"8716.20000000000000000000","time":"1559219649800213278","type":"done"}
2019/05/30 14:34:09 [Info] msg: {"sequence":"1556329020726","symbol":"BTC-USDT","reason":"canceled","side":"buy","size":"0.039","orderId":"5cefcdc189fc846389b1090e","price":"8716.30000000000000000000","time":"1559219649800288445","type":"done"}
2019/05/30 14:34:09 [Info] msg: {"sequence":"1556329020727","symbol":"BTC-USDT","reason":"canceled","side":"buy","size":"0.0252432","orderId":"5cefcdbf5137b96bcaf93b39","price":"8716.10000000000000000000","time":"1559219649810801724","type":"done"}
2019/05/30 14:34:09 [Info] msg: {"sequence":"1556329020728","symbol":"BTC-USDT","reason":"canceled","side":"sell","size":"0.0675","orderId":"5cefcdbec788c671eab3c8c6","price":"8735.20000000000000000000","time":"1559219649810872149","type":"done"}
2019/05/30 14:34:09 [Info] msg: {"sequence":"1556329020729","symbol":"BTC-USDT","reason":"canceled","side":"buy","size":"0.2907963","orderId":"5cefcdbecdaba439e54e7fe4","price":"8715.90000000000000000000","time":"1559219649810890906","type":"done"}
2019/05/30 14:34:09 [Info] msg: {"sequence":"1556329020732","symbol":"BTC-USDT","reason":"canceled","side":"buy","size":"0.2005029","orderId":"5cefcdbfc788c671b05d045c","price":"8716.00000000000000000000","time":"1559219649822036987","type":"done"}
2019/05/30 14:34:09 [Info] msg: {"sequence":"1556329020733","symbol":"BTC-USDT","reason":"canceled","side":"buy","size":"0.0515808","orderId":"5cefcdba0bad452af7db26f7","price":"8715.80000000000000000000","time":"1559219649822064353","type":"done"}
2019/05/30 14:34:10 [Info] msg: {"sequence":"1556329020762","symbol":"BTC-USDT","reason":"canceled","side":"buy","size":"0.0899","orderId":"5cefcdbe89fc8463508991de","price":"8709.80000000000000000000","time":"1559219650092665148","type":"done"}
2019/05/30 14:34:10 [Info] msg: {"sequence":"1556329020767","symbol":"BTC-USDT","reason":"canceled","side":"sell","size":"0.0001","orderId":"5cefcdc189fc8463508992c8","price":"8722.00000000000000000000","time":"1559219650273727655","type":"done"}
2019/05/30 14:34:10 [Info] msg: {"sequence":"1556329020774","symbol":"BTC-USDT","reason":"canceled","side":"sell","size":"0.00963449","orderId":"5cefcdc1c788c671eab3c9b9","price":"8735.50000000000000000000","time":"1559219650797292579","type":"done"}
2019/05/30 14:34:10 [Info] msg: {"sequence":"1556329020775","symbol":"BTC-USDT","reason":"canceled","side":"sell","size":"0.83205","orderId":"5cefcdc189fc8463508992d0","price":"8736.50000000000000000000","time":"1559219650797412586","type":"done"}
2019/05/30 14:34:10 [Info] msg: {"sequence":"1556329020776","symbol":"BTC-USDT","reason":"canceled","side":"sell","size":"1.0602","orderId":"5cefcdc1cdaba43a1e14894a","price":"8736.60000000000000000000","time":"1559219650797435252","type":"done"}
2019/05/30 14:34:10 [Info] msg: {"sequence":"1556329020777","symbol":"BTC-USDT","reason":"canceled","side":"sell","size":"0.5565906","orderId":"5cefcdc1054b463a72e7aba3","price":"8736.70000000000000000000","time":"1559219650807884273","type":"done"}
2019/05/30 14:34:10 [Info] msg: {"sequence":"1556329020778","symbol":"BTC-USDT","reason":"canceled","side":"sell","size":"0.0001","orderId":"5cefcdc1054b463aaf909ce6","price":"8721.90000000000000000000","time":"1559219650807975043","type":"done"}
2019/05/30 14:34:10 [Info] msg: {"sequence":"1556329020783","symbol":"BTC-USDT","reason":"canceled","side":"buy","size":"0.1228","orderId":"5cefcdc10bad452ac338d038","price":"8717.00000000000000000000","time":"1559219650831523094","type":"done"}
2019/05/30 14:34:10 [Info] msg: {"sequence":"1556329020790","symbol":"BTC-USDT","reason":"canceled","side":"buy","size":"0.9783054","orderId":"5cefcdc10bad452ac338d04c","price":"8719.50000000000000000000","time":"1559219650831830757","type":"done"}
2019/05/30 14:34:10 [Info] msg: {"sequence":"1556329020791","symbol":"BTC-USDT","reason":"canceled","side":"buy","size":"0.0968058","orderId":"5cefcdc1c788c671b05d04bc","price":"8719.70000000000000000000","time":"1559219650842056571","type":"done"}
2019/05/30 14:34:11 [Info] msg: {"sequence":"1556329020792","symbol":"BTC-USDT","reason":"canceled","side":"buy","size":"0.1657809","orderId":"5cefcdc189fc846389b10936","price":"8719.60000000000000000000","time":"1559219650842133736","type":"done"}
2019/05/30 14:34:11 [Info] msg: {"sequence":"1556329020797","symbol":"BTC-USDT","reason":"canceled","side":"buy","size":"0.1125","orderId":"5cefcdb9054b463aaf909af0","price":"8717.20000000000000000000","time":"1559219650874385052","type":"done"}
2019/05/30 14:34:11 [Info] msg: {"sequence":"1556329020812","symbol":"BTC-USDT","reason":"canceled","side":"buy","size":"0.00882007","orderId":"5cefcdc10bad452ac338d040","price":"8720.90000000000000000000","time":"1559219650967937511","type":"done"}
2019/05/30 14:34:11 [Info] msg: {"sequence":"1556329020813","symbol":"BTC-USDT","reason":"canceled","side":"sell","size":"0.0479331","orderId":"5cefcdc1cdaba43a1e14894d","price":"8736.80000000000000000000","time":"1559219650968018401","type":"done"}
2019/05/30 14:34:11 [Info] msg: {"sequence":"1556329020814","symbol":"BTC-USDT","reason":"canceled","side":"sell","size":"2.6493156","orderId":"5cefcdc1054b463a72e7ab95","price":"8736.40000000000000000000","time":"1559219650978590131","type":"done"}
2019/05/30 14:34:11 [Info] msg: {"sequence":"1556329020815","symbol":"BTC-USDT","reason":"canceled","side":"buy","size":"3.2501826","orderId":"5cefcdc14c06872c53322a42","price":"8720.00000000000000000000","time":"1559219651021571718","type":"done"}
2019/05/30 14:34:11 [Info] msg: {"sequence":"1556329020816","symbol":"BTC-USDT","reason":"canceled","side":"buy","size":"1.6432344","orderId":"5cefcdc189fc8463508992da","price":"8719.80000000000000000000","time":"1559219651021653914","type":"done"}
2019/05/30 14:34:11 [Info] msg: {"sequence":"1556329020817","symbol":"BTC-USDT","reason":"canceled","side":"buy","size":"0.40079","orderId":"5cefcda85137b96bcaf935e2","price":"8718.70000000000000000000","time":"1559219651185721744","type":"done"}
2019/05/30 14:34:11 [Info] msg: {"sequence":"1556329020826","symbol":"BTC-USDT","reason":"canceled","side":"buy","size":"0.039","orderId":"5cefcdc189fc846389b1091e","price":"8714.90000000000000000000","time":"1559219651398594820","type":"done"}
2019/05/30 14:34:11 [Info] msg: {"sequence":"1556329020827","symbol":"BTC-USDT","reason":"canceled","side":"sell","size":"0.099988","orderId":"5cefcdc14c06872c53322a35","price":"8733.10000000000000000000","time":"1559219651420538777","type":"done"}
2019/05/30 14:34:11 [Info] msg: {"sequence":"1556329020834","symbol":"BTC-USDT","reason":"canceled","side":"sell","size":"0.228695","orderId":"5cefcdc20bad452af7db28e1","price":"8734.80000000000000000000","time":"1559219651622351406","type":"done"}
2019/05/30 14:34:12 [Info] msg: {"sequence":"1556329020835","symbol":"BTC-USDT","reason":"canceled","side":"sell","size":"0.45","orderId":"5cefcdc25137b96b7e1e270e","price":"8735.00000000000000000000","time":"1559219651923660247","type":"done"}
2019/05/30 14:34:12 [Info] msg: {"sequence":"1556329020836","symbol":"BTC-USDT","reason":"canceled","side":"sell","size":"0.0479331","orderId":"5cefcdc2c788c671b05d04fb","price":"8735.20000000000000000000","time":"1559219651934401050","type":"done"}
2019/05/30 14:34:12 [Info] msg: {"sequence":"1556329020837","symbol":"BTC-USDT","reason":"canceled","side":"buy","size":"0.45","orderId":"5cefcdc24c06872c53322a7c","price":"8716.20000000000000000000","time":"1559219651934488584","type":"done"}
2019/05/30 14:34:12 [Info] msg: {"sequence":"1556329020838","symbol":"BTC-USDT","reason":"canceled","side":"buy","size":"0.7407963","orderId":"5cefcdc24c06872c1359d422","price":"8716.10000000000000000000","time":"1559219651944001605","type":"done"}
2019/05/30 14:34:12 [Info] msg: {"sequence":"1556329020839","symbol":"BTC-USDT","reason":"canceled","side":"buy","size":"1.24632","orderId":"5cefcdc2054b463aaf909d28","price":"8716.30000000000000000000","time":"1559219651944077084","type":"done"}
2019/05/30 14:34:12 [Info] msg: {"sequence":"1556329020840","symbol":"BTC-USDT","reason":"canceled","side":"sell","size":"3.6771534","orderId":"5cefcdc2cdaba43a1e148988","price":"8734.90000000000000000000","time":"1559219651944096622","type":"done"}
2019/05/30 14:34:12 [Info] msg: {"sequence":"1556329020841","symbol":"BTC-USDT","reason":"canceled","side":"buy","size":"0.00502209","orderId":"5cefcdc24c06872c1359d41b","price":"8716.50000000000000000000","time":"1559219651944113316","type":"done"}
2019/05/30 14:34:12 [Info] msg: {"sequence":"1556329020842","symbol":"BTC-USDT","reason":"canceled","side":"sell","size":"0.83205","orderId":"5cefcdc2c788c671eab3ca0e","price":"8734.70000000000000000000","time":"1559219651954608754","type":"done"}
2019/05/30 14:34:12 [Info] msg: {"sequence":"1556329020843","symbol":"BTC-USDT","reason":"canceled","side":"buy","size":"0.225","orderId":"5cefcdc25137b96bcaf93beb","price":"8716.40000000000000000000","time":"1559219651954679913","type":"done"}
2019/05/30 14:34:12 [Info] msg: {"sequence":"1556329020862","symbol":"BTC-USDT","reason":"canceled","side":"buy","size":"0.1228","orderId":"5cefcdc30bad452ac338d09f","price":"8719.20000000000000000000","time":"1559219652482512406","type":"done"}
2019/05/30 14:34:12 [Info] msg: {"sequence":"1556329020863","symbol":"BTC-USDT","reason":"canceled","side":"buy","size":"0.1125","orderId":"5cefcdc3054b463a72e7abf9","price":"8719.20000000000000000000","time":"1559219652493238984","type":"done"}
2019/05/30 14:34:12 [Info] msg: {"sequence":"1556329020864","symbol":"BTC-USDT","reason":"canceled","side":"sell","size":"0.0001","orderId":"5cefcdc2054b463a72e7abd5","price":"8721.80000000000000000000","time":"1559219652502932071","type":"done"}
2019/05/30 14:34:12 [Info] msg: {"sequence":"1556329020865","symbol":"BTC-USDT","reason":"canceled","side":"sell","size":"0.86310902","orderId":"5cefcda74c06872c53322476","price":"8834.80000000000000000000","time":"1559219652744384319","type":"done"}
2019/05/30 14:34:13 [Info] msg: {"sequence":"1556329020866","symbol":"BTC-USDT","reason":"canceled","side":"sell","size":"0.00698471","orderId":"5cefcdc20bad452ac338d082","price":"8733.80000000000000000000","time":"1559219652922513289","type":"done"}
2019/05/30 14:34:13 [Info] msg: {"sequence":"1556329020867","symbol":"BTC-USDT","reason":"canceled","side":"sell","size":"0.202095","orderId":"5cefcdc30bad452ac338d0c9","price":"8735.00000000000000000000","time":"1559219652933300819","type":"done"}
2019/05/30 14:34:13 [Info] msg: {"sequence":"1556329020876","symbol":"BTC-USDT","reason":"canceled","side":"sell","size":"0.0001","orderId":"5cefcdc389fc846389b10982","price":"8721.50000000000000000000","time":"1559219653083335914","type":"done"}
2019/05/30 14:34:13 [Info] msg: {"sequence":"1556329020879","symbol":"BTC-USDT","reason":"canceled","side":"sell","size":"0.0001","orderId":"5cefcdc589fc846389b109ea","price":"8723.40000000000000000000","time":"1559219653560197571","type":"done"}
2019/05/30 14:34:13 [Info] msg: {"sequence":"1556329020884","symbol":"BTC-USDT","reason":"canceled","side":"buy","size":"0.039","orderId":"5cefcdc3c788c671b05d051f","price":"8716.10000000000000000000","time":"1559219653633282772","type":"done"}
2019/05/30 14:34:13 [Info] msg: {"sequence":"1556329020885","symbol":"BTC-USDT","reason":"canceled","side":"sell","size":"0.00907868","orderId":"5cefcdc4cdaba439e54e816c","price":"8733.80000000000000000000","time":"1559219653822424319","type":"done"}
2019/05/30 14:34:14 [Info] msg: {"sequence":"1556329020890","symbol":"BTC-USDT","reason":"canceled","side":"buy","size":"0.1228","orderId":"5cefcdc5c788c671b05d058c","price":"8717.10000000000000000000","time":"1559219654646270994","type":"done"}
2019/05/30 14:34:14 [Info] msg: {"sequence":"1556329020891","symbol":"BTC-USDT","reason":"canceled","side":"buy","size":"0.1125","orderId":"5cefcdc5c788c671b05d0590","price":"8717.10000000000000000000","time":"1559219654667540407","type":"done"}
2019/05/30 14:34:14 [Info] msg: {"sequence":"1556329020892","symbol":"BTC-USDT","reason":"canceled","side":"buy","size":"0.0899","orderId":"5cefcdc289fc846389b1093a","price":"8709.90000000000000000000","time":"1559219654739970440","type":"done"}
2019/05/30 14:34:14 [Info] msg: {"sequence":"1556329020895","symbol":"BTC-USDT","reason":"canceled","side":"sell","size":"0.5565906","orderId":"5cefcdc2c788c671b05d04f8","price":"8735.10000000000000000000","time":"1559219654750689744","type":"done"}
2019/05/30 14:34:14 [Info] msg: {"sequence":"1556329020896","symbol":"BTC-USDT","reason":"canceled","side":"sell","size":"0.2307006","orderId":"5cefcdc3054b463a72e7ac25","price":"8734.90000000000000000000","time":"1559219654750775229","type":"done"}
2019/05/30 14:34:14 [Info] msg: {"sequence":"1556329020897","symbol":"BTC-USDT","reason":"canceled","side":"sell","size":"0.0807714","orderId":"5cefcdc4c788c671b05d0581","price":"8735.20000000000000000000","time":"1559219654750796315","type":"done"}
2019/05/30 14:34:14 [Info] msg: {"sequence":"1556329020898","symbol":"BTC-USDT","reason":"canceled","side":"sell","size":"0.0675","orderId":"5cefcdc3cdaba439e54e8129","price":"8734.80000000000000000000","time":"1559219654750814597","type":"done"}
2019/05/30 14:34:14 [Info] msg: {"sequence":"1556329020899","symbol":"BTC-USDT","reason":"canceled","side":"sell","size":"0.1593","orderId":"5cefcdc3054b463a72e7ac21","price":"8734.70000000000000000000","time":"1559219654761181124","type":"done"}
2019/05/30 14:34:14 [Info] msg: {"sequence":"1556329020910","symbol":"BTC-USDT","reason":"canceled","side":"buy","size":"0.078689","orderId":"5cefcdc35137b96b7e1e2742","price":"8720.80000000000000000000","time":"1559219654815367910","type":"done"}
2019/05/30 14:34:15 [Info] msg: {"sequence":"1556329020913","symbol":"BTC-USDT","reason":"canceled","side":"sell","size":"0.00739367","orderId":"5cefcdc54c06872c1359d4ed","price":"8733.80000000000000000000","time":"1559219654922356996","type":"done"}
2019/05/30 14:34:15 [Info] msg: {"sequence":"1556329020916","symbol":"BTC-USDT","reason":"canceled","side":"buy","size":"0.206277","orderId":"5cefcdc25137b96bcaf93be8","price":"8720.60000000000000000000","time":"1559219655185494961","type":"done"}
2019/05/30 14:34:15 [Info] msg: {"sequence":"1556329020927","symbol":"BTC-USDT","reason":"canceled","side":"sell","size":"0.6190155","orderId":"5cefcdc60bad452af7db29d5","price":"8735.90000000000000000000","time":"1559219655637536391","type":"done"}
2019/05/30 14:34:15 [Info] msg: {"sequence":"1556329020928","symbol":"BTC-USDT","reason":"canceled","side":"sell","size":"0.5737698","orderId":"5cefcdc60bad452ac338d152","price":"8736.00000000000000000000","time":"1559219655637630465","type":"done"}
2019/05/30 14:34:15 [Info] msg: {"sequence":"1556329020929","symbol":"BTC-USDT","reason":"canceled","side":"sell","size":"0.00900599","orderId":"5cefcdc64c06872c1359d51b","price":"8735.00000000000000000000","time":"1559219655658011035","type":"done"}
2019/05/30 14:34:15 [Info] msg: {"sequence":"1556329020930","symbol":"BTC-USDT","reason":"canceled","side":"sell","size":"3.6","orderId":"5cefcdc6cdaba439e54e81bf","price":"8736.30000000000000000000","time":"1559219655658094522","type":"done"}
2019/05/30 14:34:15 [Info] msg: {"sequence":"1556329020937","symbol":"BTC-USDT","reason":"canceled","side":"buy","size":"0.1125","orderId":"5cefcdc7c788c671b05d05fe","price":"8717.10000000000000000000","time":"1559219655724977763","type":"done"}
2019/05/30 14:34:15 [Info] msg: {"sequence":"1556329020940","symbol":"BTC-USDT","reason":"canceled","side":"buy","size":"0.229196","orderId":"5cefcdc3c788c671b05d0529","price":"8720.70000000000000000000","time":"1559219655767504489","type":"done"}
2019/05/30 14:34:16 [Info] msg: {"sequence":"1556329020945","symbol":"BTC-USDT","reason":"canceled","side":"buy","size":"0.1228","orderId":"5cefcdc7cdaba43a1e148a75","price":"8717.10000000000000000000","time":"1559219656256042273","type":"done"}
2019/05/30 14:34:16 [Info] msg: {"sequence":"1556329020948","symbol":"BTC-USDT","reason":"canceled","side":"buy","size":"0.229212","orderId":"5cefcdc0054b463a72e7ab4a","price":"8716.30000000000000000000","time":"1559219656332283080","type":"done"}
2019/05/30 14:34:16 [Info] msg: {"sequence":"1556329020949","symbol":"BTC-USDT","reason":"canceled","side":"buy","size":"0.6178221","orderId":"5cefcdc4c788c671eab3ca70","price":"8717.30000000000000000000","time":"1559219656583398416","type":"done"}
2019/05/30 14:34:17 [Info] msg: {"sequence":"1556329020952","symbol":"BTC-USDT","reason":"canceled","side":"sell","size":"0.0001","orderId":"5cefcdc689fc846389b10a34","price":"8721.40000000000000000000","time":"1559219657314185320","type":"done"}
2019/05/30 14:34:17 [Info] msg: {"sequence":"1556329020953","symbol":"BTC-USDT","reason":"canceled","side":"sell","size":"0.0001","orderId":"5cefcdc54c06872c1359d4d0","price":"8721.50000000000000000000","time":"1559219657314314485","type":"done"}
2019/05/30 14:34:17 [Info] msg: {"sequence":"1556329020954","symbol":"BTC-USDT","reason":"canceled","side":"buy","size":"0.1125","orderId":"5cefcdc8cdaba439e54e820a","price":"8717.40000000000000000000","time":"1559219657323833367","type":"done"}
2019/05/30 14:34:17 [Info] msg: {"sequence":"1556329020957","symbol":"BTC-USDT","reason":"canceled","side":"buy","size":"0.2856267","orderId":"5cefcdc889fc846389b10aba","price":"8717.30000000000000000000","time":"1559219657502468053","type":"done"}
2019/05/30 14:34:17 [Info] msg: {"sequence":"1556329020958","symbol":"BTC-USDT","reason":"canceled","side":"buy","size":"0.45","orderId":"5cefcdc4c788c671b05d0556","price":"8717.20000000000000000000","time":"1559219657502572033","type":"done"}
2019/05/30 14:34:18 [Info] msg: {"sequence":"1556329020969","symbol":"BTC-USDT","reason":"canceled","side":"buy","size":"0.0899","orderId":"5cefcdc689fc8463508993db","price":"8710.00000000000000000000","time":"1559219658078660839","type":"done"}
2019/05/30 14:34:18 [Info] msg: {"sequence":"1556329020974","symbol":"BTC-USDT","reason":"canceled","side":"sell","size":"0.0001","orderId":"5cefcdc9c788c671eab3cbcd","price":"8723.00000000000000000000","time":"1559219658381547684","type":"done"}
2019/05/30 14:34:18 [Info] msg: {"sequence":"1556329020975","symbol":"BTC-USDT","reason":"canceled","side":"sell","size":"0.0081003","orderId":"5cefcdc70bad452af7db2a11","price":"8734.90000000000000000000","time":"1559219658571820511","type":"done"}
2019/05/30 14:34:18 [Info] msg: {"sequence":"1556329020976","symbol":"BTC-USDT","reason":"canceled","side":"sell","size":"0.0767565","orderId":"5cefcdc64c06872c53322b84","price":"8736.20000000000000000000","time":"1559219658582374079","type":"done"}
2019/05/30 14:34:18 [Info] msg: {"sequence":"1556329020977","symbol":"BTC-USDT","reason":"canceled","side":"sell","size":"0.0845379","orderId":"5cefcdc6c788c671b05d05eb","price":"8736.10000000000000000000","time":"1559219658582457972","type":"done"}
2019/05/30 14:34:18 [Info] msg: {"sequence":"1556329020978","symbol":"BTC-USDT","reason":"canceled","side":"buy","size":"0.00723164","orderId":"5cefcdc3cdaba439e54e812c","price":"8718.50000000000000000000","time":"1559219658582476640","type":"done"}
2019/05/30 14:34:19 [Info] msg: {"sequence":"1556329020987","symbol":"BTC-USDT","reason":"canceled","side":"sell","size":"0.0001","orderId":"5cefcdc989fc8463508994b4","price":"8722.90000000000000000000","time":"1559219658950796587","type":"done"}
2019/05/30 14:34:19 [Info] msg: {"sequence":"1556329020992","symbol":"BTC-USDT","reason":"canceled","side":"sell","size":"0.2307006","orderId":"5cefcdcacdaba439e54e82ba","price":"8735.60000000000000000000","time":"1559219659565112974","type":"done"}
2019/05/30 14:34:19 [Info] msg: {"sequence":"1556329020993","symbol":"BTC-USDT","reason":"canceled","side":"buy","size":"0.00613514","orderId":"5cefcdcacdaba43a1e148b29","price":"8718.50000000000000000000","time":"1559219659565212777","type":"done"}
2019/05/30 14:34:20 [Info] msg: {"sequence":"1556329020998","symbol":"BTC-USDT","reason":"canceled","side":"buy","size":"0.30000000","orderId":"5cefcdbd054b463aaf909bd4","price":"8718.90000000000000000000","time":"1559219660178978278","type":"done"}
2019/05/30 14:34:20 [Info] msg: {"sequence":"1556329020999","symbol":"BTC-USDT","reason":"canceled","side":"sell","size":"0.40079","orderId":"5cefcdb7054b463a72e7a92d","price":"8728.10000000000000000000","time":"1559219660231398874","type":"done"}
2019/05/30 14:34:20 [Info] msg: {"sequence":"1556329021000","symbol":"BTC-USDT","reason":"canceled","side":"buy","size":"1.60641","orderId":"5cefcda2cdaba43a1e148230","price":"8709.50000000000000000000","time":"1559219660242176034","type":"done"}
2019/05/30 14:34:20 [Info] msg: {"sequence":"1556329021003","symbol":"BTC-USDT","reason":"canceled","side":"sell","size":"0.0001","orderId":"5cefcdca0bad452af7db2af4","price":"8722.80000000000000000000","time":"1559219660477161433","type":"done"}
2019/05/30 14:34:20 [Info] msg: {"sequence":"1556329021004","symbol":"BTC-USDT","reason":"canceled","side":"sell","size":"0.0840294","orderId":"5cefcdc789fc84635089941e","price":"8735.90000000000000000000","time":"1559219660510176170","type":"done"}
2019/05/30 14:34:20 [Info] msg: {"sequence":"1556329021005","symbol":"BTC-USDT","reason":"canceled","side":"sell","size":"0.0845379","orderId":"5cefcdc789fc846350899421","price":"8736.00000000000000000000","time":"1559219660510271255","type":"done"}
2019/05/30 14:34:20 [Info] msg: {"sequence":"1556329021006","symbol":"BTC-USDT","reason":"canceled","side":"sell","size":"0.00938974","orderId":"5cefcdca0bad452ac338d242","price":"8734.70000000000000000000","time":"1559219660519781508","type":"done"}
2019/05/30 14:34:20 [Info] msg: {"sequence":"1556329021007","symbol":"BTC-USDT","reason":"canceled","side":"buy","size":"0.00741953","orderId":"5cefcdcb5137b96b7e1e290b","price":"8718.50000000000000000000","time":"1559219660519860418","type":"done"}
2019/05/30 14:34:20 [Info] msg: {"sequence":"1556329021008","symbol":"BTC-USDT","reason":"canceled","side":"buy","size":"0.0388314","orderId":"5cefcdc3054b463a72e7ac28","price":"8717.60000000000000000000","time":"1559219660519883372","type":"done"}
2019/05/30 14:34:20 [Info] msg: {"sequence":"1556329021009","symbol":"BTC-USDT","reason":"canceled","side":"buy","size":"0.1190727","orderId":"5cefcdc94c06872c53322c1f","price":"8717.30000000000000000000","time":"1559219660519897563","type":"done"}
2019/05/30 14:34:21 [Info] msg: {"sequence":"1556329021024","symbol":"BTC-USDT","reason":"canceled","side":"sell","size":"0.0001","orderId":"5cefcdcb0bad452af7db2b0d","price":"8722.50000000000000000000","time":"1559219660918336396","type":"done"}
2019/05/30 14:34:21 [Info] msg: {"sequence":"1556329021029","symbol":"BTC-USDT","reason":"canceled","side":"sell","size":"0.202095","orderId":"5cefcdcac788c671b05d06af","price":"8735.70000000000000000000","time":"1559219661516006452","type":"done"}
2019/05/30 14:34:21 [Info] msg: {"sequence":"1556329021030","symbol":"BTC-USDT","reason":"canceled","side":"sell","size":"0.0701487","orderId":"5cefcdc75137b96bcaf93d03","price":"8735.80000000000000000000","time":"1559219661516095161","type":"done"}
2019/05/30 14:34:21 [Info] msg: {"sequence":"1556329021031","symbol":"BTC-USDT","reason":"canceled","side":"sell","size":"0.4979331","orderId":"5cefcdcc054b463aaf909f70","price":"8735.50000000000000000000","time":"1559219661516116686","type":"done"}
2019/05/30 14:34:21 [Info] msg: {"sequence":"1556329021032","symbol":"BTC-USDT","reason":"canceled","side":"sell","size":"0.00645865","orderId":"5cefcdcc5137b96bcaf93e4f","price":"8734.50000000000000000000","time":"1559219661516132648","type":"done"}
2019/05/30 14:34:21 [Info] msg: {"sequence":"1556329021033","symbol":"BTC-USDT","reason":"canceled","side":"buy","size":"0.0388314","orderId":"5cefcdcccdaba43a1e148ba4","price":"8717.10000000000000000000","time":"1559219661537536019","type":"done"}
2019/05/30 14:34:21 [Info] msg: {"sequence":"1556329021034","symbol":"BTC-USDT","reason":"canceled","side":"buy","size":"3.2682357","orderId":"5cefcdcccdaba43a1e148ba3","price":"8717.00000000000000000000","time":"1559219661548502795","type":"done"}
2019/05/30 14:34:22 [Info] msg: {"sequence":"1556329021049","symbol":"BTC-USDT","reason":"canceled","side":"buy","size":"0.09","orderId":"5cefcdca0bad452af7db2ab6","price":"8706.50000000000000000000","time":"1559219662073918210","type":"done"}
2019/05/30 14:34:22 [Info] msg: {"sequence":"1556329021052","symbol":"BTC-USDT","reason":"canceled","side":"sell","size":"0.05","orderId":"5cefcdc10bad452af7db28a7","price":"8726.70000000000000000000","time":"1559219662181006698","type":"done"}
2019/05/30 14:34:22 [Info] msg: {"sequence":"1556329021055","symbol":"BTC-USDT","reason":"canceled","side":"buy","size":"0.1125","orderId":"5cefcdc9cdaba43a1e148afa","price":"8718.00000000000000000000","time":"1559219662493029139","type":"done"}
2019/05/30 14:34:22 [Info] msg: {"sequence":"1556329021056","symbol":"BTC-USDT","reason":"canceled","side":"buy","size":"0.1228","orderId":"5cefcdc9c788c671b05d0671","price":"8717.90000000000000000000","time":"1559219662493113053","type":"done"}
2019/05/30 14:34:22 [Info] msg: {"sequence":"1556329021057","symbol":"BTC-USDT","reason":"canceled","side":"sell","size":"0.0001","orderId":"5cefcdcc054b463aaf909f7e","price":"8722.40000000000000000000","time":"1559219662514177517","type":"done"}
2019/05/30 14:34:22 [Info] msg: {"sequence":"1556329021058","symbol":"BTC-USDT","reason":"canceled","side":"sell","size":"0.2587554","orderId":"5cefcdcd5137b96bcaf93e85","price":"8735.30000000000000000000","time":"1559219662534504336","type":"done"}
2019/05/30 14:34:22 [Info] msg: {"sequence":"1556329021059","symbol":"BTC-USDT","reason":"canceled","side":"sell","size":"0.0807714","orderId":"5cefcdcb054b463aaf909f21","price":"8735.60000000000000000000","time":"1559219662534587852","type":"done"}
2019/05/30 14:34:22 [Info] msg: {"sequence":"1556329021060","symbol":"BTC-USDT","reason":"canceled","side":"buy","size":"0.00910697","orderId":"5cefcdcc054b463a72e7ae4c","price":"8718.40000000000000000000","time":"1559219662545159213","type":"done"}
2019/05/30 14:34:22 [Info] msg: {"sequence":"1556329021061","symbol":"BTC-USDT","reason":"canceled","side":"buy","size":"0.00622438","orderId":"5cefcdc20bad452ac338d08b","price":"8717.40000000000000000000","time":"1559219662554887300","type":"done"}
2019/05/30 14:34:22 [Info] msg: {"sequence":"1556329021062","symbol":"BTC-USDT","reason":"canceled","side":"buy","size":"0.1228977","orderId":"5cefcdcdcdaba439e54e8364","price":"8717.30000000000000000000","time":"1559219662554957059","type":"done"}
2019/05/30 14:34:22 [Info] msg: {"sequence":"1556329021063","symbol":"BTC-USDT","reason":"canceled","side":"buy","size":"0.0515727","orderId":"5cefcdc9cdaba43a1e148aef","price":"8717.20000000000000000000","time":"1559219662554975169","type":"done"}
2019/05/30 14:34:22 [Info] msg: {"sequence":"1556329021064","symbol":"BTC-USDT","reason":"canceled","side":"buy","size":"0.125046","orderId":"5cefcdcd89fc846389b10bd6","price":"8717.00000000000000000000","time":"1559219662576149908","type":"done"}
2019/05/30 14:34:23 [Info] msg: {"sequence":"1556329021079","symbol":"BTC-USDT","reason":"canceled","side":"sell","size":"0.02083041","orderId":"5cefcdc0054b463a72e7ab39","price":"8726.80000000000000000000","time":"1559219663159294272","type":"done"}
2019/05/30 14:34:23 [Info] msg: {"sequence":"1556329021086","symbol":"BTC-USDT","reason":"canceled","side":"sell","size":"0.00954762","orderId":"5cefcdcdcdaba43a1e148bfc","price":"8734.40000000000000000000","time":"1559219663478965048","type":"done"}
2019/05/30 14:34:23 [Info] msg: {"sequence":"1556329021087","symbol":"BTC-USDT","reason":"canceled","side":"sell","size":"0.0807714","orderId":"5cefcdcc054b463aaf909f6c","price":"8735.40000000000000000000","time":"1559219663479065288","type":"done"}
2019/05/30 14:34:23 [Info] msg: {"sequence":"1556329021088","symbol":"BTC-USDT","reason":"canceled","side":"sell","size":"0.1602","orderId":"5cefcdcd4c06872c53322d33","price":"8735.50000000000000000000","time":"1559219663479084772","type":"done"}
2019/05/30 14:34:23 [Info] msg: {"sequence":"1556329021089","symbol":"BTC-USDT","reason":"canceled","side":"buy","size":"0.00998669","orderId":"5cefcdce4c06872c53322d75","price":"8718.80000000000000000000","time":"1559219663479099591","type":"done"}
2019/05/30 14:34:23 [Info] msg: {"sequence":"1556329021090","symbol":"BTC-USDT","reason":"canceled","side":"buy","size":"0.0513306","orderId":"5cefcdce89fc8463508995c4","price":"8717.90000000000000000000","time":"1559219663489720314","type":"done"}
2019/05/30 14:34:23 [Info] msg: {"sequence":"1556329021091","symbol":"BTC-USDT","reason":"canceled","side":"sell","size":"0.0675","orderId":"5cefcdce0bad452af7db2beb","price":"8735.60000000000000000000","time":"1559219663489801963","type":"done"}
2019/05/30 14:34:23 [Info] msg: {"sequence":"1556329021092","symbol":"BTC-USDT","reason":"canceled","side":"buy","size":"0.9","orderId":"5cefcdcec788c671b05d07ab","price":"8717.70000000000000000000","time":"1559219663489850090","type":"done"}
2019/05/30 14:34:23 [Info] msg: {"sequence":"1556329021105","symbol":"BTC-USDT","reason":"canceled","side":"sell","size":"0.0807714","orderId":"5cefcdcdc788c671b05d077e","price":"8735.70000000000000000000","time":"1559219663617207492","type":"done"}
2019/05/30 14:34:23 [Info] msg: {"sequence":"1556329021110","symbol":"BTC-USDT","reason":"canceled","side":"buy","size":"1.404432","orderId":"5cefcdce5137b96b7e1e29cc","price":"8717.80000000000000000000","time":"1559219663659487862","type":"done"}
2019/05/30 14:34:24 [Info] msg: {"sequence":"1556329021113","symbol":"BTC-USDT","reason":"canceled","side":"buy","size":"0.039","orderId":"5cefcdb60bad452af7db2623","price":"8705.50000000000000000000","time":"1559219664019240034","type":"done"}
2019/05/30 14:34:24 [Info] msg: {"sequence":"1556329021114","symbol":"BTC-USDT","reason":"canceled","side":"buy","size":"0.038","orderId":"5cefcdb7c788c671b05d0269","price":"8700.00000000000000000000","time":"1559219664041827850","type":"done"}
2019/05/30 14:34:24 [Info] msg: {"sequence":"1556329021115","symbol":"BTC-USDT","reason":"canceled","side":"buy","size":"0.039","orderId":"5cefcdc5054b463a72e7ac83","price":"8716.30000000000000000000","time":"1559219664112725391","type":"done"}
2019/05/30 14:34:24 [Info] msg: {"sequence":"1556329021116","symbol":"BTC-USDT","reason":"canceled","side":"buy","size":"0.1228","orderId":"5cefcdcf4c06872c1359d716","price":"8717.60000000000000000000","time":"1559219664135824781","type":"done"}
2019/05/30 14:34:24 [Info] msg: {"sequence":"1556329021117","symbol":"BTC-USDT","reason":"canceled","side":"buy","size":"0.1125","orderId":"5cefcdcf054b463aaf90a00c","price":"8717.70000000000000000000","time":"1559219664145785837","type":"done"}
2019/05/30 14:34:24 [Info] msg: {"sequence":"1556329021120","symbol":"BTC-USDT","reason":"canceled","side":"sell","size":"0.0001","orderId":"5cefcdcdcdaba439e54e8355","price":"8722.20000000000000000000","time":"1559219664156483348","type":"done"}
2019/05/30 14:34:24 [Info] msg: {"sequence":"1556329021125","symbol":"BTC-USDT","reason":"canceled","side":"buy","size":"0.45","orderId":"5cefcdce5137b96bcaf93ec0","price":"8717.60000000000000000000","time":"1559219664543652197","type":"done"}
2019/05/30 14:34:24 [Info] msg: {"sequence":"1556329021126","symbol":"BTC-USDT","reason":"canceled","side":"buy","size":"0.1190727","orderId":"5cefcdcf054b463a72e7af0c","price":"8717.30000000000000000000","time":"1559219664555538916","type":"done"}
2019/05/30 14:34:24 [Info] msg: {"sequence":"1556329021127","symbol":"BTC-USDT","reason":"canceled","side":"buy","size":"0.6706386","orderId":"5cefcdcf0bad452ac338d391","price":"8717.40000000000000000000","time":"1559219664555650577","type":"done"}
2019/05/30 14:34:24 [Info] msg: {"sequence":"1556329021128","symbol":"BTC-USDT","reason":"canceled","side":"buy","size":"0.1301688","orderId":"5cefcdcf4c06872c53322dcb","price":"8717.20000000000000000000","time":"1559219664555670564","type":"done"}
2019/05/30 14:34:24 [Info] msg: {"sequence":"1556329021129","symbol":"BTC-USDT","reason":"canceled","side":"buy","size":"0.00532244","orderId":"5cefcdcf5137b96bcaf93f15","price":"8718.50000000000000000000","time":"1559219664555684657","type":"done"}
2019/05/30 14:34:24 [Info] msg: {"sequence":"1556329021132","symbol":"BTC-USDT","reason":"canceled","side":"buy","size":"0.0783054","orderId":"5cefcdc30bad452af7db294b","price":"8717.50000000000000000000","time":"1559219664555878145","type":"done"}
2019/05/30 14:34:25 [Info] msg: {"sequence":"1556329021157","symbol":"BTC-USDT","reason":"canceled","side":"sell","size":"0.05","orderId":"5cefcdce5137b96b7e1e29c2","price":"8726.90000000000000000000","time":"1559219665182288629","type":"done"}
2019/05/30 14:34:25 [Info] msg: {"sequence":"1556329021160","symbol":"BTC-USDT","reason":"canceled","side":"buy","size":"0.039","orderId":"5cefcdd089fc846350899614","price":"8716.30000000000000000000","time":"1559219665466039596","type":"done"}
2019/05/30 14:34:25 [Info] msg: {"sequence":"1556329021161","symbol":"BTC-USDT","reason":"canceled","side":"sell","size":"0.2307006","orderId":"5cefcdcf0bad452ac338d389","price":"8735.10000000000000000000","time":"1559219665496441261","type":"done"}
2019/05/30 14:34:25 [Info] msg: {"sequence":"1556329021164","symbol":"BTC-USDT","reason":"canceled","side":"sell","size":"0.0807714","orderId":"5cefcdcec788c671eab3ccf9","price":"8735.30000000000000000000","time":"1559219665496720058","type":"done"}
2019/05/30 14:34:25 [Info] msg: {"sequence":"1556329021165","symbol":"BTC-USDT","reason":"canceled","side":"buy","size":"0.1229355","orderId":"5cefcdd089fc84635089962f","price":"8718.10000000000000000000","time":"1559219665496739228","type":"done"}
2019/05/30 14:34:25 [Info] msg: {"sequence":"1556329021166","symbol":"BTC-USDT","reason":"canceled","side":"buy","size":"0.9","orderId":"5cefcdd0054b463aaf90a04f","price":"8718.00000000000000000000","time":"1559219665496757030","type":"done"}
2019/05/30 14:34:25 [Info] msg: {"sequence":"1556329021167","symbol":"BTC-USDT","reason":"canceled","side":"buy","size":"3.2682357","orderId":"5cefcdd089fc846350899632","price":"8717.80000000000000000000","time":"1559219665496774633","type":"done"}
2019/05/30 14:34:25 [Info] msg: {"sequence":"1556329021168","symbol":"BTC-USDT","reason":"canceled","side":"sell","size":"0.00925475","orderId":"5cefcdcf4c06872c53322dc3","price":"8734.00000000000000000000","time":"1559219665506898311","type":"done"}
2019/05/30 14:34:25 [Info] msg: {"sequence":"1556329021169","symbol":"BTC-USDT","reason":"canceled","side":"sell","size":"0.45","orderId":"5cefcdcf5137b96bcaf93f09","price":"8734.90000000000000000000","time":"1559219665506968446","type":"done"}
2019/05/30 14:34:25 [Info] msg: {"sequence":"1556329021172","symbol":"BTC-USDT","reason":"canceled","side":"sell","size":"0.7586856","orderId":"5cefcdcf89fc846389b10c53","price":"8735.20000000000000000000","time":"1559219665569745174","type":"done"}
2019/05/30 14:34:26 [Info] msg: {"sequence":"1556329021189","symbol":"BTC-USDT","reason":"canceled","side":"buy","size":"0.078682","orderId":"5cefcdd0cdaba43a1e148c9c","price":"8721.70000000000000000000","time":"1559219666030248438","type":"done"}
2019/05/30 14:34:26 [Info] msg: {"sequence":"1556329021190","symbol":"BTC-USDT","reason":"canceled","side":"sell","size":"0.05","orderId":"5cefcdd10bad452ac338d3ec","price":"8728.00000000000000000000","time":"1559219666105625502","type":"done"}
2019/05/30 14:34:26 [Info] msg: {"sequence":"1556329021193","symbol":"BTC-USDT","reason":"canceled","side":"buy","size":"0.229187","orderId":"5cefcdd04c06872c53322e04","price":"8717.30000000000000000000","time":"1559219666267727337","type":"done"}
2019/05/30 14:34:26 [Info] msg: {"sequence":"1556329021196","symbol":"BTC-USDT","reason":"canceled","side":"buy","size":"0.09","orderId":"5cefcdce4c06872c53322d57","price":"8706.60000000000000000000","time":"1559219666542004374","type":"done"}
2019/05/30 14:34:26 [Info] msg: {"sequence":"1556329021197","symbol":"BTC-USDT","reason":"canceled","side":"sell","size":"0.4338927","orderId":"5cefcdd1054b463aaf90a093","price":"8736.10000000000000000000","time":"1559219666563227913","type":"done"}
2019/05/30 14:34:26 [Info] msg: {"sequence":"1556329021198","symbol":"BTC-USDT","reason":"canceled","side":"buy","size":"0.00522398","orderId":"5cefcdd05137b96b7e1e2a2f","price":"8719.00000000000000000000","time":"1559219666572959711","type":"done"}
2019/05/30 14:34:26 [Info] msg: {"sequence":"1556329021199","symbol":"BTC-USDT","reason":"canceled","side":"sell","size":"1.5150744","orderId":"5cefcdd1054b463aaf90a090","price":"8735.90000000000000000000","time":"1559219666583451698","type":"done"}
2019/05/30 14:34:26 [Info] msg: {"sequence":"1556329021200","symbol":"BTC-USDT","reason":"canceled","side":"buy","size":"0.1223838","orderId":"5cefcdd1054b463a72e7af6f","price":"8718.00000000000000000000","time":"1559219666583524917","type":"done"}
2019/05/30 14:34:26 [Info] msg: {"sequence":"1556329021201","symbol":"BTC-USDT","reason":"canceled","side":"buy","size":"0.0388314","orderId":"5cefcdd15137b96bcaf93f79","price":"8717.80000000000000000000","time":"1559219666583546665","type":"done"}
2019/05/30 14:34:26 [Info] msg: {"sequence":"1556329021202","symbol":"BTC-USDT","reason":"canceled","side":"buy","size":"0.00501789","orderId":"5cefcdd1c788c671b05d086d","price":"8718.10000000000000000000","time":"1559219666604545826","type":"done"}
2019/05/30 14:34:26 [Info] msg: {"sequence":"1556329021203","symbol":"BTC-USDT","reason":"canceled","side":"buy","size":"0.0388314","orderId":"5cefcdd089fc846389b10c80","price":"8717.90000000000000000000","time":"1559219666604618974","type":"done"}
2019/05/30 14:34:26 [Info] msg: {"sequence":"1556329021204","symbol":"BTC-USDT","reason":"canceled","side":"sell","size":"0.0001","orderId":"5cefcdcf4c06872c53322d9f","price":"8722.10000000000000000000","time":"1559219666625176111","type":"done"}
2019/05/30 14:34:26 [Info] msg: {"sequence":"1556329021207","symbol":"BTC-USDT","reason":"canceled","side":"buy","size":"0.229175","orderId":"5cefcdd189fc846350899663","price":"8721.60000000000000000000","time":"1559219666645598362","type":"done"}
2019/05/30 14:34:26 [Info] msg: {"sequence":"1556329021216","symbol":"BTC-USDT","reason":"canceled","side":"buy","size":"0.206257","orderId":"5cefcdd15137b96b7e1e2a46","price":"8721.50000000000000000000","time":"1559219666707709579","type":"done"}
2019/05/30 14:34:26 [Info] msg: {"sequence":"1556329021217","symbol":"BTC-USDT","reason":"canceled","side":"sell","size":"0.45","orderId":"5cefcdd10bad452af7db2c8f","price":"8736.00000000000000000000","time":"1559219666718529128","type":"done"}
2019/05/30 14:34:26 [Info] msg: {"sequence":"1556329021220","symbol":"BTC-USDT","reason":"canceled","side":"buy","size":"0.0513306","orderId":"5cefcdd089fc846389b10c87","price":"8717.70000000000000000000","time":"1559219666729687493","type":"done"}
2019/05/30 14:34:27 [Info] msg: {"sequence":"1556329021227","symbol":"BTC-USDT","reason":"canceled","side":"sell","size":"0.068754","orderId":"5cefcdc85137b96b7e1e2839","price":"8728.60000000000000000000","time":"1559219666955952061","type":"done"}
2019/05/30 14:34:27 [Info] msg: {"sequence":"1556329021228","symbol":"BTC-USDT","reason":"canceled","side":"sell","size":"0.05","orderId":"5cefcdd25137b96bcaf93fbf","price":"8728.00000000000000000000","time":"1559219667139901180","type":"done"}
2019/05/30 14:34:27 [Info] msg: {"sequence":"1556329021233","symbol":"BTC-USDT","reason":"canceled","side":"sell","size":"0.0675","orderId":"5cefcdcf5137b96bcaf93f06","price":"8735.00000000000000000000","time":"1559219667586659181","type":"done"}
2019/05/30 14:34:27 [Info] msg: {"sequence":"1556329021234","symbol":"BTC-USDT","reason":"canceled","side":"sell","size":"0.45","orderId":"5cefcdd289fc8463508996cc","price":"8735.90000000000000000000","time":"1559219667586759396","type":"done"}
2019/05/30 14:34:27 [Info] msg: {"sequence":"1556329021235","symbol":"BTC-USDT","reason":"canceled","side":"sell","size":"0.0675","orderId":"5cefcdd2c788c671eab3ce26","price":"8736.00000000000000000000","time":"1559219667586778515","type":"done"}
2019/05/30 14:34:27 [Info] msg: {"sequence":"1556329021236","symbol":"BTC-USDT","reason":"canceled","side":"sell","size":"0.2307006","orderId":"5cefcdd20bad452af7db2cde","price":"8736.10000000000000000000","time":"1559219667586792836","type":"done"}
2019/05/30 14:34:27 [Info] msg: {"sequence":"1556329021237","symbol":"BTC-USDT","reason":"canceled","side":"sell","size":"0.6327837","orderId":"5cefcdd1c788c671eab3cdc7","price":"8736.20000000000000000000","time":"1559219667597267607","type":"done"}
2019/05/30 14:34:27 [Info] msg: {"sequence":"1556329021238","symbol":"BTC-USDT","reason":"canceled","side":"sell","size":"0.1602","orderId":"5cefcdd189fc846389b10cc7","price":"8736.30000000000000000000","time":"1559219667597349811","type":"done"}
2019/05/30 14:34:27 [Info] msg: {"sequence":"1556329021239","symbol":"BTC-USDT","reason":"canceled","side":"buy","size":"0.225","orderId":"5cefcdd2c788c671eab3ce2d","price":"8716.40000000000000000000","time":"1559219667597366341","type":"done"}
2019/05/30 14:34:27 [Info] msg: {"sequence":"1556329021240","symbol":"BTC-USDT","reason":"canceled","side":"buy","size":"0.116019","orderId":"5cefcdd289fc846389b10d0d","price":"8716.50000000000000000000","time":"1559219667597407554","type":"done"}
2019/05/30 14:34:27 [Info] msg: {"sequence":"1556329021241","symbol":"BTC-USDT","reason":"canceled","side":"buy","size":"0.4984515","orderId":"5cefcdd289fc846389b10d14","price":"8716.30000000000000000000","time":"1559219667606822150","type":"done"}
2019/05/30 14:34:27 [Info] msg: {"sequence":"1556329021242","symbol":"BTC-USDT","reason":"canceled","side":"buy","size":"0.45","orderId":"5cefcdd20bad452ac338d44b","price":"8716.20000000000000000000","time":"1559219667606894772","type":"done"}
2019/05/30 14:34:27 [Info] msg: {"sequence":"1556329021243","symbol":"BTC-USDT","reason":"canceled","side":"buy","size":"0.2856267","orderId":"5cefcdd2c788c671b05d08b0","price":"8716.10000000000000000000","time":"1559219667606910745","type":"done"}
2019/05/30 14:34:27 [Info] msg: {"sequence":"1556329021244","symbol":"BTC-USDT","reason":"canceled","side":"buy","size":"0.0092827","orderId":"5cefcdd2054b463aaf90a0da","price":"8717.40000000000000000000","time":"1559219667617640982","type":"done"}
2019/05/30 14:34:27 [Info] msg: {"sequence":"1556329021261","symbol":"BTC-USDT","reason":"canceled","side":"sell","size":"0.0001","orderId":"5cefcdd00bad452ac338d3b8","price":"8721.90000000000000000000","time":"1559219667703023030","type":"done"}
2019/05/30 14:34:27 [Info] msg: {"sequence":"1556329021262","symbol":"BTC-USDT","reason":"canceled","side":"sell","size":"0.0001","orderId":"5cefcdd3054b463a72e7afe6","price":"8721.80000000000000000000","time":"1559219667703104012","type":"done"}
2019/05/30 14:34:27 [Info] msg: {"sequence":"1556329021263","symbol":"BTC-USDT","reason":"canceled","side":"buy","size":"0.1125","orderId":"5cefcdd0cdaba43a1e148c84","price":"8717.40000000000000000000","time":"1559219667724290900","type":"done"}
2019/05/30 14:34:27 [Info] msg: {"sequence":"1556329021264","symbol":"BTC-USDT","reason":"canceled","side":"buy","size":"0.1228","orderId":"5cefcdd14c06872c1359d77c","price":"8717.20000000000000000000","time":"1559219667724365471","type":"done"}
2019/05/30 14:34:28 [Info] msg: {"sequence":"1556329021275","symbol":"BTC-USDT","reason":"canceled","side":"sell","size":"0.045836","orderId":"5cefcdc7cdaba439e54e81de","price":"8728.10000000000000000000","time":"1559219668067081590","type":"done"}
2019/05/30 14:34:28 [Info] msg: {"sequence":"1556329021280","symbol":"BTC-USDT","reason":"canceled","side":"sell","size":"0.6240906","orderId":"5cefcdd35137b96bcaf94015","price":"8734.50000000000000000000","time":"1559219668645680420","type":"done"}
2019/05/30 14:34:28 [Info] msg: {"sequence":"1556329021281","symbol":"BTC-USDT","reason":"canceled","side":"sell","size":"0.9","orderId":"5cefcdd389fc846350899713","price":"8735.20000000000000000000","time":"1559219668656343265","type":"done"}
2019/05/30 14:34:28 [Info] msg: {"sequence":"1556329021282","symbol":"BTC-USDT","reason":"canceled","side":"sell","size":"0.00804965","orderId":"5cefcdd3c788c671b05d08e7","price":"8733.60000000000000000000","time":"1559219668666936848","type":"done"}
2019/05/30 14:34:28 [Info] msg: {"sequence":"1556329021283","symbol":"BTC-USDT","reason":"canceled","side":"buy","size":"3.2682357","orderId":"5cefcdd389fc846350899710","price":"8717.00000000000000000000","time":"1559219668677577794","type":"done"}
2019/05/30 14:34:28 [Info] msg: {"sequence":"1556329021286","symbol":"BTC-USDT","reason":"canceled","side":"buy","size":"0.0388314","orderId":"5cefcdd3cdaba439e54e84bb","price":"8717.10000000000000000000","time":"1559219668688396687","type":"done"}
2019/05/30 14:34:29 [Info] msg: {"sequence":"1556329021301","symbol":"BTC-USDT","reason":"canceled","side":"buy","size":"0.00976189","orderId":"5cefcdd34c06872c53322ebf","price":"8718.00000000000000000000","time":"1559219668864082561","type":"done"}
2019/05/30 14:34:29 [Info] msg: {"sequence":"1556329021302","symbol":"BTC-USDT","reason":"canceled","side":"buy","size":"0.0513306","orderId":"5cefcdd389fc846350899720","price":"8716.90000000000000000000","time":"1559219668864184560","type":"done"}
2019/05/30 14:34:29 [Info] msg: {"sequence":"1556329021303","symbol":"BTC-USDT","reason":"canceled","side":"buy","size":"0.6178221","orderId":"5cefcdd34c06872c53322ebc","price":"8716.80000000000000000000","time":"1559219668864205681","type":"done"}
2019/05/30 14:34:29 [Info] msg: {"sequence":"1556329021304","symbol":"BTC-USDT","reason":"canceled","side":"buy","size":"0.566019","orderId":"5cefcdd35137b96bcaf94009","price":"8716.70000000000000000000","time":"1559219668864221759","type":"done"}
2019/05/30 14:34:29 [Info] msg: {"sequence":"1556329021309","symbol":"BTC-USDT","reason":"canceled","side":"sell","size":"1.66838","orderId":"5cefcd9589fc846350898855","price":"8737.10000000000000000000","time":"1559219669294564584","type":"done"}
2019/05/30 14:34:29 [Info] msg: {"sequence":"1556329021310","symbol":"BTC-USDT","reason":"canceled","side":"buy","size":"2.02396","orderId":"5cefcd965137b96bcaf93146","price":"8702.00000000000000000000","time":"1559219669294675107","type":"done"}
2019/05/30 14:34:29 [Info] msg: {"sequence":"1556329021311","symbol":"BTC-USDT","reason":"canceled","side":"sell","size":"2.10202","orderId":"5cefcd95c788c671eab3bf27","price":"8745.30000000000000000000","time":"1559219669315993931","type":"done"}
2019/05/30 14:34:29 [Info] msg: {"sequence":"1556329021320","symbol":"BTC-USDT","reason":"canceled","side":"buy","size":"0.4984515","orderId":"5cefcdd45137b96bcaf94055","price":"8717.40000000000000000000","time":"1559219669597345293","type":"done"}
2019/05/30 14:34:29 [Info] msg: {"sequence":"1556329021321","symbol":"BTC-USDT","reason":"canceled","side":"buy","size":"0.225","orderId":"5cefcdd44c06872c1359d869","price":"8717.50000000000000000000","time":"1559219669597492814","type":"done"}
2019/05/30 14:34:29 [Info] msg: {"sequence":"1556329021322","symbol":"BTC-USDT","reason":"canceled","side":"buy","size":"0.45","orderId":"5cefcdd40bad452af7db2d74","price":"8717.60000000000000000000","time":"1559219669597517085","type":"done"}
2019/05/30 14:34:29 [Info] msg: {"sequence":"1556329021323","symbol":"BTC-USDT","reason":"canceled","side":"buy","size":"0.2856267","orderId":"5cefcdd40bad452ac338d4f2","price":"8717.30000000000000000000","time":"1559219669607980792","type":"done"}
2019/05/30 14:34:29 [Info] msg: {"sequence":"1556329021324","symbol":"BTC-USDT","reason":"canceled","side":"buy","size":"0.00816501","orderId":"5cefcdd44c06872c1359d878","price":"8718.50000000000000000000","time":"1559219669608084402","type":"done"}
2019/05/30 14:34:29 [Info] msg: {"sequence":"1556329021325","symbol":"BTC-USDT","reason":"canceled","side":"sell","size":"0.00868044","orderId":"5cefcdd4c788c671eab3cea4","price":"8733.60000000000000000000","time":"1559219669640016934","type":"done"}
2019/05/30 14:34:29 [Info] msg: {"sequence":"1556329021344","symbol":"BTC-USDT","reason":"canceled","side":"buy","size":"0.6706386","orderId":"5cefcdd40bad452af7db2d77","price":"8717.20000000000000000000","time":"1559219669714123183","type":"done"}
2019/05/30 14:34:29 [Info] msg: {"sequence":"1556329021345","symbol":"BTC-USDT","reason":"canceled","side":"sell","size":"0.7386624","orderId":"5cefcdd389fc846350899723","price":"8734.70000000000000000000","time":"1559219669714148493","type":"done"}
2019/05/30 14:34:30 [Info] msg: {"sequence":"1556329021346","symbol":"BTC-USDT","reason":"canceled","side":"sell","size":"0.1487","orderId":"5cefcdc7cdaba439e54e81d0","price":"8733.10000000000000000000","time":"1559219669867377532","type":"done"}
2019/05/30 14:34:30 [Info] msg: {"sequence":"1556329021349","symbol":"BTC-USDT","reason":"canceled","side":"sell","size":"0.0001","orderId":"5cefcdd40bad452ac338d4c3","price":"8722.00000000000000000000","time":"1559219669881508917","type":"done"}
2019/05/30 14:34:30 [Info] msg: {"sequence":"1556329021350","symbol":"BTC-USDT","reason":"canceled","side":"buy","size":"0.09","orderId":"5cefcdd24c06872c53322e64","price":"8706.80000000000000000000","time":"1559219670092868811","type":"done"}
2019/05/30 14:34:30 [Info] msg: {"sequence":"1556329021355","symbol":"BTC-USDT","reason":"canceled","side":"buy","size":"0.00500204","orderId":"5cefcdd589fc846389b10dcb","price":"8717.10000000000000000000","time":"1559219670561061045","type":"done"}
2019/05/30 14:34:30 [Info] msg: {"sequence":"1556329021356","symbol":"BTC-USDT","reason":"canceled","side":"sell","size":"0.00553757","orderId":"5cefcdd54c06872c1359d8bc","price":"8733.60000000000000000000","time":"1559219670561163139","type":"done"}
2019/05/30 14:34:31 [Info] msg: {"sequence":"1556329021361","symbol":"BTC-USDT","reason":"canceled","side":"sell","size":"0.091672","orderId":"5cefcdc6c788c671eab3cb11","price":"8731.70000000000000000000","time":"1559219670905363365","type":"done"}
2019/05/30 14:34:31 [Info] msg: {"sequence":"1556329021362","symbol":"BTC-USDT","reason":"canceled","side":"sell","size":"0.06876","orderId":"5cefcdd3cdaba439e54e84e1","price":"8727.90000000000000000000","time":"1559219670926930056","type":"done"}
2019/05/30 14:34:31 [Info] msg: {"sequence":"1556329021369","symbol":"BTC-USDT","reason":"canceled","side":"sell","size":"0.045841","orderId":"5cefcdd55137b96bcaf940a8","price":"8727.10000000000000000000","time":"1559219671471545269","type":"done"}
2019/05/30 14:34:31 [Info] msg: {"sequence":"1556329021370","symbol":"BTC-USDT","reason":"canceled","side":"sell","size":"0.0001","orderId":"5cefcdd5054b463a72e7b063","price":"8721.90000000000000000000","time":"1559219671482358185","type":"done"}
2019/05/30 14:34:31 [Info] msg: {"sequence":"1556329021371","symbol":"BTC-USDT","reason":"canceled","side":"buy","size":"0.1228","orderId":"5cefcdd45137b96b7e1e2b1b","price":"8717.70000000000000000000","time":"1559219671482457330","type":"done"}
2019/05/30 14:34:31 [Info] msg: {"sequence":"1556329021372","symbol":"BTC-USDT","reason":"canceled","side":"buy","size":"0.1125","orderId":"5cefcdd45137b96bcaf94033","price":"8717.90000000000000000000","time":"1559219671493093484","type":"done"}
2019/05/30 14:34:31 [Info] msg: {"sequence":"1556329021373","symbol":"BTC-USDT","reason":"canceled","side":"sell","size":"0.1602","orderId":"5cefcdd3c788c671b05d08eb","price":"8735.10000000000000000000","time":"1559219671564933939","type":"done"}
2019/05/30 14:34:31 [Info] msg: {"sequence":"1556329021374","symbol":"BTC-USDT","reason":"canceled","side":"buy","size":"0.00550058","orderId":"5cefcdd50bad452af7db2dca","price":"8718.00000000000000000000","time":"1559219671565017280","type":"done"}
2019/05/30 14:34:31 [Info] msg: {"sequence":"1556329021375","symbol":"BTC-USDT","reason":"canceled","side":"buy","size":"3.3356385","orderId":"5cefcdd5cdaba43a1e148dcd","price":"8716.80000000000000000000","time":"1559219671565042012","type":"done"}
2019/05/30 14:34:31 [Info] msg: {"sequence":"1556329021376","symbol":"BTC-USDT","reason":"canceled","side":"buy","size":"0.005033","orderId":"5cefcdd65137b96bcaf940d9","price":"8717.10000000000000000000","time":"1559219671565056854","type":"done"}
2019/05/30 14:34:31 [Info] msg: {"sequence":"1556329021377","symbol":"BTC-USDT","reason":"canceled","side":"buy","size":"0.9443466","orderId":"5cefcdd55137b96bcaf940b1","price":"8717.00000000000000000000","time":"1559219671574646687","type":"done"}
2019/05/30 14:34:31 [Info] msg: {"sequence":"1556329021378","symbol":"BTC-USDT","reason":"canceled","side":"buy","size":"0.0513306","orderId":"5cefcdd5054b463aaf90a194","price":"8716.70000000000000000000","time":"1559219671574717308","type":"done"}
2019/05/30 14:34:31 [Info] msg: {"sequence":"1556329021379","symbol":"BTC-USDT","reason":"canceled","side":"buy","size":"0.0388314","orderId":"5cefcdd50bad452ac338d52f","price":"8716.90000000000000000000","time":"1559219671574734435","type":"done"}
2019/05/30 14:34:31 [Info] msg: {"sequence":"1556329021380","symbol":"BTC-USDT","reason":"canceled","side":"sell","size":"0.7211016","orderId":"5cefcdd5c788c671eab3ceec","price":"8734.80000000000000000000","time":"1559219671574747284","type":"done"}
2019/05/30 14:34:31 [Info] msg: {"sequence":"1556329021395","symbol":"BTC-USDT","reason":"canceled","side":"sell","size":"0.64733176","orderId":"5cefcda6cdaba439e54e7ab9","price":"8854.70000000000000000000","time":"1559219671752218943","type":"done"}
2019/05/30 14:34:32 [Info] msg: {"sequence":"1556329021396","symbol":"BTC-USDT","reason":"canceled","side":"sell","size":"0.5565906","orderId":"5cefcdd4cdaba439e54e851c","price":"8734.50000000000000000000","time":"1559219671885339144","type":"done"}
2019/05/30 14:34:32 [Info] msg: {"sequence":"1556329021411","symbol":"BTC-USDT","reason":"canceled","side":"buy","size":"0.039","orderId":"5cefcdd1c788c671eab3cdbe","price":"8714.90000000000000000000","time":"1559219672218198318","type":"done"}
2019/05/30 14:34:32 [Info] msg: {"sequence":"1556329021414","symbol":"BTC-USDT","reason":"canceled","side":"buy","size":"0.039","orderId":"5cefcdd80bad452ac338d5c7","price":"8716.20000000000000000000","time":"1559219672534861267","type":"done"}
2019/05/30 14:34:32 [Info] msg: {"sequence":"1556329021417","symbol":"BTC-USDT","reason":"canceled","side":"sell","size":"0.6237837","orderId":"5cefcdd30bad452af7db2d3b","price":"8734.90000000000000000000","time":"1559219672620247656","type":"done"}
2019/05/30 14:34:32 [Info] msg: {"sequence":"1556329021418","symbol":"BTC-USDT","reason":"canceled","side":"buy","size":"1.5917697","orderId":"5cefcdd7c788c671eab3cf62","price":"8718.50000000000000000000","time":"1559219672620328832","type":"done"}
2019/05/30 14:34:32 [Info] msg: {"sequence":"1556329021419","symbol":"BTC-USDT","reason":"canceled","side":"buy","size":"3.3356385","orderId":"5cefcdd7054b463aaf90a207","price":"8718.30000000000000000000","time":"1559219672631143029","type":"done"}
2019/05/30 14:34:33 [Info] msg: {"sequence":"1556329021426","symbol":"BTC-USDT","reason":"canceled","side":"buy","size":"0.1228","orderId":"5cefcdd8054b463a72e7b15a","price":"8718.00000000000000000000","time":"1559219673080466200","type":"done"}
2019/05/30 14:34:33 [Info] msg: {"sequence":"1556329021427","symbol":"BTC-USDT","reason":"canceled","side":"buy","size":"0.1125","orderId":"5cefcdd8cdaba439e54e85f2","price":"8718.10000000000000000000","time":"1559219673080571878","type":"done"}
2019/05/30 14:34:33 [Info] msg: {"sequence":"1556329021428","symbol":"BTC-USDT","reason":"canceled","side":"sell","size":"0.0001","orderId":"5cefcdd84c06872c1359d931","price":"8721.90000000000000000000","time":"1559219673143596168","type":"done"}
2019/05/30 14:34:33 [Info] msg: {"sequence":"1556329021429","symbol":"BTC-USDT","reason":"canceled","side":"buy","size":"0.206285","orderId":"5cefcdd55137b96bcaf940bd","price":"8720.30000000000000000000","time":"1559219673143686206","type":"done"}
2019/05/30 14:34:33 [Info] msg: {"sequence":"1556329021430","symbol":"BTC-USDT","reason":"canceled","side":"buy","size":"0.229216","orderId":"5cefcdd7c788c671b05d09d0","price":"8716.20000000000000000000","time":"1559219673143711241","type":"done"}
2019/05/30 14:34:33 [Info] msg: {"sequence":"1556329021431","symbol":"BTC-USDT","reason":"canceled","side":"buy","size":"0.229216","orderId":"5cefcdd70bad452af7db2e35","price":"8720.00000000000000000000","time":"1559219673174724185","type":"done"}
2019/05/30 14:34:33 [Info] msg: {"sequence":"1556329021436","symbol":"BTC-USDT","reason":"canceled","side":"sell","size":"0.0479331","orderId":"5cefcdd80bad452ac338d5f3","price":"8734.90000000000000000000","time":"1559219673549947955","type":"done"}
2019/05/30 14:34:33 [Info] msg: {"sequence":"1556329021437","symbol":"BTC-USDT","reason":"canceled","side":"buy","size":"0.00851049","orderId":"5cefcdd7c788c671eab3cf5f","price":"8719.50000000000000000000","time":"1559219673550050212","type":"done"}
2019/05/30 14:34:33 [Info] msg: {"sequence":"1556329021438","symbol":"BTC-USDT","reason":"canceled","side":"buy","size":"0.0388314","orderId":"5cefcdd889fc846350899865","price":"8718.30000000000000000000","time":"1559219673560606772","type":"done"}
2019/05/30 14:34:33 [Info] msg: {"sequence":"1556329021439","symbol":"BTC-USDT","reason":"canceled","side":"buy","size":"0.0513306","orderId":"5cefcdd75137b96bcaf94116","price":"8718.20000000000000000000","time":"1559219673560690145","type":"done"}
2019/05/30 14:34:33 [Info] msg: {"sequence":"1556329021440","symbol":"BTC-USDT","reason":"canceled","side":"buy","size":"0.0513306","orderId":"5cefcdd84c06872c53322ff2","price":"8718.10000000000000000000","time":"1559219673560707202","type":"done"}
2019/05/30 14:34:33 [Info] msg: {"sequence":"1556329021441","symbol":"BTC-USDT","reason":"canceled","side":"buy","size":"0.0065115","orderId":"5cefcdd75137b96b7e1e2bd2","price":"8718.60000000000000000000","time":"1559219673581958577","type":"done"}
2019/05/30 14:34:33 [Info] msg: {"sequence":"1556329021442","symbol":"BTC-USDT","reason":"canceled","side":"buy","size":"0.0388314","orderId":"5cefcdd7054b463a72e7b14f","price":"8718.40000000000000000000","time":"1559219673591776711","type":"done"}
2019/05/30 14:34:33 [Info] msg: {"sequence":"1556329021461","symbol":"BTC-USDT","reason":"canceled","side":"buy","size":"0.078696","orderId":"5cefcdd6054b463aaf90a1e0","price":"8720.10000000000000000000","time":"1559219673718310944","type":"done"}
2019/05/30 14:34:34 [Info] msg: {"sequence":"1556329021466","symbol":"BTC-USDT","reason":"canceled","side":"sell","size":"0.068756","orderId":"5cefcdd8054b463aaf90a241","price":"8728.40000000000000000000","time":"1559219673896712086","type":"done"}
2019/05/30 14:34:34 [Info] msg: {"sequence":"1556329021467","symbol":"BTC-USDT","reason":"canceled","side":"buy","size":"0.0899","orderId":"5cefcdd6cdaba43a1e148ddf","price":"8706.90000000000000000000","time":"1559219674071726864","type":"done"}
2019/05/30 14:34:34 [Info] msg: {"sequence":"1556329021470","symbol":"BTC-USDT","reason":"canceled","side":"buy","size":"0.02416959","orderId":"5cefcdb2c788c671eab3c5e8","price":"8714.90000000000000000000","time":"1559219674124636071","type":"done"}
2019/05/30 14:34:34 [Info] msg: {"sequence":"1556329021471","symbol":"BTC-USDT","reason":"canceled","side":"sell","size":"0.05","orderId":"5cefcdd30bad452ac338d476","price":"8726.90000000000000000000","time":"1559219674155654799","type":"done"}
2019/05/30 14:34:34 [Info] msg: {"sequence":"1556329021474","symbol":"BTC-USDT","reason":"canceled","side":"sell","size":"0.7211016","orderId":"5cefcdd9054b463aaf90a278","price":"8735.00000000000000000000","time":"1559219674508581639","type":"done"}
2019/05/30 14:34:34 [Info] msg: {"sequence":"1556329021475","symbol":"BTC-USDT","reason":"canceled","side":"sell","size":"0.6915906","orderId":"5cefcdd7c788c671b05d09f1","price":"8734.70000000000000000000","time":"1559219674508674069","type":"done"}
2019/05/30 14:34:34 [Info] msg: {"sequence":"1556329021476","symbol":"BTC-USDT","reason":"canceled","side":"buy","size":"0.4984515","orderId":"5cefcdd9054b463aaf90a26f","price":"8716.30000000000000000000","time":"1559219674508693475","type":"done"}
2019/05/30 14:34:34 [Info] msg: {"sequence":"1556329021477","symbol":"BTC-USDT","reason":"canceled","side":"buy","size":"0.00611588","orderId":"5cefcdd9054b463aaf90a27b","price":"8717.20000000000000000000","time":"1559219674519268337","type":"done"}
2019/05/30 14:34:34 [Info] msg: {"sequence":"1556329021478","symbol":"BTC-USDT","reason":"canceled","side":"buy","size":"0.1190727","orderId":"5cefcdd9c788c671eab3cfe3","price":"8715.90000000000000000000","time":"1559219674519346955","type":"done"}
2019/05/30 14:34:34 [Info] msg: {"sequence":"1556329021479","symbol":"BTC-USDT","reason":"canceled","side":"sell","size":"0.00953668","orderId":"5cefcdd60bad452af7db2e0c","price":"8733.60000000000000000000","time":"1559219674519365022","type":"done"}
2019/05/30 14:34:34 [Info] msg: {"sequence":"1556329021480","symbol":"BTC-USDT","reason":"canceled","side":"buy","size":"0.6706386","orderId":"5cefcdd9c788c671b05d0a6e","price":"8716.00000000000000000000","time":"1559219674519382941","type":"done"}
2019/05/30 14:34:34 [Info] msg: {"sequence":"1556329021481","symbol":"BTC-USDT","reason":"canceled","side":"buy","size":"0.2856267","orderId":"5cefcdd90bad452ac338d63e","price":"8716.20000000000000000000","time":"1559219674540464473","type":"done"}
2019/05/30 14:34:35 [Info] msg: {"sequence":"1556329021500","symbol":"BTC-USDT","reason":"canceled","side":"sell","size":"0.9","orderId":"5cefcdda5137b96b7e1e2c6b","price":"8734.90000000000000000000","time":"1559219675576374874","type":"done"}
2019/05/30 14:34:35 [Info] msg: {"sequence":"1556329021501","symbol":"BTC-USDT","reason":"canceled","side":"sell","size":"0.00600941","orderId":"5cefcdda89fc8463508998e8","price":"8733.60000000000000000000","time":"1559219675576480928","type":"done"}
2019/05/30 14:34:35 [Info] msg: {"sequence":"1556329021502","symbol":"BTC-USDT","reason":"canceled","side":"sell","size":"0.1507617","orderId":"5cefcdd4cdaba439e54e851f","price":"8734.60000000000000000000","time":"1559219675576502965","type":"done"}
2019/05/30 14:34:35 [Info] msg: {"sequence":"1556329021503","symbol":"BTC-USDT","reason":"canceled","side":"sell","size":"0.0479331","orderId":"5cefcdda5137b96b7e1e2c71","price":"8735.00000000000000000000","time":"1559219675576518459","type":"done"}
2019/05/30 14:34:35 [Info] msg: {"sequence":"1556329021504","symbol":"BTC-USDT","reason":"canceled","side":"buy","size":"3.3356385","orderId":"5cefcdda054b463aaf90a2cd","price":"8715.80000000000000000000","time":"1559219675576532301","type":"done"}
2019/05/30 14:34:35 [Info] msg: {"sequence":"1556329021505","symbol":"BTC-USDT","reason":"canceled","side":"buy","size":"0.0513306","orderId":"5cefcdda5137b96bcaf941b9","price":"8715.70000000000000000000","time":"1559219675576551728","type":"done"}
2019/05/30 14:34:35 [Info] msg: {"sequence":"1556329021506","symbol":"BTC-USDT","reason":"canceled","side":"buy","size":"0.1190727","orderId":"5cefcdda5137b96b7e1e2c74","price":"8716.20000000000000000000","time":"1559219675608337711","type":"done"}
2019/05/30 14:34:36 [Info] msg: {"sequence":"1556329021523","symbol":"BTC-USDT","reason":"canceled","side":"buy","size":"0.0388314","orderId":"5cefcdda0bad452ac338d685","price":"8715.90000000000000000000","time":"1559219676556316200","type":"done"}
2019/05/30 14:34:36 [Info] msg: {"sequence":"1556329021524","symbol":"BTC-USDT","reason":"canceled","side":"buy","size":"0.30000000","orderId":"5cefcdcd5137b96bcaf93e79","price":"8719.10000000000000000000","time":"1559219676567350455","type":"done"}
2019/05/30 14:34:36 [Info] msg: {"sequence":"1556329021525","symbol":"BTC-USDT","reason":"canceled","side":"buy","size":"0.0513306","orderId":"5cefcddbcdaba439e54e86b1","price":"8716.00000000000000000000","time":"1559219676577873865","type":"done"}
2019/05/30 14:34:37 [Info] msg: {"sequence":"1556329021530","symbol":"BTC-USDT","reason":"canceled","side":"buy","size":"0.1125","orderId":"5cefcdd95137b96b7e1e2c35","price":"8717.50000000000000000000","time":"1559219677377139342","type":"done"}
2019/05/30 14:34:37 [Info] msg: {"sequence":"1556329021531","symbol":"BTC-USDT","reason":"canceled","side":"buy","size":"0.1228","orderId":"5cefcdd9cdaba43a1e148eab","price":"8717.40000000000000000000","time":"1559219677377283030","type":"done"}
2019/05/30 14:34:37 [Info] msg: {"sequence":"1556329021532","symbol":"BTC-USDT","reason":"canceled","side":"buy","size":"0.45","orderId":"5cefcddc0bad452ac338d6f1","price":"8715.60000000000000000000","time":"1559219677491037092","type":"done"}
2019/05/30 14:34:38 [Info] msg: {"sequence":"1556329021535","symbol":"BTC-USDT","reason":"canceled","side":"sell","size":"0.0001","orderId":"5cefcdd6054b463a72e7b0e1","price":"8721.60000000000000000000","time":"1559219677933685650","type":"done"}
2019/05/30 14:34:38 [Info] msg: {"sequence":"1556329021536","symbol":"BTC-USDT","reason":"canceled","side":"sell","size":"0.0001","orderId":"5cefcdd95137b96bcaf9418e","price":"8721.50000000000000000000","time":"1559219677933790827","type":"done"}
2019/05/30 14:34:38 [Info] msg: {"sequence":"1556329021541","symbol":"BTC-USDT","reason":"canceled","side":"sell","size":"0.148722","orderId":"5cefcdd94c06872c1359d961","price":"8731.70000000000000000000","time":"1559219678062124392","type":"done"}
2019/05/30 14:34:38 [Info] msg: {"sequence":"1556329021545","symbol":"BTC-USDT","reason":"canceled","side":"buy","size":"0.0899","orderId":"5cefcddacdaba439e54e866d","price":"8707.00000000000000000000","time":"1559219678084333752","type":"done"}
2019/05/30 14:34:38 [Info] msg: {"sequence":"1556329021546","symbol":"BTC-USDT","reason":"canceled","side":"sell","size":"0.099975","orderId":"5cefcdc789fc846350899427","price":"8734.20000000000000000000","time":"1559219678094442171","type":"done"}
2019/05/30 14:34:38 [Info] msg: {"sequence":"1556329021553","symbol":"BTC-USDT","reason":"canceled","side":"sell","size":"0.228665","orderId":"5cefcdc7c788c671eab3cb31","price":"8735.90000000000000000000","time":"1559219678277503859","type":"done"}
2019/05/30 14:34:38 [Info] msg: {"sequence":"1556329021556","symbol":"BTC-USDT","reason":"canceled","side":"buy","size":"0.6178221","orderId":"5cefcddb4c06872c1359d9e6","price":"8715.80000000000000000000","time":"1559219678424268053","type":"done"}
2019/05/30 14:34:38 [Info] msg: {"sequence":"1556329021557","symbol":"BTC-USDT","reason":"canceled","side":"buy","size":"0.0513306","orderId":"5cefcdddcdaba43a1e148fa6","price":"8715.60000000000000000000","time":"1559219678424366007","type":"done"}
2019/05/30 14:34:38 [Info] msg: {"sequence":"1556329021562","symbol":"BTC-USDT","reason":"canceled","side":"buy","size":"0.1228","orderId":"5cefcddd054b463a72e7b2e7","price":"8717.50000000000000000000","time":"1559219678476546490","type":"done"}
2019/05/30 14:34:38 [Info] msg: {"sequence":"1556329021563","symbol":"BTC-USDT","reason":"canceled","side":"buy","size":"0.1125","orderId":"5cefcdddcdaba43a1e148fbc","price":"8717.60000000000000000000","time":"1559219678487606277","type":"done"}
2019/05/30 14:34:39 [Info] msg: {"sequence":"1556329021566","symbol":"BTC-USDT","reason":"canceled","side":"buy","size":"0.00935477","orderId":"5cefcdda054b463a72e7b1ed","price":"8717.10000000000000000000","time":"1559219679361723584","type":"done"}
2019/05/30 14:34:39 [Info] msg: {"sequence":"1556329021567","symbol":"BTC-USDT","reason":"canceled","side":"buy","size":"0.0249759","orderId":"5cefcddb89fc846389b10f45","price":"8716.20000000000000000000","time":"1559219679361826832","type":"done"}
2019/05/30 14:34:39 [Info] msg: {"sequence":"1556329021568","symbol":"BTC-USDT","reason":"canceled","side":"buy","size":"0.225","orderId":"5cefcdd90bad452af7db2ec9","price":"8716.10000000000000000000","time":"1559219679361851425","type":"done"}
2019/05/30 14:34:39 [Info] msg: {"sequence":"1556329021569","symbol":"BTC-USDT","reason":"canceled","side":"buy","size":"0.0443475","orderId":"5cefcddecdaba43a1e148fe9","price":"8715.80000000000000000000","time":"1559219679383048199","type":"done"}
2019/05/30 14:34:39 [Info] msg: {"sequence":"1556329021578","symbol":"BTC-USDT","reason":"canceled","side":"buy","size":"0.229218","orderId":"5cefcdde0bad452ac338d747","price":"8720.00000000000000000000","time":"1559219679549840619","type":"done"}
2019/05/30 14:34:39 [Info] msg: {"sequence":"1556329021589","symbol":"BTC-USDT","reason":"canceled","side":"buy","size":"0.206296","orderId":"5cefcdde054b463aaf90a379","price":"8719.90000000000000000000","time":"1559219679711427207","type":"done"}
2019/05/30 14:34:40 [Info] msg: {"sequence":"1556329021592","symbol":"BTC-USDT","reason":"canceled","side":"sell","size":"0.091687","orderId":"5cefcdd9cdaba43a1e148eaf","price":"8730.30000000000000000000","time":"1559219680049122004","type":"done"}
2019/05/30 14:34:40 [Info] msg: {"sequence":"1556329021595","symbol":"BTC-USDT","reason":"canceled","side":"sell","size":"0.068765","orderId":"5cefcddb4c06872c1359d9e0","price":"8727.20000000000000000000","time":"1559219680358877247","type":"done"}
2019/05/30 14:34:40 [Info] msg: {"sequence":"1556329021596","symbol":"BTC-USDT","reason":"canceled","side":"sell","size":"0.7211016","orderId":"5cefcddb054b463aaf90a2fe","price":"8734.40000000000000000000","time":"1559219680400710716","type":"done"}
2019/05/30 14:34:40 [Info] msg: {"sequence":"1556329021597","symbol":"BTC-USDT","reason":"canceled","side":"buy","size":"0.0513306","orderId":"5cefcddc054b463a72e7b284","price":"8715.70000000000000000000","time":"1559219680400809146","type":"done"}
2019/05/30 14:34:40 [Info] msg: {"sequence":"1556329021598","symbol":"BTC-USDT","reason":"canceled","side":"buy","size":"0.0252432","orderId":"5cefcddf0bad452af7db3037","price":"8715.80000000000000000000","time":"1559219680400865873","type":"done"}
2019/05/30 14:34:40 [Info] msg: {"sequence":"1556329021599","symbol":"BTC-USDT","reason":"canceled","side":"buy","size":"0.00992135","orderId":"5cefcddf054b463a72e7b34d","price":"8716.90000000000000000000","time":"1559219680400881554","type":"done"}
2019/05/30 14:34:40 [Info] msg: {"sequence":"1556329021600","symbol":"BTC-USDT","reason":"canceled","side":"sell","size":"0.1602","orderId":"5cefcddbc788c671b05d0ada","price":"8734.70000000000000000000","time":"1559219680400896118","type":"done"}
2019/05/30 14:34:40 [Info] msg: {"sequence":"1556329021601","symbol":"BTC-USDT","reason":"canceled","side":"buy","size":"3.3356385","orderId":"5cefcddf5137b96bcaf942bc","price":"8715.60000000000000000000","time":"1559219680400913035","type":"done"}
2019/05/30 14:34:40 [Info] msg: {"sequence":"1556329021616","symbol":"BTC-USDT","reason":"canceled","side":"sell","size":"0.045843","orderId":"5cefcdd90bad452ac338d611","price":"8726.70000000000000000000","time":"1559219680642424697","type":"done"}
2019/05/30 14:34:40 [Info] msg: {"sequence":"1556329021617","symbol":"BTC-USDT","reason":"canceled","side":"sell","size":"0.0001","orderId":"5cefcddf89fc846350899a50","price":"8721.60000000000000000000","time":"1559219680673878537","type":"done"}
2019/05/30 14:34:41 [Info] msg: {"sequence":"1556329021620","symbol":"BTC-USDT","reason":"canceled","side":"sell","size":"0.02416959","orderId":"5cefcdb95137b96bcaf9398e","price":"8745.20000000000000000000","time":"1559219681139753869","type":"done"}
2019/05/30 14:34:41 [Info] msg: {"sequence":"1556329021621","symbol":"BTC-USDT","reason":"canceled","side":"sell","size":"0.0001","orderId":"5cefcdde5137b96b7e1e2d59","price":"8721.70000000000000000000","time":"1559219681150400590","type":"done"}
2019/05/30 14:34:41 [Info] msg: {"sequence":"1556329021622","symbol":"BTC-USDT","reason":"canceled","side":"sell","size":"0.05","orderId":"5cefcdda89fc846389b10ef6","price":"8726.70000000000000000000","time":"1559219681150499883","type":"done"}
2019/05/30 14:34:41 [Info] msg: {"sequence":"1556329021623","symbol":"BTC-USDT","reason":"canceled","side":"buy","size":"0.1228","orderId":"5cefcddfcdaba43a1e149024","price":"8717.40000000000000000000","time":"1559219681161157776","type":"done"}
2019/05/30 14:34:41 [Info] msg: {"sequence":"1556329021626","symbol":"BTC-USDT","reason":"canceled","side":"buy","size":"0.1125","orderId":"5cefcddf5137b96bcaf942c8","price":"8717.40000000000000000000","time":"1559219681217302950","type":"done"}
2019/05/30 14:34:41 [Info] msg: {"sequence":"1556329021629","symbol":"BTC-USDT","reason":"canceled","side":"buy","size":"0.00779718","orderId":"5cefcde04c06872c1359db3d","price":"8717.20000000000000000000","time":"1559219681403194394","type":"done"}
2019/05/30 14:34:41 [Info] msg: {"sequence":"1556329021630","symbol":"BTC-USDT","reason":"canceled","side":"sell","size":"1.1803743","orderId":"5cefcde00bad452af7db3076","price":"8734.60000000000000000000","time":"1559219681413912516","type":"done"}
2019/05/30 14:34:41 [Info] msg: {"sequence":"1556329021631","symbol":"BTC-USDT","reason":"canceled","side":"buy","size":"0.0185733","orderId":"5cefcddfc788c671eab3d13e","price":"8715.90000000000000000000","time":"1559219681427481731","type":"done"}
2019/05/30 14:34:41 [Info] msg: {"sequence":"1556329021632","symbol":"BTC-USDT","reason":"canceled","side":"buy","size":"0.2856267","orderId":"5cefcde0cdaba43a1e14905d","price":"8716.20000000000000000000","time":"1559219681438062275","type":"done"}
2019/05/30 14:34:42 [Info] msg: {"sequence":"1556329021651","symbol":"BTC-USDT","reason":"canceled","side":"buy","size":"0.039","orderId":"5cefcdd84c06872c53322fde","price":"8714.90000000000000000000","time":"1559219681897397371","type":"done"}
2019/05/30 14:34:42 [Info] msg: {"sequence":"1556329021652","symbol":"BTC-USDT","reason":"canceled","side":"buy","size":"0.0899","orderId":"5cefcdde89fc8463508999e2","price":"8707.10000000000000000000","time":"1559219682077567768","type":"done"}
2019/05/30 14:34:42 [Info] msg: {"sequence":"1556329021653","symbol":"BTC-USDT","reason":"canceled","side":"sell","size":"0.05","orderId":"5cefcde10bad452af7db30b1","price":"8726.90000000000000000000","time":"1559219682099786063","type":"done"}
2019/05/30 14:34:42 [Info] msg: {"sequence":"1556329021656","symbol":"BTC-USDT","reason":"canceled","side":"sell","size":"0.02083041","orderId":"5cefcdd0cdaba43a1e148c6f","price":"8726.80000000000000000000","time":"1559219682130702638","type":"done"}
2019/05/30 14:34:42 [Info] msg: {"sequence":"1556329021661","symbol":"BTC-USDT","reason":"canceled","side":"buy","size":"0.039","orderId":"5cefcde189fc846350899ac8","price":"8715.90000000000000000000","time":"1559219682214745516","type":"done"}
2019/05/30 14:34:42 [Info] msg: {"sequence":"1556329021662","symbol":"BTC-USDT","reason":"canceled","side":"sell","size":"0.148726","orderId":"5cefcddf5137b96bcaf942d7","price":"8731.50000000000000000000","time":"1559219682236040471","type":"done"}
2019/05/30 14:34:42 [Info] msg: {"sequence":"1556329021665","symbol":"BTC-USDT","reason":"canceled","side":"sell","size":"0.1507617","orderId":"5cefcdd7054b463a72e7b144","price":"8734.80000000000000000000","time":"1559219682402322444","type":"done"}
2019/05/30 14:34:42 [Info] msg: {"sequence":"1556329021666","symbol":"BTC-USDT","reason":"canceled","side":"sell","size":"0.00669348","orderId":"5cefcddb5137b96bcaf941ee","price":"8733.50000000000000000000","time":"1559219682402403042","type":"done"}
2019/05/30 14:34:42 [Info] msg: {"sequence":"1556329021667","symbol":"BTC-USDT","reason":"canceled","side":"sell","size":"0.0479331","orderId":"5cefcdd75137b96b7e1e2bc9","price":"8734.50000000000000000000","time":"1559219682402424526","type":"done"}
2019/05/30 14:34:42 [Info] msg: {"sequence":"1556329021668","symbol":"BTC-USDT","reason":"canceled","side":"buy","size":"0.612396","orderId":"5cefcde0cdaba439e54e87cc","price":"8716.30000000000000000000","time":"1559219682412919146","type":"done"}
2019/05/30 14:34:42 [Info] msg: {"sequence":"1556329021669","symbol":"BTC-USDT","reason":"canceled","side":"sell","size":"0.1602","orderId":"5cefcde1cdaba43a1e14909d","price":"8735.10000000000000000000","time":"1559219682412993385","type":"done"}
2019/05/30 14:34:42 [Info] msg: {"sequence":"1556329021670","symbol":"BTC-USDT","reason":"canceled","side":"buy","size":"0.00528067","orderId":"5cefcde14c06872c1359db8e","price":"8717.30000000000000000000","time":"1559219682413013683","type":"done"}
2019/05/30 14:34:42 [Info] msg: {"sequence":"1556329021671","symbol":"BTC-USDT","reason":"canceled","side":"sell","size":"0.0479331","orderId":"5cefcddb054b463aaf90a301","price":"8734.90000000000000000000","time":"1559219682413028778","type":"done"}
2019/05/30 14:34:42 [Info] msg: {"sequence":"1556329021686","symbol":"BTC-USDT","reason":"canceled","side":"sell","size":"0.0001","orderId":"5cefcde10bad452af7db30cc","price":"8721.50000000000000000000","time":"1559219682801284741","type":"done"}
2019/05/30 14:34:42 [Info] msg: {"sequence":"1556329021687","symbol":"BTC-USDT","reason":"canceled","side":"sell","size":"0.0001","orderId":"5cefcde1054b463aaf90a410","price":"8721.60000000000000000000","time":"1559219682812006671","type":"done"}
2019/05/30 14:34:43 [Info] msg: {"sequence":"1556329021690","symbol":"BTC-USDT","reason":"canceled","side":"buy","size":"0.039","orderId":"5cefcde20bad452af7db30e5","price":"8716.00000000000000000000","time":"1559219682863437997","type":"done"}
2019/05/30 14:34:43 [Info] msg: {"sequence":"1556329021697","symbol":"BTC-USDT","reason":"canceled","side":"sell","size":"0.3101121","orderId":"5cefcde25137b96bcaf94374","price":"8735.40000000000000000000","time":"1559219683461047565","type":"done"}
2019/05/30 14:34:43 [Info] msg: {"sequence":"1556329021698","symbol":"BTC-USDT","reason":"canceled","side":"sell","size":"2.5255188","orderId":"5cefcde20bad452af7db30f2","price":"8735.50000000000000000000","time":"1559219683461135688","type":"done"}
2019/05/30 14:34:43 [Info] msg: {"sequence":"1556329021699","symbol":"BTC-USDT","reason":"canceled","side":"sell","size":"0.7211016","orderId":"5cefcde2cdaba439e54e8845","price":"8735.80000000000000000000","time":"1559219683461155343","type":"done"}
2019/05/30 14:34:43 [Info] msg: {"sequence":"1556329021700","symbol":"BTC-USDT","reason":"canceled","side":"sell","size":"0.45","orderId":"5cefcde2c788c671b05d0c70","price":"8735.30000000000000000000","time":"1559219683470716002","type":"done"}
2019/05/30 14:34:43 [Info] msg: {"sequence":"1556329021701","symbol":"BTC-USDT","reason":"canceled","side":"sell","size":"0.8363709","orderId":"5cefcde25137b96b7e1e2e41","price":"8735.60000000000000000000","time":"1559219683470806775","type":"done"}
2019/05/30 14:34:43 [Info] msg: {"sequence":"1556329021702","symbol":"BTC-USDT","reason":"canceled","side":"sell","size":"0.0065772","orderId":"5cefcde089fc846350899a78","price":"8734.40000000000000000000","time":"1559219683470826779","type":"done"}
2019/05/30 14:34:43 [Info] msg: {"sequence":"1556329021703","symbol":"BTC-USDT","reason":"canceled","side":"buy","size":"0.225","orderId":"5cefcde04c06872c533231d6","price":"8716.10000000000000000000","time":"1559219683481530404","type":"done"}
2019/05/30 14:34:43 [Info] msg: {"sequence":"1556329021704","symbol":"BTC-USDT","reason":"canceled","side":"buy","size":"0.1190727","orderId":"5cefcde15137b96bcaf94341","price":"8716.20000000000000000000","time":"1559219683481610826","type":"done"}
2019/05/30 14:34:43 [Info] msg: {"sequence":"1556329021705","symbol":"BTC-USDT","reason":"canceled","side":"buy","size":"0.00751995","orderId":"5cefcde2c788c671b05d0c73","price":"8717.40000000000000000000","time":"1559219683481629173","type":"done"}
2019/05/30 14:34:43 [Info] msg: {"sequence":"1556329021706","symbol":"BTC-USDT","reason":"canceled","side":"buy","size":"0.0185733","orderId":"5cefcdde0bad452ac338d76c","price":"8716.00000000000000000000","time":"1559219683481643305","type":"done"}
2019/05/30 14:34:43 [Info] msg: {"sequence":"1556329021707","symbol":"BTC-USDT","reason":"canceled","side":"buy","size":"0.225","orderId":"5cefcde15137b96b7e1e2e06","price":"8716.40000000000000000000","time":"1559219683492063347","type":"done"}
2019/05/30 14:34:44 [Info] msg: {"sequence":"1556329021734","symbol":"BTC-USDT","reason":"canceled","side":"sell","size":"0.099993","orderId":"5cefcddf5137b96b7e1e2dac","price":"8732.60000000000000000000","time":"1559219684016178431","type":"done"}
2019/05/30 14:34:44 [Info] msg: {"sequence":"1556329021737","symbol":"BTC-USDT","reason":"canceled","side":"buy","size":"0.039","orderId":"5cefcde2c788c671b05d0c85","price":"8712.60000000000000000000","time":"1559219684140234626","type":"done"}
2019/05/30 14:34:44 [Info] msg: {"sequence":"1556329021740","symbol":"BTC-USDT","reason":"canceled","side":"buy","size":"0.1228","orderId":"5cefcde1054b463aaf90a43f","price":"8718.50000000000000000000","time":"1559219684411429840","type":"done"}
2019/05/30 14:34:44 [Info] msg: {"sequence":"1556329021743","symbol":"BTC-USDT","reason":"canceled","side":"buy","size":"0.1125","orderId":"5cefcde1c788c671b05d0c35","price":"8718.50000000000000000000","time":"1559219684463700177","type":"done"}
2019/05/30 14:34:44 [Info] msg: {"sequence":"1556329021744","symbol":"BTC-USDT","reason":"canceled","side":"sell","size":"0.00919315","orderId":"5cefcde389fc846350899b2e","price":"8733.50000000000000000000","time":"1559219684474207131","type":"done"}
2019/05/30 14:34:44 [Info] msg: {"sequence":"1556329021745","symbol":"BTC-USDT","reason":"canceled","side":"sell","size":"0.00500258","orderId":"5cefcde3054b463a72e7b445","price":"8734.40000000000000000000","time":"1559219684484936635","type":"done"}
2019/05/30 14:34:44 [Info] msg: {"sequence":"1556329021746","symbol":"BTC-USDT","reason":"canceled","side":"sell","size":"0.6045237","orderId":"5cefcde30bad452ac338d8af","price":"8734.60000000000000000000","time":"1559219684485015762","type":"done"}
2019/05/30 14:34:44 [Info] msg: {"sequence":"1556329021747","symbol":"BTC-USDT","reason":"canceled","side":"sell","size":"0.45","orderId":"5cefcde389fc846389b1110b","price":"8734.70000000000000000000","time":"1559219684485036185","type":"done"}
2019/05/30 14:34:44 [Info] msg: {"sequence":"1556329021748","symbol":"BTC-USDT","reason":"canceled","side":"sell","size":"0.2307006","orderId":"5cefcde34c06872c1359dc13","price":"8734.80000000000000000000","time":"1559219684485050466","type":"done"}
2019/05/30 14:34:44 [Info] msg: {"sequence":"1556329021749","symbol":"BTC-USDT","reason":"canceled","side":"buy","size":"1.0526481","orderId":"5cefcde3cdaba43a1e149103","price":"8716.90000000000000000000","time":"1559219684516866909","type":"done"}
2019/05/30 14:34:44 [Info] msg: {"sequence":"1556329021750","symbol":"BTC-USDT","reason":"canceled","side":"buy","size":"0.0431667","orderId":"5cefcde3cdaba439e54e889f","price":"8716.80000000000000000000","time":"1559219684516956803","type":"done"}
2019/05/30 14:34:44 [Info] msg: {"sequence":"1556329021751","symbol":"BTC-USDT","reason":"canceled","side":"buy","size":"3.65388595","orderId":"5cefcde3054b463aaf90a4a4","price":"8716.70000000000000000000","time":"1559219684516975699","type":"done"}
2019/05/30 14:34:44 [Info] msg: {"sequence":"1556329021752","symbol":"BTC-USDT","reason":"canceled","side":"buy","size":"0.00964564","orderId":"5cefcde34c06872c533232a1","price":"8717.80000000000000000000","time":"1559219684516990892","type":"done"}
2019/05/30 14:34:44 [Info] msg: {"sequence":"1556329021753","symbol":"BTC-USDT","reason":"canceled","side":"buy","size":"0.3994029","orderId":"5cefcde3c788c671b05d0cdc","price":"8716.60000000000000000000","time":"1559219684517005168","type":"done"}
2019/05/30 14:34:44 [Info] msg: {"sequence":"1556329021754","symbol":"BTC-USDT","reason":"canceled","side":"buy","size":"0.0513306","orderId":"5cefcde24c06872c1359dbbd","price":"8716.50000000000000000000","time":"1559219684517018611","type":"done"}
2019/05/30 14:34:44 [Info] msg: {"sequence":"1556329021777","symbol":"BTC-USDT","reason":"canceled","side":"sell","size":"0.068763","orderId":"5cefcde35137b96b7e1e2e75","price":"8727.50000000000000000000","time":"1559219684740713470","type":"done"}
2019/05/30 14:34:45 [Info] msg: {"sequence":"1556329021778","symbol":"BTC-USDT","reason":"canceled","side":"sell","size":"0.0001","orderId":"5cefcde3cdaba439e54e88b1","price":"8723.20000000000000000000","time":"1559219684938038837","type":"done"}
2019/05/30 14:34:45 [Info] msg: {"sequence":"1556329021781","symbol":"BTC-USDT","reason":"canceled","side":"sell","size":"0.228694","orderId":"5cefcde3cdaba439e54e887f","price":"8734.80000000000000000000","time":"1559219685070240816","type":"done"}
2019/05/30 14:34:45 [Info] msg: {"sequence":"1556329021782","symbol":"BTC-USDT","reason":"canceled","side":"buy","size":"0.229218","orderId":"5cefcddec788c671b05d0b6d","price":"8716.20000000000000000000","time":"1559219685084938762","type":"done"}
2019/05/30 14:34:45 [Info] msg: {"sequence":"1556329021783","symbol":"BTC-USDT","reason":"canceled","side":"sell","size":"0.091684","orderId":"5cefcde3cdaba43a1e1490f9","price":"8730.50000000000000000000","time":"1559219685345854011","type":"done"}
2019/05/30 14:34:45 [Info] msg: {"sequence":"1556329021784","symbol":"BTC-USDT","reason":"canceled","side":"buy","size":"0.229217","orderId":"5cefcde1cdaba43a1e14908a","price":"8720.00000000000000000000","time":"1559219685428278512","type":"done"}
2019/05/30 14:34:45 [Info] msg: {"sequence":"1556329021789","symbol":"BTC-USDT","reason":"canceled","side":"sell","size":"0.6237837","orderId":"5cefcde489fc846389b11147","price":"8735.80000000000000000000","time":"1559219685615969821","type":"done"}
2019/05/30 14:34:45 [Info] msg: {"sequence":"1556329021790","symbol":"BTC-USDT","reason":"canceled","side":"sell","size":"0.1602","orderId":"5cefcde3c788c671b05d0cc3","price":"8734.50000000000000000000","time":"1559219685616065531","type":"done"}
2019/05/30 14:34:45 [Info] msg: {"sequence":"1556329021791","symbol":"BTC-USDT","reason":"canceled","side":"sell","size":"0.1602","orderId":"5cefcde489fc846350899b7d","price":"8736.00000000000000000000","time":"1559219685616086244","type":"done"}
2019/05/30 14:34:46 [Info] msg: {"sequence":"1556329021798","symbol":"BTC-USDT","reason":"canceled","side":"buy","size":"0.1125","orderId":"5cefcde40bad452ac338d91f","price":"8718.90000000000000000000","time":"1559219686022441036","type":"done"}
2019/05/30 14:34:46 [Info] msg: {"sequence":"1556329021803","symbol":"BTC-USDT","reason":"canceled","side":"buy","size":"0.0899","orderId":"5cefcde24c06872c53323238","price":"8707.30000000000000000000","time":"1559219686535354720","type":"done"}
2019/05/30 14:34:46 [Info] msg: {"sequence":"1556329021804","symbol":"BTC-USDT","reason":"canceled","side":"buy","size":"0.1228","orderId":"5cefcde54c06872c1359dc93","price":"8718.90000000000000000000","time":"1559219686555597149","type":"done"}
2019/05/30 14:34:46 [Info] msg: {"sequence":"1556329021807","symbol":"BTC-USDT","reason":"canceled","side":"sell","size":"0.0001","orderId":"5cefcde4cdaba439e54e88d8","price":"8723.10000000000000000000","time":"1559219686609311695","type":"done"}
2019/05/30 14:34:46 [Info] msg: {"sequence":"1556329021808","symbol":"BTC-USDT","reason":"canceled","side":"buy","size":"0.00679971","orderId":"5cefcde40bad452ac338d907","price":"8719.40000000000000000000","time":"1559219686651105911","type":"done"}
2019/05/30 14:34:46 [Info] msg: {"sequence":"1556329021809","symbol":"BTC-USDT","reason":"canceled","side":"sell","size":"0.6237837","orderId":"5cefcde5cdaba439e54e8929","price":"8735.70000000000000000000","time":"1559219686651187940","type":"done"}
2019/05/30 14:34:46 [Info] msg: {"sequence":"1556329021810","symbol":"BTC-USDT","reason":"canceled","side":"sell","size":"0.7316811","orderId":"5cefcde4cdaba439e54e88e5","price":"8735.60000000000000000000","time":"1559219686651211348","type":"done"}
2019/05/30 14:34:46 [Info] msg: {"sequence":"1556329021811","symbol":"BTC-USDT","reason":"canceled","side":"sell","size":"0.1602","orderId":"5cefcde5c788c671eab3d2e6","price":"8735.90000000000000000000","time":"1559219686651226506","type":"done"}
2019/05/30 14:34:46 [Info] msg: {"sequence":"1556329021812","symbol":"BTC-USDT","reason":"canceled","side":"buy","size":"3.60110036","orderId":"5cefcde44c06872c1359dc5c","price":"8718.40000000000000000000","time":"1559219686651240413","type":"done"}
2019/05/30 14:34:46 [Info] msg: {"sequence":"1556329021813","symbol":"BTC-USDT","reason":"canceled","side":"buy","size":"0.3994029","orderId":"5cefcde4cdaba439e54e88e9","price":"8718.10000000000000000000","time":"1559219686651255454","type":"done"}
2019/05/30 14:34:47 [Info] msg: {"sequence":"1556329021832","symbol":"BTC-USDT","reason":"canceled","side":"sell","size":"0.02083041","orderId":"5cefcdbec788c671b05d0400","price":"8727.00000000000000000000","time":"1559219687162584445","type":"done"}
2019/05/30 14:34:47 [Info] msg: {"sequence":"1556329021833","symbol":"BTC-USDT","reason":"canceled","side":"sell","size":"0.05","orderId":"5cefcde289fc846389b110cc","price":"8726.90000000000000000000","time":"1559219687184165644","type":"done"}
2019/05/30 14:34:47 [Info] msg: {"sequence":"1556329021838","symbol":"BTC-USDT","reason":"canceled","side":"buy","size":"0.0082352","orderId":"5cefcde689fc846350899bf7","price":"8719.50000000000000000000","time":"1559219687683779613","type":"done"}
2019/05/30 14:34:47 [Info] msg: {"sequence":"1556329021839","symbol":"BTC-USDT","reason":"canceled","side":"buy","size":"0.0675","orderId":"5cefcde689fc846389b111cb","price":"8718.60000000000000000000","time":"1559219687683878253","type":"done"}
2019/05/30 14:34:47 [Info] msg: {"sequence":"1556329021840","symbol":"BTC-USDT","reason":"canceled","side":"buy","size":"0.5719509","orderId":"5cefcde489fc846350899b80","price":"8718.50000000000000000000","time":"1559219687694592968","type":"done"}
2019/05/30 14:34:48 [Info] msg: {"sequence":"1556329021857","symbol":"BTC-USDT","reason":"canceled","side":"sell","size":"0.3101121","orderId":"5cefcde44c06872c1359dc59","price":"8735.40000000000000000000","time":"1559219688623403811","type":"done"}
2019/05/30 14:34:48 [Info] msg: {"sequence":"1556329021858","symbol":"BTC-USDT","reason":"canceled","side":"buy","size":"0.00844461","orderId":"5cefcde7cdaba43a1e1491d8","price":"8719.60000000000000000000","time":"1559219688654593160","type":"done"}
2019/05/30 14:34:48 [Info] msg: {"sequence":"1556329021859","symbol":"BTC-USDT","reason":"canceled","side":"sell","size":"0.45","orderId":"5cefcde65137b96b7e1e2f32","price":"8735.70000000000000000000","time":"1559219688665018405","type":"done"}
2019/05/30 14:34:48 [Info] msg: {"sequence":"1556329021860","symbol":"BTC-USDT","reason":"canceled","side":"sell","size":"1.5150744","orderId":"5cefcde6054b463a72e7b4ff","price":"8735.80000000000000000000","time":"1559219688665104914","type":"done"}
2019/05/30 14:34:48 [Info] msg: {"sequence":"1556329021861","symbol":"BTC-USDT","reason":"canceled","side":"buy","size":"0.038493","orderId":"5cefcde44c06872c533232cc","price":"8718.20000000000000000000","time":"1559219688665124632","type":"done"}
2019/05/30 14:34:48 [Info] msg: {"sequence":"1556329021862","symbol":"BTC-USDT","reason":"canceled","side":"buy","size":"0.0431667","orderId":"5cefcde40bad452af7db3162","price":"8718.30000000000000000000","time":"1559219688675689125","type":"done"}
2019/05/30 14:34:48 [Info] msg: {"sequence":"1556329021863","symbol":"BTC-USDT","reason":"canceled","side":"sell","size":"0.269595","orderId":"5cefcde689fc846389b111c7","price":"8735.60000000000000000000","time":"1559219688685623770","type":"done"}
2019/05/30 14:34:48 [Info] msg: {"sequence":"1556329021864","symbol":"BTC-USDT","reason":"canceled","side":"buy","size":"0.1125","orderId":"5cefcde60bad452af7db31c0","price":"8718.60000000000000000000","time":"1559219688696200980","type":"done"}
2019/05/30 14:34:48 [Info] msg: {"sequence":"1556329021865","symbol":"BTC-USDT","reason":"canceled","side":"buy","size":"0.1228","orderId":"5cefcde7054b463a72e7b517","price":"8718.60000000000000000000","time":"1559219688706801675","type":"done"}
2019/05/30 14:34:48 [Info] msg: {"sequence":"1556329021880","symbol":"BTC-USDT","reason":"canceled","side":"buy","size":"0.03000000","orderId":"5cefcde4cdaba439e54e88ce","price":"8721.40000000000000000000","time":"1559219688767967306","type":"done"}
2019/05/30 14:34:49 [Info] msg: {"sequence":"1556329021883","symbol":"BTC-USDT","reason":"canceled","side":"sell","size":"0.05","orderId":"5cefcde75137b96b7e1e2f6c","price":"8728.80000000000000000000","time":"1559219689142992320","type":"done"}
2019/05/30 14:34:49 [Info] msg: {"sequence":"1556329021890","symbol":"BTC-USDT","reason":"canceled","side":"sell","size":"0.00059399","orderId":"5cefcdb80bad452ac338ce53","price":"8737.50000000000000000000","time":"1559219689387232929","type":"done"}
2019/05/30 14:34:49 [Info] msg: {"sequence":"1556329021893","symbol":"BTC-USDT","reason":"canceled","side":"buy","size":"0.00057408","orderId":"5cefcdb9054b463a72e7a9ab","price":"8709.60000000000000000000","time":"1559219689450472007","type":"done"}
2019/05/30 14:34:49 [Info] msg: {"sequence":"1556329021894","symbol":"BTC-USDT","reason":"canceled","side":"sell","size":"0.269595","orderId":"5cefcde85137b96b7e1e2fb1","price":"8735.70000000000000000000","time":"1559219689626335574","type":"done"}
2019/05/30 14:34:49 [Info] msg: {"sequence":"1556329021895","symbol":"BTC-USDT","reason":"canceled","side":"sell","size":"0.0701487","orderId":"5cefcde45137b96bcaf94405","price":"8735.50000000000000000000","time":"1559219689626435282","type":"done"}
2019/05/30 14:34:49 [Info] msg: {"sequence":"1556329021896","symbol":"BTC-USDT","reason":"canceled","side":"sell","size":"1.0065906","orderId":"5cefcde8054b463a72e7b57a","price":"8735.80000000000000000000","time":"1559219689637086781","type":"done"}
2019/05/30 14:34:49 [Info] msg: {"sequence":"1556329021897","symbol":"BTC-USDT","reason":"canceled","side":"sell","size":"0.2307006","orderId":"5cefcde8c788c671b05d0dfd","price":"8735.60000000000000000000","time":"1559219689637181377","type":"done"}
2019/05/30 14:34:50 [Info] msg: {"sequence":"1556329021906","symbol":"BTC-USDT","reason":"canceled","side":"sell","size":"0.068751","orderId":"5cefcde9c788c671eab3d3e5","price":"8728.90000000000000000000","time":"1559219690594420502","type":"done"}
2019/05/30 14:34:50 [Info] msg: {"sequence":"1556329021907","symbol":"BTC-USDT","reason":"canceled","side":"buy","size":"0.5905989","orderId":"5cefcde60bad452af7db31ca","price":"8718.40000000000000000000","time":"1559219690627459915","type":"done"}
2019/05/30 14:34:50 [Info] msg: {"sequence":"1556329021908","symbol":"BTC-USDT","reason":"canceled","side":"buy","size":"1.8557082","orderId":"5cefcde85137b96b7e1e2fae","price":"8718.80000000000000000000","time":"1559219690638280340","type":"done"}
2019/05/30 14:34:50 [Info] msg: {"sequence":"1556329021909","symbol":"BTC-USDT","reason":"canceled","side":"buy","size":"0.00726395","orderId":"5cefcde80bad452ac338d9ee","price":"8719.70000000000000000000","time":"1559219690638357594","type":"done"}
2019/05/30 14:34:50 [Info] msg: {"sequence":"1556329021910","symbol":"BTC-USDT","reason":"canceled","side":"sell","size":"0.1685772","orderId":"5cefcde9054b463aaf90a5e7","price":"8735.70000000000000000000","time":"1559219690638377297","type":"done"}
2019/05/30 14:34:50 [Info] msg: {"sequence":"1556329021911","symbol":"BTC-USDT","reason":"canceled","side":"buy","size":"0.0320112","orderId":"5cefcde84c06872c533233b2","price":"8718.30000000000000000000","time":"1559219690638397883","type":"done"}
2019/05/30 14:34:50 [Info] msg: {"sequence":"1556329021923","symbol":"BTC-USDT","reason":"canceled","side":"buy","size":"0.0899","orderId":"5cefcde6054b463a72e7b4de","price":"8707.40000000000000000000","time":"1559219690724402859","type":"done"}
2019/05/30 14:34:51 [Info] msg: {"sequence":"1556329021928","symbol":"BTC-USDT","reason":"canceled","side":"sell","size":"0.099971","orderId":"5cefcde789fc846350899c42","price":"8734.50000000000000000000","time":"1559219690913809558","type":"done"}
2019/05/30 14:34:51 [Info] msg: {"sequence":"1556329021931","symbol":"BTC-USDT","reason":"canceled","side":"sell","size":"0.228656","orderId":"5cefcde7cdaba439e54e89a6","price":"8736.20000000000000000000","time":"1559219691060844281","type":"done"}
2019/05/30 14:34:51 [Info] msg: {"sequence":"1556329021934","symbol":"BTC-USDT","reason":"canceled","side":"buy","size":"0.1228","orderId":"5cefcde94c06872c533233d9","price":"8717.50000000000000000000","time":"1559219691405051212","type":"done"}
2019/05/30 14:34:51 [Info] msg: {"sequence":"1556329021935","symbol":"BTC-USDT","reason":"canceled","side":"buy","size":"0.1125","orderId":"5cefcde9cdaba439e54e89f4","price":"8717.60000000000000000000","time":"1559219691405149356","type":"done"}
2019/05/30 14:34:51 [Info] msg: {"sequence":"1556329021936","symbol":"BTC-USDT","reason":"canceled","side":"sell","size":"0.091669","orderId":"5cefcde8cdaba439e54e89c1","price":"8732.00000000000000000000","time":"1559219691635251161","type":"done"}
2019/05/30 14:34:51 [Info] msg: {"sequence":"1556329021937","symbol":"BTC-USDT","reason":"canceled","side":"buy","size":"0.5094738","orderId":"5cefcdea054b463a72e7b5e0","price":"8718.90000000000000000000","time":"1559219691667484380","type":"done"}
2019/05/30 14:34:51 [Info] msg: {"sequence":"1556329021938","symbol":"BTC-USDT","reason":"canceled","side":"buy","size":"0.0431667","orderId":"5cefcdea5137b96bcaf9454b","price":"8718.60000000000000000000","time":"1559219691667582287","type":"done"}
2019/05/30 14:34:52 [Info] msg: {"sequence":"1556329021947","symbol":"BTC-USDT","reason":"canceled","side":"sell","size":"0.045834","orderId":"5cefcde8cdaba439e54e89db","price":"8728.40000000000000000000","time":"1559219692176524873","type":"done"}
2019/05/30 14:34:52 [Info] msg: {"sequence":"1556329021948","symbol":"BTC-USDT","reason":"canceled","side":"buy","size":"0.324","orderId":"5cefcdea4c06872c1359ddba","price":"8718.80000000000000000000","time":"1559219692522129008","type":"done"}
2019/05/30 14:34:52 [Info] msg: {"sequence":"1556329021949","symbol":"BTC-USDT","reason":"canceled","side":"buy","size":"0.116019","orderId":"5cefcde789fc846389b11202","price":"8718.50000000000000000000","time":"1559219692522235859","type":"done"}
2019/05/30 14:34:52 [Info] msg: {"sequence":"1556329021950","symbol":"BTC-USDT","reason":"canceled","side":"buy","size":"0.022761","orderId":"5cefcde7054b463a72e7b544","price":"8718.70000000000000000000","time":"1559219692522259360","type":"done"}
2019/05/30 14:34:53 [Info] msg: {"sequence":"1556329021957","symbol":"BTC-USDT","reason":"canceled","side":"sell","size":"0.148694","orderId":"5cefcde8054b463a72e7b55a","price":"8733.40000000000000000000","time":"1559219693032828315","type":"done"}
2019/05/30 14:34:53 [Info] msg: {"sequence":"1556329021958","symbol":"BTC-USDT","reason":"canceled","side":"sell","size":"0.0001","orderId":"5cefcde5054b463a72e7b4b5","price":"8723.00000000000000000000","time":"1559219693076542848","type":"done"}
2019/05/30 14:34:53 [Info] msg: {"sequence":"1556329021959","symbol":"BTC-USDT","reason":"canceled","side":"buy","size":"0.1228","orderId":"5cefcdeb5137b96b7e1e305c","price":"8718.50000000000000000000","time":"1559219693121277649","type":"done"}
2019/05/30 14:34:53 [Info] msg: {"sequence":"1556329021960","symbol":"BTC-USDT","reason":"canceled","side":"sell","size":"0.05","orderId":"5cefcde94c06872c1359dd71","price":"8728.30000000000000000000","time":"1559219693121366131","type":"done"}
2019/05/30 14:34:53 [Info] msg: {"sequence":"1556329021961","symbol":"BTC-USDT","reason":"canceled","side":"sell","size":"0.43155451","orderId":"5cefcda6054b463aaf9096ac","price":"9499.90000000000000000000","time":"1559219693185639145","type":"done"}
2019/05/30 14:34:53 [Info] msg: {"sequence":"1556329021962","symbol":"BTC-USDT","reason":"canceled","side":"buy","size":"0.06104879","orderId":"5cefcdcd054b463a72e7ae97","price":"8721.40000000000000000000","time":"1559219693354627397","type":"done"}
2019/05/30 14:34:53 [Info] msg: {"sequence":"1556329021967","symbol":"BTC-USDT","reason":"canceled","side":"sell","size":"0.0001","orderId":"5cefcde70bad452af7db31de","price":"8722.90000000000000000000","time":"1559219693545564446","type":"done"}
2019/05/30 14:34:53 [Info] msg: {"sequence":"1556329021968","symbol":"BTC-USDT","reason":"canceled","side":"buy","size":"0.1125","orderId":"5cefcdeb5137b96b7e1e305f","price":"8718.50000000000000000000","time":"1559219693567060946","type":"done"}
2019/05/30 14:34:53 [Info] msg: {"sequence":"1556329021971","symbol":"BTC-USDT","reason":"canceled","side":"buy","size":"0.0995112","orderId":"5cefcdec89fc846350899d37","price":"8718.50000000000000000000","time":"1559219693692597976","type":"done"}
2019/05/30 14:34:53 [Info] msg: {"sequence":"1556329021972","symbol":"BTC-USDT","reason":"canceled","side":"buy","size":"0.6222906","orderId":"5cefcdebcdaba439e54e8a6c","price":"8718.40000000000000000000","time":"1559219693692690219","type":"done"}
2019/05/30 14:34:53 [Info] msg: {"sequence":"1556329021973","symbol":"BTC-USDT","reason":"canceled","side":"buy","size":"0.116019","orderId":"5cefcdec4c06872c1359de33","price":"8718.60000000000000000000","time":"1559219693692710796","type":"done"}
2019/05/30 14:34:53 [Info] msg: {"sequence":"1556329021974","symbol":"BTC-USDT","reason":"canceled","side":"sell","size":"0.1685772","orderId":"5cefcde8cdaba439e54e89ce","price":"8735.40000000000000000000","time":"1559219693692725555","type":"done"}
2019/05/30 14:34:53 [Info] msg: {"sequence":"1556329021975","symbol":"BTC-USDT","reason":"canceled","side":"buy","size":"0.45","orderId":"5cefcdeb5137b96b7e1e3053","price":"8718.90000000000000000000","time":"1559219693703867759","type":"done"}
2019/05/30 14:34:53 [Info] msg: {"sequence":"1556329021978","symbol":"BTC-USDT","reason":"canceled","side":"sell","size":"0.2307006","orderId":"5cefcde989fc846350899c93","price":"8735.80000000000000000000","time":"1559219693704127029","type":"done"}
2019/05/30 14:34:54 [Info] msg: {"sequence":"1556329021997","symbol":"BTC-USDT","reason":"canceled","side":"buy","size":"2.4627933","orderId":"5cefcded4c06872c533234a5","price":"8718.70000000000000000000","time":"1559219694602716969","type":"done"}
2019/05/30 14:34:54 [Info] msg: {"sequence":"1556329021998","symbol":"BTC-USDT","reason":"canceled","side":"sell","size":"0.0001","orderId":"5cefcded89fc846350899d78","price":"8723.20000000000000000000","time":"1559219694654958905","type":"done"}
2019/05/30 14:34:54 [Info] msg: {"sequence":"1556329022001","symbol":"BTC-USDT","reason":"canceled","side":"buy","size":"0.0899","orderId":"5cefcdea054b463a72e7b5eb","price":"8707.50000000000000000000","time":"1559219694706446649","type":"done"}
2019/05/30 14:34:55 [Info] msg: {"sequence":"1556329022002","symbol":"BTC-USDT","reason":"canceled","side":"buy","size":"0.30000000","orderId":"5cefcddf054b463a72e7b363","price":"8720.90000000000000000000","time":"1559219694876290436","type":"done"}
2019/05/30 14:34:55 [Info] msg: {"sequence":"1556329022005","symbol":"BTC-USDT","reason":"canceled","side":"buy","size":"0.0675","orderId":"5cefcdeec788c671eab3d4da","price":"8718.50000000000000000000","time":"1559219695552024090","type":"done"}
2019/05/30 14:34:55 [Info] msg: {"sequence":"1556329022006","symbol":"BTC-USDT","reason":"canceled","side":"sell","size":"0.1303686","orderId":"5cefcdea0bad452af7db32a0","price":"8735.70000000000000000000","time":"1559219695552124546","type":"done"}
2019/05/30 14:34:55 [Info] msg: {"sequence":"1556329022007","symbol":"BTC-USDT","reason":"canceled","side":"sell","size":"0.0479331","orderId":"5cefcde90bad452ac338da3e","price":"8735.60000000000000000000","time":"1559219695552148368","type":"done"}
2019/05/30 14:34:55 [Info] msg: {"sequence":"1556329022008","symbol":"BTC-USDT","reason":"canceled","side":"buy","size":"0.3994029","orderId":"5cefcdedc788c671eab3d4b2","price":"8718.90000000000000000000","time":"1559219695572466749","type":"done"}
2019/05/30 14:34:55 [Info] msg: {"sequence":"1556329022017","symbol":"BTC-USDT","reason":"canceled","side":"sell","size":"0.0001","orderId":"5cefcdef4c06872c533234ee","price":"8723.20000000000000000000","time":"1559219695731832472","type":"done"}
2019/05/30 14:34:56 [Info] msg: {"sequence":"1556329022020","symbol":"BTC-USDT","reason":"canceled","side":"sell","size":"0.0001","orderId":"5cefcded054b463aaf90a6d5","price":"8723.20000000000000000000","time":"1559219696797716362","type":"done"}
2019/05/30 14:34:56 [Info] msg: {"sequence":"1556329022021","symbol":"BTC-USDT","reason":"canceled","side":"sell","size":"0.0001","orderId":"5cefcdf0c788c671b05d0f7f","price":"8723.20000000000000000000","time":"1559219696797825201","type":"done"}
2019/05/30 14:34:57 [Info] msg: {"sequence":"1556329022029","symbol":"BTC-USDT","reason":"canceled","side":"buy","size":"2.4627933","orderId":"5cefcdef89fc846350899de8","price":"8718.70000000000000000000","time":"1559219697385324078","type":"done"}
2019/05/30 14:34:57 [Info] msg: {"sequence":"1556329022030","symbol":"BTC-USDT","reason":"canceled","side":"buy","size":"0.00763686","orderId":"5cefcdea054b463a72e7b5e3","price":"8719.80000000000000000000","time":"1559219697385427133","type":"done"}
2019/05/30 14:34:57 [Info] msg: {"sequence":"1556329022031","symbol":"BTC-USDT","reason":"canceled","side":"buy","size":"0.116019","orderId":"5cefcded054b463a72e7b67e","price":"8718.40000000000000000000","time":"1559219697385447993","type":"done"}
2019/05/30 14:34:57 [Info] msg: {"sequence":"1556329022032","symbol":"BTC-USDT","reason":"canceled","side":"buy","size":"0.225","orderId":"5cefcdef5137b96b7e1e311b","price":"8718.90000000000000000000","time":"1559219697385463275","type":"done"}
2019/05/30 14:34:58 [Info] msg: {"sequence":"1556329022045","symbol":"BTC-USDT","reason":"canceled","side":"buy","size":"0.0899","orderId":"5cefcdee0bad452af7db335e","price":"8707.60000000000000000000","time":"1559219698092228086","type":"done"}
2019/05/30 14:34:58 [Info] msg: {"sequence":"1556329022050","symbol":"BTC-USDT","reason":"canceled","side":"buy","size":"0.1125","orderId":"5cefcdedc788c671b05d0f0a","price":"8718.70000000000000000000","time":"1559219698271875825","type":"done"}
2019/05/30 14:34:58 [Info] msg: {"sequence":"1556329022051","symbol":"BTC-USDT","reason":"canceled","side":"buy","size":"0.9422937","orderId":"5cefcdf15137b96bcaf9469e","price":"8718.70000000000000000000","time":"1559219698302740588","type":"done"}
2019/05/30 14:34:59 [Info] msg: {"sequence":"1556329022060","symbol":"BTC-USDT","reason":"canceled","side":"buy","size":"0.206295","orderId":"5cefcde04c06872c533231ea","price":"8719.90000000000000000000","time":"1559219698988069598","type":"done"}
2019/05/30 14:34:59 [Info] msg: {"sequence":"1556329022061","symbol":"BTC-USDT","reason":"canceled","side":"sell","size":"0.148692","orderId":"5cefcdf189fc846350899e55","price":"8733.50000000000000000000","time":"1559219698998809945","type":"done"}
2019/05/30 14:34:59 [Info] msg: {"sequence":"1556329022062","symbol":"BTC-USDT","reason":"canceled","side":"buy","size":"0.039","orderId":"5cefcde4054b463aaf90a4be","price":"8716.90000000000000000000","time":"1559219699008560868","type":"done"}
2019/05/30 14:34:59 [Info] msg: {"sequence":"1556329022063","symbol":"BTC-USDT","reason":"canceled","side":"sell","size":"0.228654","orderId":"5cefcdf1c788c671b05d0fd1","price":"8736.30000000000000000000","time":"1559219699165633242","type":"done"}
2019/05/30 14:34:59 [Info] msg: {"sequence":"1556329022064","symbol":"BTC-USDT","reason":"canceled","side":"sell","size":"0.0084434","orderId":"5cefcde50bad452ac338d946","price":"8734.50000000000000000000","time":"1559219699195790167","type":"done"}
2019/05/30 14:34:59 [Info] msg: {"sequence":"1556329022065","symbol":"BTC-USDT","reason":"canceled","side":"sell","size":"0.0479331","orderId":"5cefcded5137b96b7e1e30c2","price":"8735.40000000000000000000","time":"1559219699195889046","type":"done"}
2019/05/30 14:34:59 [Info] msg: {"sequence":"1556329022066","symbol":"BTC-USDT","reason":"canceled","side":"sell","size":"0.2372778","orderId":"5cefcded4c06872c533234a6","price":"8735.50000000000000000000","time":"1559219699195909371","type":"done"}
2019/05/30 14:34:59 [Info] msg: {"sequence":"1556329022067","symbol":"BTC-USDT","reason":"canceled","side":"sell","size":"0.2372778","orderId":"5cefcdefcdaba439e54e8b3d","price":"8735.80000000000000000000","time":"1559219699205499781","type":"done"}
2019/05/30 14:34:59 [Info] msg: {"sequence":"1556329022068","symbol":"BTC-USDT","reason":"canceled","side":"sell","size":"0.269595","orderId":"5cefcde95137b96b7e1e2ff2","price":"8735.90000000000000000000","time":"1559219699205576546","type":"done"}
2019/05/30 14:34:59 [Info] msg: {"sequence":"1556329022069","symbol":"BTC-USDT","reason":"canceled","side":"sell","size":"0.0479331","orderId":"5cefcdefcdaba43a1e1493b3","price":"8735.70000000000000000000","time":"1559219699216129909","type":"done"}
2019/05/30 14:34:59 [Info] msg: {"sequence":"1556329022070","symbol":"BTC-USDT","reason":"canceled","side":"buy","size":"0.022761","orderId":"5cefcdec89fc846350899d3b","price":"8718.80000000000000000000","time":"1559219699226993980","type":"done"}
2019/05/30 14:34:59 [Info] msg: {"sequence":"1556329022079","symbol":"BTC-USDT","reason":"canceled","side":"buy","size":"0.022761","orderId":"5cefcded89fc846389b11324","price":"8718.60000000000000000000","time":"1559219699258984092","type":"done"}
2019/05/30 14:34:59 [Info] msg: {"sequence":"1556329022086","symbol":"BTC-USDT","reason":"canceled","side":"buy","size":"0.022761","orderId":"5cefcdf189fc846350899e62","price":"8718.90000000000000000000","time":"1559219699343745626","type":"done"}
2019/05/30 14:34:59 [Info] msg: {"sequence":"1556329022091","symbol":"BTC-USDT","reason":"canceled","side":"buy","size":"1.8557082","orderId":"5cefcdf1054b463a72e7b737","price":"8719.00000000000000000000","time":"1559219699364066474","type":"done"}
2019/05/30 14:34:59 [Info] msg: {"sequence":"1556329022092","symbol":"BTC-USDT","reason":"canceled","side":"buy","size":"0.0422937","orderId":"5cefcdf20bad452ac338dc0b","price":"8718.70000000000000000000","time":"1559219699395206671","type":"done"}
2019/05/30 14:34:59 [Info] msg: {"sequence":"1556329022097","symbol":"BTC-USDT","reason":"canceled","side":"buy","size":"0.40079","orderId":"5cefcdc3054b463a72e7abeb","price":"8720.60000000000000000000","time":"1559219699459648386","type":"done"}
2019/05/30 14:34:59 [Info] msg: {"sequence":"1556329022100","symbol":"BTC-USDT","reason":"canceled","side":"sell","size":"0.0001","orderId":"5cefcdf10bad452af7db33f0","price":"8723.70000000000000000000","time":"1559219699824352008","type":"done"}
2019/05/30 14:34:59 [Info] msg: {"sequence":"1556329022101","symbol":"BTC-USDT","reason":"canceled","side":"buy","size":"0.036","orderId":"5cefcdd1054b463aaf90a075","price":"8710.80000000000000000000","time":"1559219699824454499","type":"done"}
2019/05/30 14:34:59 [Info] msg: {"sequence":"1556329022102","symbol":"BTC-USDT","reason":"canceled","side":"buy","size":"0.1228","orderId":"5cefcdedcdaba439e54e8ad7","price":"8718.70000000000000000000","time":"1559219699834992955","type":"done"}
2019/05/30 14:35:00 [Info] msg: {"sequence":"1556329022103","symbol":"BTC-USDT","reason":"canceled","side":"buy","size":"0.038","orderId":"5cefcdd1c788c671eab3cde2","price":"8706.40000000000000000000","time":"1559219699856026795","type":"done"}
2019/05/30 14:35:00 [Info] msg: {"sequence":"1556329022104","symbol":"BTC-USDT","reason":"canceled","side":"sell","size":"0.45","orderId":"5cefcdf389fc846350899ee6","price":"8736.20000000000000000000","time":"1559219700272649516","type":"done"}
2019/05/30 14:35:00 [Info] msg: {"sequence":"1556329022107","symbol":"BTC-USDT","reason":"canceled","side":"buy","size":"0.03000000","orderId":"5cefcdf25137b96b7e1e31ac","price":"8721.70000000000000000000","time":"1559219700346866946","type":"done"}
2019/05/30 14:35:00 [Info] msg: {"sequence":"1556329022108","symbol":"BTC-USDT","reason":"canceled","side":"buy","size":"0.1125","orderId":"5cefcdf2cdaba43a1e149487","price":"8719.00000000000000000000","time":"1559219700409515036","type":"done"}
2019/05/30 14:35:00 [Info] msg: {"sequence":"1556329022109","symbol":"BTC-USDT","reason":"canceled","side":"buy","size":"0.078697","orderId":"5cefcde0c788c671eab3d16a","price":"8720.10000000000000000000","time":"1559219700451557804","type":"done"}
2019/05/30 14:35:01 [Info] msg: {"sequence":"1556329022120","symbol":"BTC-USDT","reason":"canceled","side":"sell","size":"0.2372778","orderId":"5cefcdf30bad452ac338dc3a","price":"8736.00000000000000000000","time":"1559219701285512305","type":"done"}
2019/05/30 14:35:01 [Info] msg: {"sequence":"1556329022121","symbol":"BTC-USDT","reason":"canceled","side":"buy","size":"3.83471424","orderId":"5cefcdf389fc846389b1144b","price":"8719.70000000000000000000","time":"1559219701285611662","type":"done"}
2019/05/30 14:35:01 [Info] msg: {"sequence":"1556329022122","symbol":"BTC-USDT","reason":"canceled","side":"sell","size":"0.269595","orderId":"5cefcdf30bad452ac338dc3d","price":"8736.10000000000000000000","time":"1559219701285639180","type":"done"}
2019/05/30 14:35:01 [Info] msg: {"sequence":"1556329022127","symbol":"BTC-USDT","reason":"canceled","side":"sell","size":"0.0001","orderId":"5cefcdf2cdaba439e54e8bc4","price":"8723.60000000000000000000","time":"1559219701485837552","type":"done"}
2019/05/30 14:35:02 [Info] msg: {"sequence":"1556329022134","symbol":"BTC-USDT","reason":"canceled","side":"sell","size":"0.0001","orderId":"5cefcdf40bad452af7db34dc","price":"8723.20000000000000000000","time":"1559219702162009863","type":"done"}
2019/05/30 14:35:02 [Info] msg: {"sequence":"1556329022137","symbol":"BTC-USDT","reason":"canceled","side":"buy","size":"0.1228","orderId":"5cefcdf4cdaba43a1e149509","price":"8719.10000000000000000000","time":"1559219702414095992","type":"done"}
2019/05/30 14:35:02 [Info] msg: {"sequence":"1556329022138","symbol":"BTC-USDT","reason":"canceled","side":"buy","size":"0.00831019","orderId":"5cefcdf3cdaba439e54e8c08","price":"8720.80000000000000000000","time":"1559219702550247037","type":"done"}
2019/05/30 14:35:02 [Info] msg: {"sequence":"1556329022139","symbol":"BTC-USDT","reason":"canceled","side":"buy","size":"0.9","orderId":"5cefcdf589fc846350899f4b","price":"8719.70000000000000000000","time":"1559219702550353202","type":"done"}
2019/05/30 14:35:02 [Info] msg: {"sequence":"1556329022140","symbol":"BTC-USDT","reason":"canceled","side":"sell","size":"0.40079","orderId":"5cefcdccc788c671b05d0717","price":"8729.60000000000000000000","time":"1559219702550374590","type":"done"}
2019/05/30 14:35:02 [Info] msg: {"sequence":"1556329022145","symbol":"BTC-USDT","reason":"canceled","side":"buy","size":"1.35","orderId":"5cefcdf30bad452af7db345f","price":"8719.80000000000000000000","time":"1559219702602560303","type":"done"}
2019/05/30 14:35:02 [Info] msg: {"sequence":"1556329022146","symbol":"BTC-USDT","reason":"canceled","side":"sell","size":"0.0479331","orderId":"5cefcdf34c06872c533235de","price":"8735.90000000000000000000","time":"1559219702602592774","type":"done"}
2019/05/30 14:35:02 [Info] msg: {"sequence":"1556329022147","symbol":"BTC-USDT","reason":"canceled","side":"sell","size":"0.0001","orderId":"5cefcdf64c06872c1359e031","price":"8725.70000000000000000000","time":"1559219702613033158","type":"done"}
2019/05/30 14:35:02 [Info] msg: {"sequence":"1556329022148","symbol":"BTC-USDT","reason":"canceled","side":"sell","size":"0.00619407","orderId":"5cefcdf3054b463aaf90a820","price":"8735.00000000000000000000","time":"1559219702613104093","type":"done"}
2019/05/30 14:35:02 [Info] msg: {"sequence":"1556329022149","symbol":"BTC-USDT","reason":"canceled","side":"buy","size":"0.225","orderId":"5cefcdf30bad452ac338dc49","price":"8719.50000000000000000000","time":"1559219702613120968","type":"done"}
2019/05/30 14:35:02 [Info] msg: {"sequence":"1556329022150","symbol":"BTC-USDT","reason":"canceled","side":"buy","size":"0.0431667","orderId":"5cefcdf35137b96b7e1e31f1","price":"8719.60000000000000000000","time":"1559219702613138396","type":"done"}
2019/05/30 14:35:02 [Info] msg: {"sequence":"1556329022155","symbol":"BTC-USDT","reason":"canceled","side":"buy","size":"0.1125","orderId":"5cefcdf4054b463a72e7b80b","price":"8719.20000000000000000000","time":"1559219702685789235","type":"done"}
2019/05/30 14:35:02 [Info] msg: {"sequence":"1556329022156","symbol":"BTC-USDT","reason":"canceled","side":"buy","size":"0.0899","orderId":"5cefcdf2054b463aaf90a7dd","price":"8707.80000000000000000000","time":"1559219702706018258","type":"done"}
2019/05/30 14:35:03 [Info] msg: {"sequence":"1556329022171","symbol":"BTC-USDT","reason":"canceled","side":"sell","size":"0.0001","orderId":"5cefcdf689fc846350899f83","price":"8724.20000000000000000000","time":"1559219703096299276","type":"done"}
2019/05/30 14:35:03 [Info] msg: {"sequence":"1556329022178","symbol":"BTC-USDT","reason":"canceled","side":"buy","size":"0.1125","orderId":"5cefcdf7cdaba43a1e149589","price":"8719.60000000000000000000","time":"1559219703762381323","type":"done"}
2019/05/30 14:35:03 [Info] msg: {"sequence":"1556329022179","symbol":"BTC-USDT","reason":"canceled","side":"buy","size":"0.1228","orderId":"5cefcdf6cdaba439e54e8cb8","price":"8719.40000000000000000000","time":"1559219703762471691","type":"done"}
2019/05/30 14:35:03 [Info] msg: {"sequence":"1556329022180","symbol":"BTC-USDT","reason":"canceled","side":"sell","size":"0.162","orderId":"5cefcdf389fc846350899ee3","price":"8736.40000000000000000000","time":"1559219703793414555","type":"done"}
2019/05/30 14:35:03 [Info] msg: {"sequence":"1556329022181","symbol":"BTC-USDT","reason":"canceled","side":"sell","size":"1.2506139","orderId":"5cefcdf65137b96b7e1e32d2","price":"8736.50000000000000000000","time":"1559219703803963877","type":"done"}
2019/05/30 14:35:03 [Info] msg: {"sequence":"1556329022182","symbol":"BTC-USDT","reason":"canceled","side":"buy","size":"0.00883527","orderId":"5cefcdf6cdaba43a1e14956a","price":"8721.00000000000000000000","time":"1559219703804043261","type":"done"}
2019/05/30 14:35:03 [Info] msg: {"sequence":"1556329022183","symbol":"BTC-USDT","reason":"canceled","side":"buy","size":"1.35","orderId":"5cefcdf60bad452af7db353d","price":"8720.10000000000000000000","time":"1559219703804067076","type":"done"}
2019/05/30 14:35:03 [Info] msg: {"sequence":"1556329022184","symbol":"BTC-USDT","reason":"canceled","side":"buy","size":"3.83821512","orderId":"5cefcdf6054b463a72e7b865","price":"8720.00000000000000000000","time":"1559219703814635411","type":"done"}
2019/05/30 14:35:03 [Info] msg: {"sequence":"1556329022185","symbol":"BTC-USDT","reason":"canceled","side":"buy","size":"0.412245","orderId":"5cefcdf689fc846389b11514","price":"8719.70000000000000000000","time":"1559219703814706161","type":"done"}
2019/05/30 14:35:03 [Info] msg: {"sequence":"1556329022192","symbol":"BTC-USDT","reason":"canceled","side":"buy","size":"0.225","orderId":"5cefcdf64c06872c1359e05d","price":"8719.80000000000000000000","time":"1559219703856509580","type":"done"}
2019/05/30 14:35:04 [Info] msg: {"sequence":"1556329022203","symbol":"BTC-USDT","reason":"canceled","side":"buy","size":"0.039","orderId":"5cefcdf2c788c671b05d1023","price":"8717.80000000000000000000","time":"1559219704055395110","type":"done"}
2019/05/30 14:35:04 [Info] msg: {"sequence":"1556329022204","symbol":"BTC-USDT","reason":"canceled","side":"sell","size":"0.0001","orderId":"5cefcdf7c788c671eab3d6d4","price":"8724.60000000000000000000","time":"1559219704233441582","type":"done"}
2019/05/30 14:35:04 [Info] msg: {"sequence":"1556329022211","symbol":"BTC-USDT","reason":"canceled","side":"sell","size":"0.0001","orderId":"5cefcdf7054b463aaf90a915","price":"8724.70000000000000000000","time":"1559219704348554703","type":"done"}
2019/05/30 14:35:04 [Info] msg: {"sequence":"1556329022212","symbol":"BTC-USDT","reason":"canceled","side":"buy","size":"0.039","orderId":"5cefcdf7cdaba439e54e8d30","price":"8719.40000000000000000000","time":"1559219704358606113","type":"done"}
2019/05/30 14:35:04 [Info] msg: {"sequence":"1556329022213","symbol":"BTC-USDT","reason":"canceled","side":"buy","size":"0.229175","orderId":"5cefcde6c788c671b05d0d7a","price":"8717.80000000000000000000","time":"1559219704619912067","type":"done"}
2019/05/30 14:35:04 [Info] msg: {"sequence":"1556329022214","symbol":"BTC-USDT","reason":"canceled","side":"sell","size":"0.00059399","orderId":"5cefcdc1054b463a72e7aba8","price":"8744.80000000000000000000","time":"1559219704630370022","type":"done"}
2019/05/30 14:35:04 [Info] msg: {"sequence":"1556329022219","symbol":"BTC-USDT","reason":"canceled","side":"sell","size":"0.00711432","orderId":"5cefcdf60bad452ac338dce9","price":"8735.20000000000000000000","time":"1559219704736841313","type":"done"}
2019/05/30 14:35:04 [Info] msg: {"sequence":"1556329022220","symbol":"BTC-USDT","reason":"canceled","side":"buy","size":"0.1125","orderId":"5cefcdf8c788c671b05d1159","price":"8719.60000000000000000000","time":"1559219704747293719","type":"done"}
2019/05/30 14:35:04 [Info] msg: {"sequence":"1556329022221","symbol":"BTC-USDT","reason":"canceled","side":"sell","size":"0.162","orderId":"5cefcdf5cdaba439e54e8c7c","price":"8736.10000000000000000000","time":"1559219704758061484","type":"done"}
2019/05/30 14:35:04 [Info] msg: {"sequence":"1556329022222","symbol":"BTC-USDT","reason":"canceled","side":"sell","size":"0.45","orderId":"5cefcdf55137b96b7e1e327d","price":"8736.20000000000000000000","time":"1559219704758139024","type":"done"}
2019/05/30 14:35:04 [Info] msg: {"sequence":"1556329022223","symbol":"BTC-USDT","reason":"canceled","side":"sell","size":"0.0479331","orderId":"5cefcdf44c06872c1359dfcc","price":"8736.30000000000000000000","time":"1559219704758156328","type":"done"}
2019/05/30 14:35:04 [Info] msg: {"sequence":"1556329022224","symbol":"BTC-USDT","reason":"canceled","side":"sell","size":"0.0297","orderId":"5cefcdf74c06872c1359e087","price":"8736.40000000000000000000","time":"1559219704758170946","type":"done"}
2019/05/30 14:35:04 [Info] msg: {"sequence":"1556329022225","symbol":"BTC-USDT","reason":"canceled","side":"sell","size":"0.0479331","orderId":"5cefcdf789fc846389b11568","price":"8736.60000000000000000000","time":"1559219704758184111","type":"done"}
2019/05/30 14:35:04 [Info] msg: {"sequence":"1556329022226","symbol":"BTC-USDT","reason":"canceled","side":"buy","size":"0.324","orderId":"5cefcdf70bad452ac338dd4a","price":"8720.10000000000000000000","time":"1559219704789362979","type":"done"}
2019/05/30 14:35:04 [Info] msg: {"sequence":"1556329022229","symbol":"BTC-USDT","reason":"canceled","side":"buy","size":"0.00057429","orderId":"5cefcdc24c06872c53322a48","price":"8706.40000000000000000000","time":"1559219704800059828","type":"done"}
2019/05/30 14:35:05 [Info] msg: {"sequence":"1556329022248","symbol":"BTC-USDT","reason":"canceled","side":"buy","size":"0.9","orderId":"5cefcdf789fc846389b11564","price":"8720.00000000000000000000","time":"1559219704947351404","type":"done"}
2019/05/30 14:35:05 [Info] msg: {"sequence":"1556329022249","symbol":"BTC-USDT","reason":"canceled","side":"buy","size":"0.00895334","orderId":"5cefcdf789fc846389b11567","price":"8721.10000000000000000000","time":"1559219704947438246","type":"done"}
2019/05/30 14:35:05 [Info] msg: {"sequence":"1556329022250","symbol":"BTC-USDT","reason":"canceled","side":"buy","size":"0.0431667","orderId":"5cefcdf70bad452af7db35a0","price":"8719.80000000000000000000","time":"1559219704947457274","type":"done"}
2019/05/30 14:35:05 [Info] msg: {"sequence":"1556329022253","symbol":"BTC-USDT","reason":"canceled","side":"buy","size":"0.039","orderId":"5cefcdf8054b463a72e7b8c1","price":"8720.10000000000000000000","time":"1559219705020377129","type":"done"}
2019/05/30 14:35:05 [Info] msg: {"sequence":"1556329022254","symbol":"BTC-USDT","reason":"canceled","side":"sell","size":"0.00059399","orderId":"5cefcdc24c06872c1359d40a","price":"8740.40000000000000000000","time":"1559219705106411939","type":"done"}
2019/05/30 14:35:05 [Info] msg: {"sequence":"1556329022255","symbol":"BTC-USDT","reason":"canceled","side":"buy","size":"0.22916148","orderId":"5cefcde64c06872c53323349","price":"8721.70000000000000000000","time":"1559219705190301776","type":"done"}
2019/05/30 14:35:05 [Info] msg: {"sequence":"1556329022256","symbol":"BTC-USDT","reason":"canceled","side":"buy","size":"0.000574","orderId":"5cefcdc20bad452ac338d07b","price":"8710.80000000000000000000","time":"1559219705212034530","type":"done"}
2019/05/30 14:35:05 [Info] msg: {"sequence":"1556329022257","symbol":"BTC-USDT","reason":"canceled","side":"sell","size":"0.0001","orderId":"5cefcdf8c788c671eab3d71e","price":"8724.50000000000000000000","time":"1559219705243838718","type":"done"}
2019/05/30 14:35:05 [Info] msg: {"sequence":"1556329022262","symbol":"BTC-USDT","reason":"canceled","side":"buy","size":"0.039","orderId":"5cefcdf80bad452ac338dd86","price":"8720.20000000000000000000","time":"1559219705328874658","type":"done"}
2019/05/30 14:35:05 [Info] msg: {"sequence":"1556329022263","symbol":"BTC-USDT","reason":"canceled","side":"buy","size":"1.60641","orderId":"5cefcdd55137b96b7e1e2b50","price":"8712.10000000000000000000","time":"1559219705516882691","type":"done"}
2019/05/30 14:35:05 [Info] msg: {"sequence":"1556329022264","symbol":"BTC-USDT","reason":"canceled","side":"sell","size":"2.10202","orderId":"5cefcdd589fc8463508997a0","price":"8747.60000000000000000000","time":"1559219705516977172","type":"done"}
2019/05/30 14:35:05 [Info] msg: {"sequence":"1556329022265","symbol":"BTC-USDT","reason":"canceled","side":"sell","size":"1.66838","orderId":"5cefcdd5054b463aaf90a17d","price":"8739.40000000000000000000","time":"1559219705517001698","type":"done"}
2019/05/30 14:35:05 [Info] msg: {"sequence":"1556329022266","symbol":"BTC-USDT","reason":"canceled","side":"buy","size":"2.02396","orderId":"5cefcde74c06872c1359dd05","price":"8704.30000000000000000000","time":"1559219705528785482","type":"done"}
2019/05/30 14:35:05 [Info] msg: {"sequence":"1556329022267","symbol":"BTC-USDT","reason":"canceled","side":"buy","size":"0.206236","orderId":"5cefcdf4cdaba43a1e149500","price":"8722.50000000000000000000","time":"1559219705539136128","type":"done"}
2019/05/30 14:35:05 [Info] msg: {"sequence":"1556329022268","symbol":"BTC-USDT","reason":"canceled","side":"sell","size":"0.40079","orderId":"5cefcdf6cdaba43a1e149566","price":"8731.50000000000000000000","time":"1559219705539211367","type":"done"}
2019/05/30 14:35:05 [Info] msg: {"sequence":"1556329022276","symbol":"BTC-USDT","reason":"canceled","side":"sell","orderId":"5cefcdf90bad452ac338ddb5","time":"1559219705718815273","type":"done"}
2019/05/30 14:35:05 [Info] msg: {"sequence":"1556329022277","symbol":"BTC-USDT","reason":"canceled","side":"buy","size":"0.1228","orderId":"5cefcdf80bad452af7db35b4","price":"8719.50000000000000000000","time":"1559219705788098527","type":"done"}
2019/05/30 14:35:05 [Info] msg: {"sequence":"1556329022278","symbol":"BTC-USDT","reason":"canceled","side":"buy","size":"0.40079","orderId":"5cefcdf3c788c671b05d1051","price":"8722.10000000000000000000","time":"1559219705788196140","type":"done"}
2019/05/30 14:35:05 [Info] msg: {"sequence":"1556329022280","symbol":"BTC-USDT","reason":"canceled","side":"sell","orderId":"5cefcdf95137b96bcaf948aa","time":"1559219705809168835","type":"done"}
2019/05/30 14:35:06 [Info] msg: {"sequence":"1556329022287","symbol":"BTC-USDT","reason":"canceled","side":"sell","size":"0.00592531","orderId":"5cefcdf80bad452af7db35d2","price":"8736.00000000000000000000","time":"1559219705936523107","type":"done"}
2019/05/30 14:35:06 [Info] msg: {"sequence":"1556329022288","symbol":"BTC-USDT","reason":"canceled","side":"sell","size":"2.6821188","orderId":"5cefcdf8c788c671eab3d721","price":"8736.90000000000000000000","time":"1559219705936616236","type":"done"}
2019/05/30 14:35:06 [Info] msg: {"sequence":"1556329022289","symbol":"BTC-USDT","reason":"canceled","side":"sell","size":"0.9217341","orderId":"5cefcdf8054b463aaf90a952","price":"8737.00000000000000000000","time":"1559219705936636932","type":"done"}
2019/05/30 14:35:06 [Info] msg: {"sequence":"1556329022290","symbol":"BTC-USDT","reason":"canceled","side":"sell","size":"1.0541934","orderId":"5cefcdf8cdaba43a1e1495d7","price":"8737.10000000000000000000","time":"1559219705936652855","type":"done"}
2019/05/30 14:35:06 [Info] msg: {"sequence":"1556329022291","symbol":"BTC-USDT","reason":"canceled","side":"sell","size":"1.2506139","orderId":"5cefcdf8054b463a72e7b8e4","price":"8737.20000000000000000000","time":"1559219705947121119","type":"done"}
2019/05/30 14:35:06 [Info] msg: {"sequence":"1556329022292","symbol":"BTC-USDT","reason":"canceled","side":"sell","size":"0.45","orderId":"5cefcdf84c06872c1359e0bd","price":"8737.30000000000000000000","time":"1559219705947204711","type":"done"}
2019/05/30 14:35:06 [Info] msg: {"sequence":"1556329022303","symbol":"BTC-USDT","reason":"canceled","side":"buy","size":"0.078673","orderId":"5cefcdf60bad452af7db352b","price":"8722.70000000000000000000","time":"1559219706003367682","type":"done"}
2019/05/30 14:35:06 [Info] msg: {"sequence":"1556329022304","symbol":"BTC-USDT","reason":"canceled","side":"buy","size":"0.0431667","orderId":"5cefcdf8c788c671b05d117f","price":"8720.10000000000000000000","time":"1559219706087840394","type":"done"}
2019/05/30 14:35:06 [Info] msg: {"sequence":"1556329022305","symbol":"BTC-USDT","reason":"canceled","side":"buy","size":"0.0899","orderId":"5cefcdf65137b96b7e1e32c8","price":"8707.90000000000000000000","time":"1559219706097982074","type":"done"}
2019/05/30 14:35:06 [Info] msg: {"sequence":"1556329022306","symbol":"BTC-USDT","reason":"canceled","side":"buy","size":"0.225","orderId":"5cefcdf84c06872c53323721","price":"8720.00000000000000000000","time":"1559219706098066290","type":"done"}
2019/05/30 14:35:06 [Info] msg: {"sequence":"1556329022307","symbol":"BTC-USDT","reason":"canceled","side":"buy","size":"0.7164567","orderId":"5cefcdf70bad452ac338dd40","price":"8720.20000000000000000000","time":"1559219706098087699","type":"done"}
2019/05/30 14:35:06 [Info] msg: {"sequence":"1556329022310","symbol":"BTC-USDT","reason":"canceled","side":"sell","size":"0.05","orderId":"5cefcdedc788c671eab3d4a0","price":"8728.80000000000000000000","time":"1559219706132005583","type":"done"}
2019/05/30 14:35:06 [Info] msg: {"sequence":"1556329022313","symbol":"BTC-USDT","reason":"canceled","side":"buy","size":"0.00806949","orderId":"5cefcdf8054b463aaf90a955","price":"8721.20000000000000000000","time":"1559219706171502484","type":"done"}
2019/05/30 14:35:06 [Info] msg: {"sequence":"1556329022316","symbol":"BTC-USDT","reason":"canceled","side":"buy","size":"0.00912703","orderId":"5cefcdf15137b96b7e1e3181","price":"8719.90000000000000000000","time":"1559219706171744731","type":"done"}
2019/05/30 14:35:06 [Info] msg: {"sequence":"1556329022317","symbol":"BTC-USDT","reason":"canceled","side":"buy","size":"0.9","orderId":"5cefcdf8c788c671eab3d72b","price":"8720.30000000000000000000","time":"1559219706183166816","type":"done"}
2019/05/30 14:35:06 [Info] msg: {"sequence":"1556329022334","symbol":"BTC-USDT","reason":"canceled","side":"buy","size":"0.1125","orderId":"5cefcdf9c788c671b05d1191","price":"8721.20000000000000000000","time":"1559219706336838784","type":"done"}
2019/05/30 14:35:06 [Info] msg: {"sequence":"1556329022342","symbol":"BTC-USDT","reason":"canceled","side":"buy","orderId":"5cefcdfa4c06872c1359e12b","time":"1559219706527978470","type":"done"}
2019/05/30 14:35:07 [Info] msg: {"sequence":"1556329022351","symbol":"BTC-USDT","reason":"canceled","side":"buy","size":"0.039","orderId":"5cefcdf9c788c671b05d1194","price":"8720.30000000000000000000","time":"1559219706931787003","type":"done"}
2019/05/30 14:35:07 [Info] msg: {"sequence":"1556329022352","symbol":"BTC-USDT","reason":"canceled","side":"sell","size":"0.00500229","orderId":"5cefcdf9c788c671eab3d776","price":"8738.80000000000000000000","time":"1559219707027172804","type":"done"}
2019/05/30 14:35:07 [Info] msg: {"sequence":"1556329022353","symbol":"BTC-USDT","reason":"canceled","side":"sell","size":"0.9217341","orderId":"5cefcdf95137b96bcaf948b2","price":"8739.00000000000000000000","time":"1559219707027263295","type":"done"}
2019/05/30 14:35:07 [Info] msg: {"sequence":"1556329022354","symbol":"BTC-USDT","reason":"canceled","side":"sell","size":"1.0541934","orderId":"5cefcdfacdaba43a1e149635","price":"8739.10000000000000000000","time":"1559219707037999294","type":"done"}
2019/05/30 14:35:07 [Info] msg: {"sequence":"1556329022355","symbol":"BTC-USDT","reason":"canceled","side":"sell","size":"0.0077048","orderId":"5cefcdf90bad452af7db362c","price":"8737.90000000000000000000","time":"1559219707038082974","type":"done"}
2019/05/30 14:35:07 [Info] msg: {"sequence":"1556329022356","symbol":"BTC-USDT","reason":"canceled","side":"sell","size":"2.6821188","orderId":"5cefcdf90bad452ac338ddc5","price":"8738.90000000000000000000","time":"1559219707038101482","type":"done"}
2019/05/30 14:35:07 [Info] msg: {"sequence":"1556329022357","symbol":"BTC-USDT","reason":"canceled","side":"buy","size":"0.0084998","orderId":"5cefcdfa0bad452ac338ddd2","price":"8723.00000000000000000000","time":"1559219707038120740","type":"done"}
2019/05/30 14:35:07 [Info] msg: {"sequence":"1556329022358","symbol":"BTC-USDT","reason":"canceled","side":"sell","size":"1.2506139","orderId":"5cefcdfa5137b96b7e1e339f","price":"8739.20000000000000000000","time":"1559219707049329113","type":"done"}
2019/05/30 14:35:07 [Info] msg: {"sequence":"1556329022359","symbol":"BTC-USDT","reason":"canceled","side":"buy","size":"0.9","orderId":"5cefcdfa4c06872c53323783","price":"8721.90000000000000000000","time":"1559219707059589639","type":"done"}
2019/05/30 14:35:07 [Info] msg: {"sequence":"1556329022360","symbol":"BTC-USDT","reason":"canceled","side":"buy","size":"2.3443506","orderId":"5cefcdfac788c671b05d11eb","price":"8721.80000000000000000000","time":"1559219707059658869","type":"done"}
2019/05/30 14:35:07 [Info] msg: {"sequence":"1556329022361","symbol":"BTC-USDT","reason":"canceled","side":"buy","size":"0.0833319","orderId":"5cefcdfa89fc84635089a045","price":"8721.70000000000000000000","time":"1559219707059675749","type":"done"}
2019/05/30 14:35:07 [Info] msg: {"sequence":"1556329022385","symbol":"BTC-USDT","reason":"canceled","side":"buy","orderId":"5cefcdfb5137b96b7e1e33f2","time":"1559219707528339200","type":"done"}
2019/05/30 14:35:08 [Info] msg: {"sequence":"1556329022387","symbol":"BTC-USDT","reason":"canceled","side":"buy","orderId":"5cefcdfbc788c671b05d1261","time":"1559219707844072672","type":"done"}
2019/05/30 14:35:08 [Info] msg: {"sequence":"1556329022388","symbol":"BTC-USDT","reason":"canceled","side":"sell","size":"1.5163173","orderId":"5cefcdfb89fc846389b1165b","price":"8739.80000000000000000000","time":"1559219708039740330","type":"done"}
2019/05/30 14:35:08 [Info] msg: {"sequence":"1556329022389","symbol":"BTC-USDT","reason":"canceled","side":"buy","size":"1.9277424","orderId":"5cefcdfb4c06872c533237b0","price":"8721.80000000000000000000","time":"1559219708039837733","type":"done"}
2019/05/30 14:35:08 [Info] msg: {"sequence":"1556329022390","symbol":"BTC-USDT","reason":"canceled","side":"buy","size":"0.036","orderId":"5cefcdfb5137b96b7e1e33d8","price":"8721.90000000000000000000","time":"1559219708039863712","type":"done"}
2019/05/30 14:35:08 [Info] msg: {"sequence":"1556329022391","symbol":"BTC-USDT","reason":"canceled","side":"sell","size":"0.134595","orderId":"5cefcdfb4c06872c1359e14f","price":"8739.90000000000000000000","time":"1559219708039879117","type":"done"}
2019/05/30 14:35:08 [Info] msg: {"sequence":"1556329022392","symbol":"BTC-USDT","reason":"canceled","side":"buy","size":"0.324","orderId":"5cefcdfacdaba439e54e8dc2","price":"8722.00000000000000000000","time":"1559219708039892472","type":"done"}
2019/05/30 14:35:08 [Info] msg: {"sequence":"1556329022393","symbol":"BTC-USDT","reason":"canceled","side":"buy","size":"0.1498833","orderId":"5cefcdfb89fc846389b11661","price":"8721.60000000000000000000","time":"1559219708052777518","type":"done"}
2019/05/30 14:35:08 [Info] msg: {"sequence":"1556329022394","symbol":"BTC-USDT","reason":"canceled","side":"buy","size":"0.00562723","orderId":"5cefcdfbcdaba43a1e149671","price":"8723.00000000000000000000","time":"1559219708068784061","type":"done"}
2019/05/30 14:35:08 [Info] msg: {"sequence":"1556329022399","symbol":"BTC-USDT","reason":"canceled","side":"buy","size":"0.00503349","orderId":"5cefcdfa0bad452ac338ddd5","price":"8722.10000000000000000000","time":"1559219708079442640","type":"done"}
2019/05/30 14:35:08 [Info] msg: {"sequence":"1556329022406","symbol":"BTC-USDT","reason":"canceled","side":"buy","size":"0.039","orderId":"5cefcdfacdaba439e54e8df2","price":"8720.70000000000000000000","time":"1559219708188060587","type":"done"}
2019/05/30 14:35:08 [Info] msg: {"sequence":"1556329022416","symbol":"BTC-USDT","reason":"canceled","side":"buy","orderId":"5cefcdfc0bad452af7db36a8","time":"1559219708260975575","type":"done"}
2019/05/30 14:35:08 [Info] msg: {"sequence":"1556329022420","symbol":"BTC-USDT","reason":"canceled","side":"buy","orderId":"5cefcdfc4c06872c1359e1a5","time":"1559219708730868756","type":"done"}
2019/05/30 14:35:09 [Info] msg: {"sequence":"1556329022425","symbol":"BTC-USDT","reason":"canceled","side":"buy","size":"0.1228","orderId":"5cefcdfac788c671eab3d793","price":"8721.40000000000000000000","time":"1559219709012438711","type":"done"}
2019/05/30 14:35:09 [Info] msg: {"sequence":"1556329022426","symbol":"BTC-USDT","reason":"canceled","side":"sell","size":"0.1237626","orderId":"5cefcdfb0bad452ac338de13","price":"8740.00000000000000000000","time":"1559219709022378690","type":"done"}
2019/05/30 14:35:09 [Info] msg: {"sequence":"1556329022427","symbol":"BTC-USDT","reason":"canceled","side":"buy","size":"0.1125","orderId":"5cefcdfa5137b96bcaf948f8","price":"8721.50000000000000000000","time":"1559219709022456698","type":"done"}
2019/05/30 14:35:09 [Info] msg: {"sequence":"1556329022428","symbol":"BTC-USDT","reason":"canceled","side":"sell","size":"0.0760626","orderId":"5cefcdfc89fc846389b1169b","price":"8739.60000000000000000000","time":"1559219709022480394","type":"done"}
2019/05/30 14:35:09 [Info] msg: {"sequence":"1556329022429","symbol":"BTC-USDT","reason":"canceled","side":"sell","size":"0.00593818","orderId":"5cefcdfb89fc846389b11655","price":"8738.60000000000000000000","time":"1559219709032875346","type":"done"}
2019/05/30 14:35:09 [Info] msg: {"sequence":"1556329022430","symbol":"BTC-USDT","reason":"canceled","side":"sell","size":"0.0288","orderId":"5cefcdfbcdaba43a1e14966e","price":"8740.10000000000000000000","time":"1559219709032943351","type":"done"}
2019/05/30 14:35:09 [Info] msg: {"sequence":"1556329022431","symbol":"BTC-USDT","reason":"canceled","side":"buy","size":"0.00502941","orderId":"5cefcdfc89fc846389b116a8","price":"8720.10000000000000000000","time":"1559219709032959258","type":"done"}
2019/05/30 14:35:09 [Info] msg: {"sequence":"1556329022432","symbol":"BTC-USDT","reason":"canceled","side":"buy","size":"0.00780472","orderId":"5cefcdfc89fc84635089a0bd","price":"8721.00000000000000000000","time":"1559219709032979719","type":"done"}
2019/05/30 14:35:09 [Info] msg: {"sequence":"1556329022433","symbol":"BTC-USDT","reason":"canceled","side":"buy","size":"0.1498833","orderId":"5cefcdfc89fc846389b116a7","price":"8720.00000000000000000000","time":"1559219709032998964","type":"done"}
2019/05/30 14:35:09 [Info] msg: {"sequence":"1556329022434","symbol":"BTC-USDT","reason":"canceled","side":"buy","size":"0.45","orderId":"5cefcdfc5137b96b7e1e3415","price":"8719.90000000000000000000","time":"1559219709033015520","type":"done"}
2019/05/30 14:35:09 [Info] msg: {"sequence":"1556329022435","symbol":"BTC-USDT","reason":"canceled","side":"sell","size":"0.5565906","orderId":"5cefcdfb89fc846389b11658","price":"8739.50000000000000000000","time":"1559219709033029378","type":"done"}
2019/05/30 14:35:09 [Info] msg: {"sequence":"1556329022446","symbol":"BTC-USDT","reason":"canceled","side":"sell","size":"0.05","orderId":"5cefcdfa4c06872c5332378a","price":"8733.40000000000000000000","time":"1559219709172365231","type":"done"}
2019/05/30 14:35:10 [Info] msg: {"sequence":"1556329022461","symbol":"BTC-USDT","reason":"canceled","side":"sell","size":"0.068731","orderId":"5cefcdfc5137b96b7e1e3436","price":"8731.50000000000000000000","time":"1559219709925111348","type":"done"}
2019/05/30 14:35:10 [Info] msg: {"sequence":"1556329022462","symbol":"BTC-USDT","reason":"canceled","side":"sell","size":"0.5565906","orderId":"5cefcdfd054b463aaf90aa57","price":"8739.40000000000000000000","time":"1559219710013171453","type":"done"}
2019/05/30 14:35:10 [Info] msg: {"sequence":"1556329022463","symbol":"BTC-USDT","reason":"canceled","side":"sell","size":"0.5565906","orderId":"5cefcdfccdaba43a1e1496ab","price":"8739.70000000000000000000","time":"1559219710029372737","type":"done"}
2019/05/30 14:35:10 [Info] msg: {"sequence":"1556329022464","symbol":"BTC-USDT","reason":"canceled","side":"sell","size":"0.00735298","orderId":"5cefcdfdcdaba43a1e1496da","price":"8738.40000000000000000000","time":"1559219710029469775","type":"done"}
2019/05/30 14:35:10 [Info] msg: {"sequence":"1556329022465","symbol":"BTC-USDT","reason":"canceled","side":"buy","size":"0.00503122","orderId":"5cefcdfd054b463aaf90aa46","price":"8720.00000000000000000000","time":"1559219710029488695","type":"done"}
2019/05/30 14:35:10 [Info] msg: {"sequence":"1556329022466","symbol":"BTC-USDT","reason":"canceled","side":"buy","size":"0.5094738","orderId":"5cefcdfccdaba439e54e8e38","price":"8719.70000000000000000000","time":"1559219710029509918","type":"done"}
2019/05/30 14:35:10 [Info] msg: {"sequence":"1556329022467","symbol":"BTC-USDT","reason":"canceled","side":"sell","size":"0.1545948","orderId":"5cefcdfd89fc846389b116dd","price":"8739.80000000000000000000","time":"1559219710040389742","type":"done"}
2019/05/30 14:35:10 [Info] msg: {"sequence":"1556329022468","symbol":"BTC-USDT","reason":"canceled","side":"sell","size":"3.78123631","orderId":"5cefcdfd89fc84635089a0f9","price":"8739.90000000000000000000","time":"1559219710040464164","type":"done"}
2019/05/30 14:35:10 [Info] msg: {"sequence":"1556329022477","symbol":"BTC-USDT","reason":"canceled","side":"buy","size":"0.0899","orderId":"5cefcdfa89fc84635089a03a","price":"8708.00000000000000000000","time":"1559219710124838867","type":"done"}
2019/05/30 14:35:10 [Info] msg: {"sequence":"1556329022484","symbol":"BTC-USDT","reason":"canceled","side":"buy","size":"0.039","orderId":"5cefcdfcc788c671eab3d805","price":"8718.90000000000000000000","time":"1559219710197943380","type":"done"}
2019/05/30 14:35:10 [Info] msg: {"sequence":"1556329022495","symbol":"BTC-USDT","reason":"canceled","side":"buy","size":"0.039","orderId":"5cefcdfec788c671eab3d883","price":"8719.80000000000000000000","time":"1559219710438695962","type":"done"}
2019/05/30 14:35:10 [Info] msg: {"sequence":"1556329022500","symbol":"BTC-USDT","reason":"canceled","side":"buy","size":"0.039","orderId":"5cefcdfe4c06872c1359e1ed","price":"8720.00000000000000000000","time":"1559219710773633602","type":"done"}
2019/05/30 14:35:11 [Info] msg: {"sequence":"1556329022501","symbol":"BTC-USDT","reason":"canceled","side":"buy","size":"0.00656221","orderId":"5cefcdfd0bad452ac338de93","price":"8720.90000000000000000000","time":"1559219710994594514","type":"done"}
2019/05/30 14:35:11 [Info] msg: {"sequence":"1556329022502","symbol":"BTC-USDT","reason":"canceled","side":"sell","size":"0.5565906","orderId":"5cefcdfe0bad452af7db3728","price":"8739.50000000000000000000","time":"1559219710994697304","type":"done"}
2019/05/30 14:35:11 [Info] msg: {"sequence":"1556329022503","symbol":"BTC-USDT","reason":"canceled","side":"buy","size":"0.036","orderId":"5cefcdfe89fc84635089a11a","price":"8719.50000000000000000000","time":"1559219711004831489","type":"done"}
2019/05/30 14:35:11 [Info] msg: {"sequence":"1556329022504","symbol":"BTC-USDT","reason":"canceled","side":"buy","size":"0.00501449","orderId":"5cefcdfe4c06872c1359e1db","price":"8720.00000000000000000000","time":"1559219711004907434","type":"done"}
2019/05/30 14:35:11 [Info] msg: {"sequence":"1556329022519","symbol":"BTC-USDT","reason":"canceled","side":"buy","size":"0.039","orderId":"5cefcdfe4c06872c53323871","price":"8719.60000000000000000000","time":"1559219711093362084","type":"done"}
2019/05/30 14:35:11 [Info] msg: {"sequence":"1556329022520","symbol":"BTC-USDT","reason":"canceled","side":"buy","size":"0.225","orderId":"5cefcdfdc788c671eab3d841","price":"8719.90000000000000000000","time":"1559219711271988057","type":"done"}
2019/05/30 14:35:11 [Info] msg: {"sequence":"1556329022521","symbol":"BTC-USDT","reason":"canceled","side":"sell","size":"0.00751133","orderId":"5cefcdfe0bad452af7db3718","price":"8738.20000000000000000000","time":"1559219711282796041","type":"done"}
2019/05/30 14:35:11 [Info] msg: {"sequence":"1556329022522","symbol":"BTC-USDT","reason":"canceled","side":"buy","size":"0.036","orderId":"5cefcdfd054b463a72e7b9d6","price":"8719.60000000000000000000","time":"1559219711302381087","type":"done"}
2019/05/30 14:35:11 [Info] msg: {"sequence":"1556329022529","symbol":"BTC-USDT","reason":"canceled","side":"buy","size":"0.039","orderId":"5cefcdfe0bad452af7db3746","price":"8719.70000000000000000000","time":"1559219711386341264","type":"done"}
2019/05/30 14:35:11 [Info] msg: {"sequence":"1556329022530","symbol":"BTC-USDT","reason":"canceled","side":"buy","size":"0.1228","orderId":"5cefcdfecdaba43a1e149712","price":"8718.60000000000000000000","time":"1559219711545214690","type":"done"}
2019/05/30 14:35:11 [Info] msg: {"sequence":"1556329022531","symbol":"BTC-USDT","reason":"canceled","side":"buy","size":"0.1125","orderId":"5cefcdfe4c06872c1359e1de","price":"8718.60000000000000000000","time":"1559219711555772657","type":"done"}
2019/05/30 14:35:11 [Info] msg: {"sequence":"1556329022532","symbol":"BTC-USDT","reason":"canceled","side":"sell","size":"0.40079","orderId":"5cefcdf9cdaba43a1e149606","price":"8733.50000000000000000000","time":"1559219711597145847","type":"done"}
2019/05/30 14:35:11 [Info] msg: {"sequence":"1556329022533","symbol":"BTC-USDT","reason":"canceled","side":"buy","size":"0.40069","orderId":"5cefcdf95137b96b7e1e3366","price":"8724.50000000000000000000","time":"1559219711607799485","type":"done"}
2019/05/30 14:35:11 [Info] msg: {"sequence":"1556329022540","symbol":"BTC-USDT","reason":"canceled","side":"buy","size":"0.039","orderId":"5cefcdff89fc846389b1176a","price":"8719.60000000000000000000","time":"1559219711712256899","type":"done"}
2019/05/30 14:35:12 [Info] msg: {"sequence":"1556329022541","symbol":"BTC-USDT","reason":"canceled","side":"sell","size":"0.00504184","orderId":"5cefcdfe054b463a72e7ba16","price":"8739.10000000000000000000","time":"1559219712004164700","type":"done"}
2019/05/30 14:35:12 [Info] msg: {"sequence":"1556329022542","symbol":"BTC-USDT","reason":"canceled","side":"sell","size":"0.00936853","orderId":"5cefcdfecdaba43a1e149737","price":"8738.20000000000000000000","time":"1559219712004286001","type":"done"}
2019/05/30 14:35:12 [Info] msg: {"sequence":"1556329022543","symbol":"BTC-USDT","reason":"canceled","side":"sell","size":"0.1237563","orderId":"5cefcdfd0bad452ac338ded1","price":"8739.20000000000000000000","time":"1559219712004316079","type":"done"}
2019/05/30 14:35:12 [Info] msg: {"sequence":"1556329022544","symbol":"BTC-USDT","reason":"canceled","side":"sell","size":"0.1435626","orderId":"5cefcdfdcdaba439e54e8e65","price":"8739.30000000000000000000","time":"1559219712004338285","type":"done"}
2019/05/30 14:35:12 [Info] msg: {"sequence":"1556329022559","symbol":"BTC-USDT","reason":"canceled","side":"buy","size":"0.039","orderId":"5cefcdff0bad452af7db3789","price":"8720.00000000000000000000","time":"1559219712050229386","type":"done"}
2019/05/30 14:35:12 [Info] msg: {"sequence":"1556329022564","symbol":"BTC-USDT","reason":"canceled","side":"buy","size":"0.1298871","orderId":"5cefcdfe054b463aaf90aab5","price":"8719.90000000000000000000","time":"1559219712131340967","type":"done"}
2019/05/30 14:35:12 [Info] msg: {"sequence":"1556329022567","symbol":"BTC-USDT","reason":"canceled","side":"sell","size":"0.05","orderId":"5cefcdfd0bad452ac338deb1","price":"8730.90000000000000000000","time":"1559219712173528357","type":"done"}
2019/05/30 14:35:12 [Info] msg: {"sequence":"1556329022568","symbol":"BTC-USDT","reason":"canceled","side":"sell","size":"1.5163173","orderId":"5cefcdfe0bad452ac338df05","price":"8739.70000000000000000000","time":"1559219712257315468","type":"done"}
2019/05/30 14:35:12 [Info] msg: {"sequence":"1556329022569","symbol":"BTC-USDT","reason":"canceled","side":"buy","size":"0.9","orderId":"5cefcdfe89fc846389b11758","price":"8720.10000000000000000000","time":"1559219712267936886","type":"done"}
2019/05/30 14:35:12 [Info] msg: {"sequence":"1556329022570","symbol":"BTC-USDT","reason":"canceled","side":"sell","size":"0.1435626","orderId":"5cefcdfec788c671b05d12e4","price":"8739.40000000000000000000","time":"1559219712278480660","type":"done"}
2019/05/30 14:35:12 [Info] msg: {"sequence":"1556329022571","symbol":"BTC-USDT","reason":"canceled","side":"buy","size":"0.00815224","orderId":"5cefcdffcdaba439e54e8ec1","price":"8721.10000000000000000000","time":"1559219712289224522","type":"done"}
2019/05/30 14:35:12 [Info] msg: {"sequence":"1556329022576","symbol":"BTC-USDT","reason":"canceled","side":"buy","size":"0.036","orderId":"5cefcdff5137b96b7e1e34ba","price":"8719.70000000000000000000","time":"1559219712342006040","type":"done"}
2019/05/30 14:35:12 [Info] msg: {"sequence":"1556329022577","symbol":"BTC-USDT","reason":"canceled","side":"buy","size":"0.2924622","orderId":"5cefcdfc89fc846389b116a0","price":"8719.80000000000000000000","time":"1559219712342085655","type":"done"}
2019/05/30 14:35:12 [Info] msg: {"sequence":"1556329022578","symbol":"BTC-USDT","reason":"canceled","side":"buy","size":"1.0866951","orderId":"5cefcdff054b463aaf90aab8","price":"8720.20000000000000000000","time":"1559219712352524978","type":"done"}
2019/05/30 14:35:12 [Info] msg: {"sequence":"1556329022587","symbol":"BTC-USDT","reason":"canceled","side":"sell","size":"0.0001","orderId":"5cefcdfa0bad452af7db364c","price":"8724.60000000000000000000","time":"1559219712625437193","type":"done"}
2019/05/30 14:35:12 [Info] msg: {"sequence":"1556329022588","symbol":"BTC-USDT","reason":"canceled","side":"buy","size":"0.229083","orderId":"5cefcdf989fc846389b115ff","price":"8721.30000000000000000000","time":"1559219712741854600","type":"done"}
2019/05/30 14:35:13 [Info] msg: {"sequence":"1556329022589","symbol":"BTC-USDT","reason":"canceled","side":"buy","size":"0.30000000","orderId":"5cefcdf2c788c671eab3d590","price":"8720.90000000000000000000","time":"1559219713120711113","type":"done"}
2019/05/30 14:35:13 [Info] msg: {"sequence":"1556329022593","symbol":"BTC-USDT","reason":"canceled","side":"buy","size":"0.1228","orderId":"5cefce004c06872c1359e250","price":"8721.50000000000000000000","time":"1559219713172190663","type":"done"}
2019/05/30 14:35:13 [Info] msg: {"sequence":"1556329022594","symbol":"BTC-USDT","reason":"canceled","side":"buy","size":"0.1125","orderId":"5cefce00cdaba43a1e1497a7","price":"8721.50000000000000000000","time":"1559219713172276748","type":"done"}
2019/05/30 14:35:13 [Info] msg: {"sequence":"1556329022595","symbol":"BTC-USDT","reason":"canceled","side":"sell","size":"0.1237563","orderId":"5cefcdffcdaba439e54e8f00","price":"8737.70000000000000000000","time":"1559219713235652796","type":"done"}
2019/05/30 14:35:13 [Info] msg: {"sequence":"1556329022596","symbol":"BTC-USDT","reason":"canceled","side":"sell","size":"0.5565906","orderId":"5cefcdff4c06872c1359e24b","price":"8738.00000000000000000000","time":"1559219713235747069","type":"done"}
2019/05/30 14:35:13 [Info] msg: {"sequence":"1556329022597","symbol":"BTC-USDT","reason":"canceled","side":"buy","size":"0.7265133","orderId":"5cefce005137b96b7e1e34f5","price":"8720.00000000000000000000","time":"1559219713235766503","type":"done"}
2019/05/30 14:35:13 [Info] msg: {"sequence":"1556329022606","symbol":"BTC-USDT","reason":"canceled","side":"buy","size":"0.039","orderId":"5cefcdff0bad452af7db37aa","price":"8718.90000000000000000000","time":"1559219713633066717","type":"done"}
2019/05/30 14:35:14 [Info] msg: {"sequence":"1556329022609","symbol":"BTC-USDT","reason":"canceled","side":"sell","size":"0.068731","orderId":"5cefcdffc788c671b05d132c","price":"8731.50000000000000000000","time":"1559219713987790625","type":"done"}
2019/05/30 14:35:14 [Info] msg: {"sequence":"1556329022610","symbol":"BTC-USDT","reason":"canceled","side":"buy","size":"0.0899","orderId":"5cefcdfecdaba43a1e14970f","price":"8708.10000000000000000000","time":"1559219714081864896","type":"done"}
2019/05/30 14:35:14 [Info] msg: {"sequence":"1556329022613","symbol":"BTC-USDT","reason":"canceled","side":"sell","size":"0.045821","orderId":"5cefcdfc0bad452af7db36c9","price":"8731.00000000000000000000","time":"1559219714181004473","type":"done"}
2019/05/30 14:35:14 [Info] msg: {"sequence":"1556329022614","symbol":"BTC-USDT","reason":"canceled","side":"sell","size":"3.8484","orderId":"5cefce010bad452ac338df9a","price":"8737.60000000000000000000","time":"1559219714243948498","type":"done"}
2019/05/30 14:35:14 [Info] msg: {"sequence":"1556329022615","symbol":"BTC-USDT","reason":"canceled","side":"buy","size":"0.0057174","orderId":"5cefce005137b96b7e1e34e9","price":"8721.20000000000000000000","time":"1559219714244037723","type":"done"}
2019/05/30 14:35:14 [Info] msg: {"sequence":"1556329022616","symbol":"BTC-USDT","reason":"canceled","side":"buy","size":"0.1498833","orderId":"5cefce004c06872c1359e259","price":"8720.30000000000000000000","time":"1559219714254605029","type":"done"}
2019/05/30 14:35:14 [Info] msg: {"sequence":"1556329022621","symbol":"BTC-USDT","reason":"canceled","side":"sell","size":"0.0416106","orderId":"5cefce014c06872c5332391c","price":"8737.70000000000000000000","time":"1559219714264542994","type":"done"}
2019/05/30 14:35:14 [Info] msg: {"sequence":"1556329022622","symbol":"BTC-USDT","reason":"canceled","side":"buy","size":"0.0515412","orderId":"5cefce01054b463aaf90ab44","price":"8720.00000000000000000000","time":"1559219714275075311","type":"done"}
2019/05/30 14:35:14 [Info] msg: {"sequence":"1556329022623","symbol":"BTC-USDT","reason":"canceled","side":"sell","size":"1.2506139","orderId":"5cefcdff4c06872c1359e244","price":"8737.50000000000000000000","time":"1559219714275151009","type":"done"}
2019/05/30 14:35:14 [Info] msg: {"sequence":"1556329022624","symbol":"BTC-USDT","reason":"canceled","side":"sell","size":"0.0001","orderId":"5cefce01054b463a72e7bafc","price":"8724.40000000000000000000","time":"1559219714275171321","type":"done"}
2019/05/30 14:35:14 [Info] msg: {"sequence":"1556329022637","symbol":"BTC-USDT","reason":"canceled","side":"buy","size":"0.5094738","orderId":"5cefce000bad452af7db37cc","price":"8720.10000000000000000000","time":"1559219714479224184","type":"done"}
2019/05/30 14:35:14 [Info] msg: {"sequence":"1556329022638","symbol":"BTC-USDT","reason":"canceled","side":"buy","size":"0.2924622","orderId":"5cefce000bad452ac338df74","price":"8720.20000000000000000000","time":"1559219714489932451","type":"done"}
2019/05/30 14:35:14 [Info] msg: {"sequence":"1556329022645","symbol":"BTC-USDT","reason":"canceled","side":"sell","size":"0.228558","orderId":"5cefcdfccdaba439e54e8e4f","price":"8740.00000000000000000000","time":"1559219714755654958","type":"done"}
2019/05/30 14:35:14 [Info] msg: {"sequence":"1556329022646","symbol":"BTC-USDT","reason":"canceled","side":"sell","size":"0.0001","orderId":"5cefcdfb054b463a72e7b97f","price":"8724.60000000000000000000","time":"1559219714766303683","type":"done"}
2019/05/30 14:35:15 [Info] msg: {"sequence":"1556329022651","symbol":"BTC-USDT","reason":"canceled","side":"buy","size":"0.02416959","orderId":"5cefcddb89fc846350899918","price":"8716.20000000000000000000","time":"1559219715143954200","type":"done"}
2019/05/30 14:35:15 [Info] msg: {"sequence":"1556329022660","symbol":"BTC-USDT","reason":"canceled","side":"sell","size":"1.2506139","orderId":"5cefce0289fc846389b11851","price":"8737.60000000000000000000","time":"1559219715238743317","type":"done"}
2019/05/30 14:35:15 [Info] msg: {"sequence":"1556329022661","symbol":"BTC-USDT","reason":"canceled","side":"sell","size":"1.0541934","orderId":"5cefce02054b463a72e7bb29","price":"8737.50000000000000000000","time":"1559219715238833999","type":"done"}
2019/05/30 14:35:15 [Info] msg: {"sequence":"1556329022664","symbol":"BTC-USDT","reason":"canceled","side":"buy","size":"0.00503188","orderId":"5cefce02054b463aaf90abb3","price":"8720.00000000000000000000","time":"1559219715249326929","type":"done"}
2019/05/30 14:35:15 [Info] msg: {"sequence":"1556329022665","symbol":"BTC-USDT","reason":"canceled","side":"buy","size":"0.00787046","orderId":"5cefce02054b463aaf90ab9c","price":"8720.90000000000000000000","time":"1559219715249430239","type":"done"}
2019/05/30 14:35:15 [Info] msg: {"sequence":"1556329022666","symbol":"BTC-USDT","reason":"canceled","side":"buy","size":"0.039","orderId":"5cefce015137b96bcaf94a8b","price":"8716.20000000000000000000","time":"1559219715249447896","type":"done"}
2019/05/30 14:35:15 [Info] msg: {"sequence":"1556329022667","symbol":"BTC-USDT","reason":"canceled","side":"buy","size":"0.0448839","orderId":"5cefce024c06872c1359e2fd","price":"8719.60000000000000000000","time":"1559219715259903375","type":"done"}
2019/05/30 14:35:15 [Info] msg: {"sequence":"1556329022680","symbol":"BTC-USDT","reason":"canceled","side":"sell","size":"0.0001","orderId":"5cefce03054b463a72e7bb66","price":"8725.40000000000000000000","time":"1559219715401944579","type":"done"}
2019/05/30 14:35:15 [Info] msg: {"sequence":"1556329022684","symbol":"BTC-USDT","reason":"canceled","side":"sell","orderId":"5cefce035137b96bcaf94b29","time":"1559219715433744263","type":"done"}
2019/05/30 14:35:15 [Info] msg: {"sequence":"1556329022685","symbol":"BTC-USDT","reason":"canceled","side":"sell","size":"0.00881168","orderId":"5cefcdffcdaba43a1e149799","price":"8736.60000000000000000000","time":"1559219715486440820","type":"done"}
2019/05/30 14:35:15 [Info] msg: {"sequence":"1556329022686","symbol":"BTC-USDT","reason":"canceled","side":"sell","size":"0.1435626","orderId":"5cefcdff4c06872c1359e247","price":"8737.90000000000000000000","time":"1559219715486525255","type":"done"}
2019/05/30 14:35:15 [Info] msg: {"sequence":"1556329022687","symbol":"BTC-USDT","reason":"canceled","side":"buy","size":"0.0515412","orderId":"5cefce004c06872c1359e25e","price":"8719.90000000000000000000","time":"1559219715486546589","type":"done"}
2019/05/30 14:35:15 [Info] msg: {"sequence":"1556329022688","symbol":"BTC-USDT","reason":"canceled","side":"buy","size":"0.412245","orderId":"5cefce024c06872c1359e2dd","price":"8719.80000000000000000000","time":"1559219715517846730","type":"done"}
2019/05/30 14:35:15 [Info] msg: {"sequence":"1556329022689","symbol":"BTC-USDT","reason":"canceled","side":"sell","size":"0.6485895","orderId":"5cefcdff89fc84635089a193","price":"8737.80000000000000000000","time":"1559219715538227108","type":"done"}
2019/05/30 14:35:15 [Info] msg: {"sequence":"1556329022692","symbol":"BTC-USDT","reason":"canceled","side":"buy","size":"0.1498833","orderId":"5cefce02cdaba43a1e14982c","price":"8719.40000000000000000000","time":"1559219715548823220","type":"done"}
2019/05/30 14:35:15 [Info] msg: {"sequence":"1556329022703","symbol":"BTC-USDT","reason":"canceled","side":"sell","size":"0.5565906","orderId":"5cefce020bad452af7db3853","price":"8738.00000000000000000000","time":"1559219715626007791","type":"done"}
2019/05/30 14:35:16 [Info] msg: {"sequence":"1556329022706","symbol":"BTC-USDT","reason":"canceled","side":"buy","size":"0.039","orderId":"5cefce030bad452af7db388e","price":"8718.60000000000000000000","time":"1559219715883040235","type":"done"}
2019/05/30 14:35:16 [Info] msg: {"sequence":"1556329022707","symbol":"BTC-USDT","reason":"canceled","side":"buy","size":"0.1228","orderId":"5cefce020bad452ac338dfe8","price":"8718.50000000000000000000","time":"1559219716029348893","type":"done"}
2019/05/30 14:35:16 [Info] msg: {"sequence":"1556329022708","symbol":"BTC-USDT","reason":"canceled","side":"sell","size":"0.148651","orderId":"5cefcdfecdaba439e54e8eb3","price":"8735.90000000000000000000","time":"1559219716050637851","type":"done"}
2019/05/30 14:35:16 [Info] msg: {"sequence":"1556329022710","symbol":"BTC-USDT","reason":"canceled","side":"sell","orderId":"5cefce03c788c671b05d14bd","time":"1559219716061602806","type":"done"}
2019/05/30 14:35:16 [Info] msg: {"sequence":"1556329022711","symbol":"BTC-USDT","reason":"canceled","side":"sell","size":"0.00500298","orderId":"5cefce034c06872c1359e325","price":"8737.70000000000000000000","time":"1559219716092128652","type":"done"}
2019/05/30 14:35:16 [Info] msg: {"sequence":"1556329022712","symbol":"BTC-USDT","reason":"canceled","side":"sell","size":"0.00555746","orderId":"5cefce03c788c671b05d1478","price":"8736.80000000000000000000","time":"1559219716092216310","type":"done"}
2019/05/30 14:35:16 [Info] msg: {"sequence":"1556329022713","symbol":"BTC-USDT","reason":"canceled","side":"buy","size":"0.1125","orderId":"5cefce02054b463a72e7bb24","price":"8718.60000000000000000000","time":"1559219716092235207","type":"done"}
2019/05/30 14:35:16 [Info] msg: {"sequence":"1556329022714","symbol":"BTC-USDT","reason":"canceled","side":"sell","size":"0.1237599","orderId":"5cefce034c06872c533239cc","price":"8737.80000000000000000000","time":"1559219716092255539","type":"done"}
2019/05/30 14:35:16 [Info] msg: {"sequence":"1556329022717","symbol":"BTC-USDT","reason":"canceled","side":"sell","size":"0.5131377","orderId":"5cefce030bad452af7db38a4","price":"8738.10000000000000000000","time":"1559219716092455261","type":"done"}
2019/05/30 14:35:16 [Info] msg: {"sequence":"1556329022718","symbol":"BTC-USDT","reason":"canceled","side":"sell","size":"0.05","orderId":"5cefce004c06872c1359e265","price":"8728.80000000000000000000","time":"1559219716134303878","type":"done"}
2019/05/30 14:35:16 [Info] msg: {"sequence":"1556329022737","symbol":"BTC-USDT","reason":"canceled","side":"buy","size":"0.039","orderId":"5cefce03c788c671b05d14ad","price":"8718.90000000000000000000","time":"1559219716186356337","type":"done"}
2019/05/30 14:35:16 [Info] msg: {"sequence":"1556329022738","symbol":"BTC-USDT","reason":"canceled","side":"sell","size":"0.6084","orderId":"5cefce03cdaba43a1e14987c","price":"8738.20000000000000000000","time":"1559219716258327316","type":"done"}
2019/05/30 14:35:16 [Info] msg: {"sequence":"1556329022739","symbol":"BTC-USDT","reason":"canceled","side":"buy","size":"0.00992551","orderId":"5cefce030bad452ac338e041","price":"8720.40000000000000000000","time":"1559219716318052855","type":"done"}
2019/05/30 14:35:16 [Info] msg: {"sequence":"1556329022740","symbol":"BTC-USDT","reason":"canceled","side":"buy","size":"0.9","orderId":"5cefce030bad452af7db3894","price":"8719.50000000000000000000","time":"1559219716329318344","type":"done"}
2019/05/30 14:35:16 [Info] msg: {"sequence":"1556329022741","symbol":"BTC-USDT","reason":"canceled","side":"buy","size":"0.9550782","orderId":"5cefce03cdaba43a1e149880","price":"8719.30000000000000000000","time":"1559219716329427507","type":"done"}
2019/05/30 14:35:16 [Info] msg: {"sequence":"1556329022742","symbol":"BTC-USDT","reason":"canceled","side":"buy","size":"0.1644021","orderId":"5cefce03054b463aaf90abf0","price":"8719.10000000000000000000","time":"1559219716329446896","type":"done"}
2019/05/30 14:35:16 [Info] msg: {"sequence":"1556329022751","symbol":"BTC-USDT","reason":"canceled","side":"buy","size":"0.1498833","orderId":"5cefce03c788c671b05d1498","price":"8718.90000000000000000000","time":"1559219716435053415","type":"done"}
2019/05/30 14:35:16 [Info] msg: {"sequence":"1556329022752","symbol":"BTC-USDT","reason":"canceled","side":"sell","size":"0.091642","orderId":"5cefcdfd0bad452ac338dea0","price":"8734.60000000000000000000","time":"1559219716508896504","type":"done"}
2019/05/30 14:35:17 [Info] msg: {"sequence":"1556329022763","symbol":"BTC-USDT","reason":"canceled","side":"sell","size":"0.099953","orderId":"5cefcdfd5137b96bcaf9498a","price":"8737.10000000000000000000","time":"1559219716936877622","type":"done"}
2019/05/30 14:35:17 [Info] msg: {"sequence":"1556329022768","symbol":"BTC-USDT","reason":"canceled","side":"buy","size":"0.039","orderId":"5cefce044c06872c1359e362","price":"8719.20000000000000000000","time":"1559219717157689742","type":"done"}
2019/05/30 14:35:17 [Info] msg: {"sequence":"1556329022769","symbol":"BTC-USDT","reason":"canceled","side":"sell","size":"0.06874","orderId":"5cefce035137b96b7e1e35b9","price":"8730.40000000000000000000","time":"1559219717304617307","type":"done"}
2019/05/30 14:35:18 [Info] msg: {"sequence":"1556329022770","symbol":"BTC-USDT","reason":"canceled","side":"sell","size":"0.00503777","orderId":"5cefce04c788c671eab3da2b","price":"8738.90000000000000000000","time":"1559219718105663513","type":"done"}
2019/05/30 14:35:18 [Info] msg: {"sequence":"1556329022771","symbol":"BTC-USDT","reason":"canceled","side":"sell","size":"0.5574681","orderId":"5cefce0489fc846389b118c6","price":"8739.00000000000000000000","time":"1559219718105789457","type":"done"}
2019/05/30 14:35:18 [Info] msg: {"sequence":"1556329022772","symbol":"BTC-USDT","reason":"canceled","side":"sell","size":"0.6084","orderId":"5cefce04c788c671eab3da2e","price":"8739.10000000000000000000","time":"1559219718116349517","type":"done"}
2019/05/30 14:35:18 [Info] msg: {"sequence":"1556329022773","symbol":"BTC-USDT","reason":"canceled","side":"sell","size":"2.8077948","orderId":"5cefce04cdaba439e54e8ff9","price":"8739.20000000000000000000","time":"1559219718116434996","type":"done"}
2019/05/30 14:35:18 [Info] msg: {"sequence":"1556329022774","symbol":"BTC-USDT","reason":"canceled","side":"sell","size":"0.05","orderId":"5cefce045137b96bcaf94b6d","price":"8730.30000000000000000000","time":"1559219718116456470","type":"done"}
2019/05/30 14:35:18 [Info] msg: {"sequence":"1556329022775","symbol":"BTC-USDT","reason":"canceled","side":"buy","size":"2.4370569","orderId":"5cefce040bad452ac338e06e","price":"8719.40000000000000000000","time":"1559219718116472989","type":"done"}
2019/05/30 14:35:18 [Info] msg: {"sequence":"1556329022776","symbol":"BTC-USDT","reason":"canceled","side":"buy","size":"0.412245","orderId":"5cefce034c06872c533239c2","price":"8719.20000000000000000000","time":"1559219718126816675","type":"done"}
2019/05/30 14:35:18 [Info] msg: {"sequence":"1556329022777","symbol":"BTC-USDT","reason":"canceled","side":"sell","size":"0.0311022","orderId":"5cefce034c06872c1359e32d","price":"8738.00000000000000000000","time":"1559219718126890263","type":"done"}
2019/05/30 14:35:18 [Info] msg: {"sequence":"1556329022778","symbol":"BTC-USDT","reason":"canceled","side":"sell","size":"0.9217341","orderId":"5cefce044c06872c1359e35f","price":"8739.30000000000000000000","time":"1559219718126911339","type":"done"}
2019/05/30 14:35:18 [Info] msg: {"sequence":"1556329022781","symbol":"BTC-USDT","reason":"canceled","side":"buy","size":"0.2924622","orderId":"5cefce04c788c671b05d14c1","price":"8719.60000000000000000000","time":"1559219718168313688","type":"done"}
2019/05/30 14:35:18 [Info] msg: {"sequence":"1556329022782","symbol":"BTC-USDT","reason":"canceled","side":"buy","size":"0.5094738","orderId":"5cefce0489fc846389b118d6","price":"8719.50000000000000000000","time":"1559219718168389979","type":"done"}
2019/05/30 14:35:18 [Info] msg: {"sequence":"1556329022793","symbol":"BTC-USDT","reason":"canceled","side":"buy","size":"0.0899","orderId":"5cefce024c06872c1359e2c6","price":"8707.80000000000000000000","time":"1559219718408093783","type":"done"}
2019/05/30 14:35:19 [Info] msg: {"sequence":"1556329022804","symbol":"BTC-USDT","reason":"canceled","side":"buy","size":"0.039","orderId":"5cefce05054b463aaf90ac5b","price":"8715.60000000000000000000","time":"1559219719720916370","type":"done"}
2019/05/30 14:35:20 [Info] msg: {"sequence":"1556329022807","symbol":"BTC-USDT","reason":"canceled","side":"buy","size":"0.1228","orderId":"5cefce0789fc846389b1196d","price":"8718.90000000000000000000","time":"1559219720237106499","type":"done"}
2019/05/30 14:35:20 [Info] msg: {"sequence":"1556329022808","symbol":"BTC-USDT","reason":"canceled","side":"buy","size":"0.1125","orderId":"5cefce045137b96bcaf94b7b","price":"8718.90000000000000000000","time":"1559219720237223132","type":"done"}
2019/05/30 14:35:20 [Info] msg: {"sequence":"1556329022811","symbol":"BTC-USDT","reason":"canceled","side":"buy","size":"0.039","orderId":"5cefce07cdaba439e54e90a3","price":"8719.10000000000000000000","time":"1559219720692414953","type":"done"}
2019/05/30 14:35:21 [Info] msg: {"sequence":"1556329022818","symbol":"BTC-USDT","reason":"canceled","side":"buy","size":"0.039","orderId":"5cefce085137b96bcaf94c48","price":"8719.30000000000000000000","time":"1559219721330709945","type":"done"}
2019/05/30 14:35:21 [Info] msg: {"sequence":"1556329022821","symbol":"BTC-USDT","reason":"canceled","side":"buy","size":"0.039","orderId":"5cefce09cdaba43a1e1499c7","price":"8715.60000000000000000000","time":"1559219721656755974","type":"done"}
2019/05/30 14:35:22 [Info] msg: {"sequence":"1556329022822","symbol":"BTC-USDT","reason":"canceled","side":"buy","size":"0.0899","orderId":"5cefce060bad452ac338e0d1","price":"8707.90000000000000000000","time":"1559219722078159303","type":"done"}
2019/05/30 14:35:22 [Info] msg: {"sequence":"1556329022825","symbol":"BTC-USDT","reason":"canceled","side":"sell","size":"0.9217341","orderId":"5cefce0689fc84635089a30d","price":"8736.30000000000000000000","time":"1559219722257633146","type":"done"}
2019/05/30 14:35:22 [Info] msg: {"sequence":"1556329022826","symbol":"BTC-USDT","reason":"canceled","side":"sell","size":"1.2506139","orderId":"5cefce0689fc84635089a338","price":"8736.50000000000000000000","time":"1559219722320900287","type":"done"}
2019/05/30 14:35:22 [Info] msg: {"sequence":"1556329022827","symbol":"BTC-USDT","reason":"canceled","side":"buy","size":"0.00749387","orderId":"5cefce04c788c671eab3da31","price":"8720.50000000000000000000","time":"1559219722331630961","type":"done"}
2019/05/30 14:35:22 [Info] msg: {"sequence":"1556329022828","symbol":"BTC-USDT","reason":"canceled","side":"buy","size":"0.0515412","orderId":"5cefce04c788c671b05d14cc","price":"8719.30000000000000000000","time":"1559219722341290616","type":"done"}
2019/05/30 14:35:22 [Info] msg: {"sequence":"1556329022829","symbol":"BTC-USDT","reason":"canceled","side":"sell","size":"0.00744841","orderId":"5cefce064c06872c53323a59","price":"8735.30000000000000000000","time":"1559219722341364490","type":"done"}
2019/05/30 14:35:22 [Info] msg: {"sequence":"1556329022830","symbol":"BTC-USDT","reason":"canceled","side":"sell","size":"2.8077948","orderId":"5cefce060bad452af7db3930","price":"8736.20000000000000000000","time":"1559219722341404648","type":"done"}
2019/05/30 14:35:22 [Info] msg: {"sequence":"1556329022833","symbol":"BTC-USDT","reason":"canceled","side":"buy","size":"0.1228","orderId":"5cefce08054b463aaf90ad37","price":"8722.00000000000000000000","time":"1559219722373424603","type":"done"}
2019/05/30 14:35:22 [Info] msg: {"sequence":"1556329022836","symbol":"BTC-USDT","reason":"canceled","side":"sell","size":"0.6485895","orderId":"5cefce06c788c671eab3dabb","price":"8736.70000000000000000000","time":"1559219722669750214","type":"done"}
2019/05/30 14:35:23 [Info] msg: {"sequence":"1556329022841","symbol":"BTC-USDT","reason":"canceled","side":"sell","size":"0.02416959","orderId":"5cefcde3c788c671b05d0ca0","price":"8747.50000000000000000000","time":"1559219723163372872","type":"done"}
2019/05/30 14:35:23 [Info] msg: {"sequence":"1556329022844","symbol":"BTC-USDT","reason":"canceled","side":"buy","size":"0.039","orderId":"5cefce095137b96bcaf94c7e","price":"8719.30000000000000000000","time":"1559219723246566597","type":"done"}
2019/05/30 14:35:24 [Info] msg: {"sequence":"1556329022859","symbol":"BTC-USDT","reason":"canceled","side":"buy","size":"0.229116","orderId":"5cefce044c06872c1359e392","price":"8723.80000000000000000000","time":"1559219723954747329","type":"done"}
2019/05/30 14:35:24 [Info] msg: {"sequence":"1556329022862","symbol":"BTC-USDT","reason":"canceled","side":"buy","size":"0.078667","orderId":"5cefce040bad452af7db38df","price":"8723.40000000000000000000","time":"1559219723975393796","type":"done"}
2019/05/30 14:35:24 [Info] msg: {"sequence":"1556329022867","symbol":"BTC-USDT","reason":"canceled","side":"sell","size":"0.05","orderId":"5cefce06cdaba439e54e9062","price":"8731.40000000000000000000","time":"1559219724187036764","type":"done"}
2019/05/30 14:35:24 [Info] msg: {"sequence":"1556329022870","symbol":"BTC-USDT","reason":"canceled","side":"sell","size":"1.0541934","orderId":"5cefce065137b96b7e1e3678","price":"8736.40000000000000000000","time":"1559219724218378655","type":"done"}
2019/05/30 14:35:24 [Info] msg: {"sequence":"1556329022871","symbol":"BTC-USDT","reason":"canceled","side":"buy","size":"0.5094738","orderId":"5cefce064c06872c1359e3ec","price":"8719.10000000000000000000","time":"1559219724239688951","type":"done"}
