2019/05/30 14:35:24 [Info] msg: {"sequence":"1556329022876","symbol":"BTC-USDT","reason":"canceled","side":"buy","size":"0.1125","orderId":"5cefce0889fc84635089a399","price":"8722.10000000000000000000","time":"1559219724515168752","type":"done"}
2019/05/30 14:35:24 [Info] msg: {"sequence":"1556329022877","symbol":"BTC-USDT","reason":"canceled","side":"buy","size":"0.1228","orderId":"5cefce0a054b463a72e7bd0b","price":"8722.20000000000000000000","time":"1559219724515258991","type":"done"}
2019/05/30 14:35:25 [Info] msg: {"sequence":"1556329022878","symbol":"BTC-USDT","reason":"canceled","side":"sell","size":"0.091654","orderId":"5cefce0b89fc84635089a429","price":"8733.40000000000000000000","time":"1559219725080854860","type":"done"}
2019/05/30 14:35:25 [Info] msg: {"sequence":"1556329022879","symbol":"BTC-USDT","reason":"canceled","side":"sell","size":"0.0050461","orderId":"5cefce0c4c06872c1359e534","price":"8738.70000000000000000000","time":"1559219725080960203","type":"done"}
2019/05/30 14:35:25 [Info] msg: {"sequence":"1556329022882","symbol":"BTC-USDT","reason":"canceled","side":"sell","size":"0.134595","orderId":"5cefce0a4c06872c1359e4d8","price":"8739.00000000000000000000","time":"1559219725091496641","type":"done"}
2019/05/30 14:35:25 [Info] msg: {"sequence":"1556329022883","symbol":"BTC-USDT","reason":"canceled","side":"sell","size":"0.0593379","orderId":"5cefce0bcdaba439e54e9177","price":"8739.20000000000000000000","time":"1559219725091524976","type":"done"}
2019/05/30 14:35:25 [Info] msg: {"sequence":"1556329022884","symbol":"BTC-USDT","reason":"canceled","side":"sell","size":"0.00682217","orderId":"5cefce0a054b463aaf90adb9","price":"8737.80000000000000000000","time":"1559219725091539910","type":"done"}
2019/05/30 14:35:25 [Info] msg: {"sequence":"1556329022887","symbol":"BTC-USDT","reason":"canceled","side":"buy","size":"0.9","orderId":"5cefce0bcdaba43a1e149a2f","price":"8719.70000000000000000000","time":"1559219725102207669","type":"done"}
2019/05/30 14:35:25 [Info] msg: {"sequence":"1556329022888","symbol":"BTC-USDT","reason":"canceled","side":"buy","size":"0.00872896","orderId":"5cefce0b89fc846389b11a32","price":"8720.80000000000000000000","time":"1559219725113634339","type":"done"}
2019/05/30 14:35:25 [Info] msg: {"sequence":"1556329022889","symbol":"BTC-USDT","reason":"canceled","side":"sell","size":"1.5163173","orderId":"5cefce0a4c06872c1359e4d5","price":"8738.90000000000000000000","time":"1559219725113705368","type":"done"}
2019/05/30 14:35:25 [Info] msg: {"sequence":"1556329022890","symbol":"BTC-USDT","reason":"canceled","side":"sell","size":"0.0795699","orderId":"5cefce0cc788c671eab3dbf1","price":"8739.10000000000000000000","time":"1559219725113737313","type":"done"}
2019/05/30 14:35:25 [Info] msg: {"sequence":"1556329022893","symbol":"BTC-USDT","reason":"canceled","side":"buy","size":"0.45","orderId":"5cefce0b0bad452ac338e1d7","price":"8719.90000000000000000000","time":"1559219725134539024","type":"done"}
2019/05/30 14:35:25 [Info] msg: {"sequence":"1556329022894","symbol":"BTC-USDT","reason":"canceled","side":"buy","size":"0.1415439","orderId":"5cefce0bcdaba43a1e149a2c","price":"8719.80000000000000000000","time":"1559219725186097470","type":"done"}
2019/05/30 14:35:25 [Info] msg: {"sequence":"1556329022903","symbol":"BTC-USDT","reason":"canceled","side":"sell","size":"0.22862","orderId":"5cefce0b0bad452ac338e1f3","price":"8737.60000000000000000000","time":"1559219725334127437","type":"done"}
2019/05/30 14:35:25 [Info] msg: {"sequence":"1556329022904","symbol":"BTC-USDT","reason":"canceled","side":"sell","size":"0.045827","orderId":"5cefce0bc788c671eab3dbe2","price":"8729.80000000000000000000","time":"1559219725355601397","type":"done"}
2019/05/30 14:35:25 [Info] msg: {"sequence":"1556329022905","symbol":"BTC-USDT","reason":"canceled","side":"sell","size":"0.099967","orderId":"5cefce0bc788c671b05d1626","price":"8735.90000000000000000000","time":"1559219725376070536","type":"done"}
2019/05/30 14:35:25 [Info] msg: {"sequence":"1556329022908","symbol":"BTC-USDT","reason":"canceled","side":"buy","size":"0.1228","orderId":"5cefce0d89fc84635089a472","price":"8719.60000000000000000000","time":"1559219725573926245","type":"done"}
2019/05/30 14:35:25 [Info] msg: {"sequence":"1556329022909","symbol":"BTC-USDT","reason":"canceled","side":"buy","size":"0.1125","orderId":"5cefce0dc788c671b05d1679","price":"8719.60000000000000000000","time":"1559219725584579218","type":"done"}
2019/05/30 14:35:26 [Info] msg: {"sequence":"1556329022912","symbol":"BTC-USDT","reason":"canceled","side":"buy","size":"0.0899","orderId":"5cefce0a054b463a72e7bcde","price":"8708.00000000000000000000","time":"1559219726077077085","type":"done"}
2019/05/30 14:35:26 [Info] msg: {"sequence":"1556329022917","symbol":"BTC-USDT","reason":"canceled","side":"sell","size":"1.0541934","orderId":"5cefce0d5137b96b7e1e37a0","price":"8737.00000000000000000000","time":"1559219726182973319","type":"done"}
2019/05/30 14:35:26 [Info] msg: {"sequence":"1556329022918","symbol":"BTC-USDT","reason":"canceled","side":"sell","size":"0.05","orderId":"5cefce0cc788c671b05d1655","price":"8729.70000000000000000000","time":"1559219726183059115","type":"done"}
2019/05/30 14:35:26 [Info] msg: {"sequence":"1556329022919","symbol":"BTC-USDT","reason":"canceled","side":"buy","size":"0.1185453","orderId":"5cefce0d4c06872c1359e57e","price":"8719.10000000000000000000","time":"1559219726183078800","type":"done"}
