2019/08/25 18:31:23 [Info] received msg: {"id":"","type":"message","sn":"","topic":"/market/level3:BTC-USDT","subject":"trade.l3done","data":{"sequence":"1556573506478","symbol":"BTC-USDT","reason":"canceled","side":"buy","size":"0.10000000","orderId":"5d62b7da4c06876f06c44753","price":"10062.90000000000000000000","time":"1566750683413829605","type":"done"}}
2019/08/25 18:31:23 [Info] received msg: {"id":"","type":"message","sn":"","topic":"/market/level3:BTC-USDT","subject":"trade.l3done","data":{"sequence":"1556573506481","symbol":"BTC-USDT","reason":"canceled","side":"buy","size":"0.00016680","orderId":"5d62b7dac788c64261a56d9e","price":"10062.80000000000000000000","time":"1566750683583346955","type":"done"}}
2019/08/25 18:31:23 [Info] received msg: {"id":"","type":"message","sn":"","topic":"/market/level3:BTC-USDT","subject":"trade.l3done","data":{"sequence":"1556573506493","symbol":"BTC-USDT","reason":"canceled","side":"buy","orderId":"5d62b7dbcdaba42f8cfbc355","time":"1566750683777149643","type":"done"}}
2019/08/25 18:31:24 [Info] received msg: {"id":"","type":"message","sn":"","topic":"/market/level3:BTC-USDT","subject":"trade.l3done","data":{"sequence":"1556573506494","symbol":"BTC-USDT","reason":"canceled","side":"buy","size":"0.49710673","orderId":"5d62b7da4c06876f06c44686","price":"10058.00000000000000000000","time":"1566750683896077871","type":"done"}}
2019/08/25 18:31:24 [Info] received msg: {"id":"","type":"message","sn":"","topic":"/market/level3:BTC-USDT","subject":"trade.l3done","data":{"sequence":"1556573506495","symbol":"BTC-USDT","reason":"canceled","side":"sell","size":"0.50000997","orderId":"5d62b7da4c06876f06c446a2","price":"10074.10000000000000000000","time":"1566750683896174889","type":"done"}}
2019/08/25 18:31:24 [Info] received msg: {"id":"","type":"message","sn":"","topic":"/market/level3:BTC-USDT","subject":"trade.l3done","data":{"sequence":"1556573506496","symbol":"BTC-USDT","reason":"canceled","side":"sell","size":"0.1125","orderId":"5d62b7d94c06876f06c44604","price":"10068.60000000000000000000","time":"1566750684220118089","type":"done"}}
2019/08/25 18:31:24 [Info] received msg: {"id":"","type":"message","sn":"","topic":"/market/level3:BTC-USDT","subject":"trade.l3done","data":{"sequence":"1556573506499","symbol":"BTC-USDT","reason":"canceled","side":"buy","size":"0.16671785","orderId":"5d62b7d1c788c64261a564cf","price":"10062.30000000000000000000","time":"1566750684348762570","type":"done"}}
2019/08/25 18:31:24 [Info] received msg: {"id":"","type":"message","sn":"","topic":"/market/level3:BTC-USDT","subject":"trade.l3done","data":{"sequence":"1556573506500","symbol":"BTC-USDT","reason":"canceled","side":"sell","size":"0.0467","orderId":"5d62b7d9cdaba42f8cfbc162","price":"10109.40000000000000000000","time":"1566750684348858709","type":"done"}}
2019/08/25 18:31:24 [Info] received msg: {"id":"","type":"message","sn":"","topic":"/market/level3:BTC-USDT","subject":"trade.l3done","data":{"sequence":"1556573506503","symbol":"BTC-USDT","reason":"canceled","side":"buy","size":"0.125","orderId":"5d62b7d8c788c64261a56c2b","price":"10019.50000000000000000000","time":"1566750684392254048","type":"done"}}
2019/08/25 18:31:24 [Info] received msg: {"id":"","type":"message","sn":"","topic":"/market/level3:BTC-USDT","subject":"trade.l3done","data":{"sequence":"1556573506513","symbol":"BTC-USDT","reason":"canceled","side":"buy","orderId":"5d62b7dc4c06876f06c448cf","time":"1566750684556889086","type":"done"}}
2019/08/25 18:31:24 [Info] received msg: {"id":"","type":"message","sn":"","topic":"/market/level3:BTC-USDT","subject":"trade.l3done","data":{"sequence":"1556573506516","symbol":"BTC-USDT","reason":"canceled","side":"buy","size":"0.11114790","orderId":"5d62b7d9cdaba42f8cfbc148","price":"10062.50000000000000000000","time":"1566750684589669505","type":"done"}}
2019/08/25 18:31:24 [Info] received msg: {"id":"","type":"message","sn":"","topic":"/market/level3:BTC-USDT","subject":"trade.l3done","data":{"sequence":"1556573506521","symbol":"BTC-USDT","reason":"canceled","side":"buy","size":"0.29879882","orderId":"5d62b7db0bad4556c808e979","price":"10040.20000000000000000000","time":"1566750684827446045","type":"done"}}
2019/08/25 18:31:25 [Info] received msg: {"id":"","type":"message","sn":"","topic":"/market/level3:BTC-USDT","subject":"trade.l3done","data":{"sequence":"1556573506532","symbol":"BTC-USDT","reason":"canceled","side":"sell","size":"0.1125","orderId":"5d62b7dc4c06876f06c448c7","price":"10068.30000000000000000000","time":"1566750685395647253","type":"done"}}
2019/08/25 18:31:26 [Info] received msg: {"id":"","type":"message","sn":"","topic":"/market/level3:BTC-USDT","subject":"trade.l3done","data":{"sequence":"1556573506539","symbol":"BTC-USDT","reason":"canceled","side":"sell","size":"0.33413","orderId":"5d62b7cec788c64261a56219","price":"10087.80000000000000000000","time":"1566750686049579053","type":"done"}}
2019/08/25 18:31:26 [Info] received msg: {"id":"","type":"message","sn":"","topic":"/market/level3:BTC-USDT","subject":"trade.l3done","data":{"sequence":"1556573506545","symbol":"BTC-USDT","reason":"canceled","side":"buy","orderId":"5d62b7dec788c64261a5710d","time":"1566750686213366285","type":"done"}}
2019/08/25 18:31:26 [Info] received msg: {"id":"","type":"message","sn":"","topic":"/market/level3:BTC-USDT","subject":"trade.l3done","data":{"sequence":"1556573506554","symbol":"BTC-USDT","reason":"canceled","side":"buy","size":"0.517","orderId":"5d62b6d55137b940c51d3c65","price":"10036.30000000000000000000","time":"1566750686454842038","type":"done"}}
2019/08/25 18:31:26 [Info] received msg: {"id":"","type":"message","sn":"","topic":"/market/level3:BTC-USDT","subject":"trade.l3done","data":{"sequence":"1556573506555","symbol":"BTC-USDT","reason":"canceled","side":"sell","size":"0.517","orderId":"5d62b6d5c788c64261a48810","price":"10111.70000000000000000000","time":"1566750686465594618","type":"done"}}
2019/08/25 18:31:26 [Info] received msg: {"id":"","type":"message","sn":"","topic":"/market/level3:BTC-USDT","subject":"trade.l3done","data":{"sequence":"1556573506560","symbol":"BTC-USDT","reason":"canceled","side":"buy","size":"0.11115777","orderId":"5d62b7dc4c06876f06c44928","price":"10063.00000000000000000000","time":"1566750686568710759","type":"done"}}
2019/08/25 18:31:27 [Info] received msg: {"id":"","type":"message","sn":"","topic":"/market/level3:BTC-USDT","subject":"trade.l3done","data":{"sequence":"1556573506569","symbol":"BTC-USDT","reason":"canceled","side":"sell","size":"0.1125","orderId":"5d62b7de89fc844d237de69d","price":"10068.30000000000000000000","time":"1566750687170891009","type":"done"}}
2019/08/25 18:31:27 [Info] received msg: {"id":"","type":"message","sn":"","topic":"/market/level3:BTC-USDT","subject":"trade.l3done","data":{"sequence":"1556573506588","symbol":"BTC-USDT","reason":"canceled","side":"buy","size":"0.40079","orderId":"5d62b7d04c06876f06c43dec","price":"10061.10000000000000000000","time":"1566750687760860772","type":"done"}}
2019/08/25 18:31:27 [Info] received msg: {"id":"","type":"message","sn":"","topic":"/market/level3:BTC-USDT","subject":"trade.l3done","data":{"sequence":"1556573506589","symbol":"BTC-USDT","reason":"canceled","side":"sell","size":"1.72993","orderId":"5d62b7d3c788c64261a56703","price":"10083.90000000000000000000","time":"1566750687771568181","type":"done"}}
2019/08/25 18:31:27 [Info] received msg: {"id":"","type":"message","sn":"","topic":"/market/level3:BTC-USDT","subject":"trade.l3done","data":{"sequence":"1556573506590","symbol":"BTC-USDT","reason":"canceled","side":"buy","size":"1.60339","orderId":"5d62b7d0cdaba42f8cfbb998","price":"10049.00000000000000000000","time":"1566750687771657706","type":"done"}}
2019/08/25 18:31:27 [Info] received msg: {"id":"","type":"message","sn":"","topic":"/market/level3:BTC-USDT","subject":"trade.l3done","data":{"sequence":"1556573506591","symbol":"BTC-USDT","reason":"canceled","side":"sell","size":"0.40079","orderId":"5d62b7d05137b940c51e1736","price":"10071.30000000000000000000","time":"1566750687771682348","type":"done"}}
2019/08/25 18:31:27 [Info] received msg: {"id":"","type":"message","sn":"","topic":"/market/level3:BTC-USDT","subject":"trade.l3done","data":{"sequence":"1556573506592","symbol":"BTC-USDT","reason":"canceled","side":"buy","size":"1.60339","orderId":"5d62b7d3c788c64261a56711","price":"10040.60000000000000000000","time":"1566750687781156234","type":"done"}}
2019/08/25 18:31:27 [Info] received msg: {"id":"","type":"message","sn":"","topic":"/market/level3:BTC-USDT","subject":"trade.l3done","data":{"sequence":"1556573506593","symbol":"BTC-USDT","reason":"canceled","side":"sell","size":"1.72993","orderId":"5d62b7d35137b940c51e1a2d","price":"10092.60000000000000000000","time":"1566750687781243931","type":"done"}}
2019/08/25 18:31:28 [Info] received msg: {"id":"","type":"message","sn":"","topic":"/market/level3:BTC-USDT","subject":"trade.l3done","data":{"sequence":"1556573506620","symbol":"BTC-USDT","reason":"canceled","side":"sell","size":"0.50000997","orderId":"5d62b7de5137b940c51e245c","price":"10071.90000000000000000000","time":"1566750688521521560","type":"done"}}
2019/08/25 18:31:28 [Info] received msg: {"id":"","type":"message","sn":"","topic":"/market/level3:BTC-USDT","subject":"trade.l3done","data":{"sequence":"1556573506621","symbol":"BTC-USDT","reason":"canceled","side":"buy","size":"0.49721549","orderId":"5d62b7dec788c64261a571b3","price":"10055.80000000000000000000","time":"1566750688521605025","type":"done"}}
2019/08/25 18:31:28 [Info] received msg: {"id":"","type":"message","sn":"","topic":"/market/level3:BTC-USDT","subject":"trade.l3done","data":{"sequence":"1556573506622","symbol":"BTC-USDT","reason":"canceled","side":"buy","size":"0.29884347","orderId":"5d62b7df054b4671f3c838e1","price":"10038.70000000000000000000","time":"1566750688714478139","type":"done"}}
2019/08/25 18:31:29 [Info] received msg: {"id":"","type":"message","sn":"","topic":"/market/level3:BTC-USDT","subject":"trade.l3done","data":{"sequence":"1556573506623","symbol":"BTC-USDT","reason":"canceled","side":"buy","size":"0.011907","orderId":"5d62b6f3054b4671f3c76a7c","price":"10061.50000000000000000000","time":"1566750688937745171","type":"done"}}
2019/08/25 18:31:29 [Info] received msg: {"id":"","type":"message","sn":"","topic":"/market/level3:BTC-USDT","subject":"trade.l3done","data":{"sequence":"1556573506626","symbol":"BTC-USDT","reason":"canceled","side":"buy","size":"0.00016680","orderId":"5d62b7dfcdaba42f8cfbc69d","price":"10063.00000000000000000000","time":"1566750688980028641","type":"done"}}
2019/08/25 18:31:29 [Info] received msg: {"id":"","type":"message","sn":"","topic":"/market/level3:BTC-USDT","subject":"trade.l3done","data":{"sequence":"1556573506627","symbol":"BTC-USDT","reason":"canceled","side":"sell","size":"0.0467","orderId":"5d62b7dc89fc844d237de4c6","price":"10109.30000000000000000000","time":"1566750689012500380","type":"done"}}
2019/08/25 18:31:29 [Info] received msg: {"id":"","type":"message","sn":"","topic":"/market/level3:BTC-USDT","subject":"trade.l3done","data":{"sequence":"1556573506628","symbol":"BTC-USDT","reason":"canceled","side":"buy","size":"0.125","orderId":"5d62b7dc5137b940c51e21d2","price":"10019.60000000000000000000","time":"1566750689023433169","type":"done"}}
2019/08/25 18:31:29 [Info] received msg: {"id":"","type":"message","sn":"","topic":"/market/level3:BTC-USDT","subject":"trade.l3done","data":{"sequence":"1556573506629","symbol":"BTC-USDT","reason":"canceled","side":"sell","size":"0.33413","orderId":"5d62b6cbcdaba42f8cfae042","price":"10095.50000000000000000000","time":"1566750689081426107","type":"done"}}
2019/08/25 18:31:29 [Info] received msg: {"id":"","type":"message","sn":"","topic":"/market/level3:BTC-USDT","subject":"trade.l3done","data":{"sequence":"1556573506630","symbol":"BTC-USDT","reason":"canceled","side":"sell","size":"0.1125","orderId":"5d62b7e04c06876f06c44c67","price":"10066.40000000000000000000","time":"1566750689179567708","type":"done"}}
2019/08/25 18:31:29 [Info] received msg: {"id":"","type":"message","sn":"","topic":"/market/level3:BTC-USDT","subject":"trade.l3done","data":{"sequence":"1556573506633","symbol":"BTC-USDT","reason":"canceled","side":"sell","size":"0.10682853","orderId":"5d62b7d05137b940c51e1697","price":"10074.40000000000000000000","time":"1566750689236036475","type":"done"}}
2019/08/25 18:31:29 [Info] received msg: {"id":"","type":"message","sn":"","topic":"/market/level3:BTC-USDT","subject":"trade.l3done","data":{"sequence":"1556573506644","symbol":"BTC-USDT","reason":"canceled","side":"buy","size":"0.04122233","orderId":"5d62b7d05137b940c51e16bc","price":"10058.30000000000000000000","time":"1566750689310760765","type":"done"}}
2019/08/25 18:31:29 [Info] received msg: {"id":"","type":"message","sn":"","topic":"/market/level3:BTC-USDT","subject":"trade.l3done","data":{"sequence":"1556573506647","symbol":"BTC-USDT","reason":"canceled","side":"sell","size":"0.00095405","orderId":"5d62b7ce89fc844d237dd74c","price":"10076.50000000000000000000","time":"1566750689386978966","type":"done"}}
2019/08/25 18:31:29 [Info] received msg: {"id":"","type":"message","sn":"","topic":"/market/level3:BTC-USDT","subject":"trade.l3done","data":{"sequence":"1556573506652","symbol":"BTC-USDT","reason":"canceled","side":"buy","size":"0.14819536","orderId":"5d62b7ce0bad4556c808dd33","price":"10056.40000000000000000000","time":"1566750689464393524","type":"done"}}
2019/08/25 18:31:29 [Info] received msg: {"id":"","type":"message","sn":"","topic":"/market/level3:BTC-USDT","subject":"trade.l3done","data":{"sequence":"1556573506653","symbol":"BTC-USDT","reason":"canceled","side":"buy","size":"0.029","orderId":"5d62b7dac788c64261a56d54","price":"10049.50000000000000000000","time":"1566750689708990909","type":"done"}}
2019/08/25 18:31:30 [Info] received msg: {"id":"","type":"message","sn":"","topic":"/market/level3:BTC-USDT","subject":"trade.l3done","data":{"sequence":"1556573506662","symbol":"BTC-USDT","reason":"canceled","side":"sell","size":"0.00051068","orderId":"5d62b7d589fc844d237dde16","price":"10078.60000000000000000000","time":"1566750690074412240","type":"done"}}
2019/08/25 18:31:30 [Info] received msg: {"id":"","type":"message","sn":"","topic":"/market/level3:BTC-USDT","subject":"trade.l3done","data":{"sequence":"1556573506663","symbol":"BTC-USDT","reason":"canceled","side":"buy","size":"0.09499378","orderId":"5d62b7d50bad4556c808e3f5","price":"10058.50000000000000000000","time":"1566750690074514152","type":"done"}}
2019/08/25 18:31:30 [Info] received msg: {"id":"","type":"message","sn":"","topic":"/market/level3:BTC-USDT","subject":"trade.l3done","data":{"sequence":"1556573506664","symbol":"BTC-USDT","reason":"canceled","side":"sell","size":"0.47574932","orderId":"5d62b7d95137b940c51e1f34","price":"10083.20000000000000000000","time":"1566750690108998354","type":"done"}}
2019/08/25 18:31:30 [Info] received msg: {"id":"","type":"message","sn":"","topic":"/market/level3:BTC-USDT","subject":"trade.l3done","data":{"sequence":"1556573506671","symbol":"BTC-USDT","reason":"canceled","side":"buy","size":"0.11116728","orderId":"5d62b7de5137b940c51e2437","price":"10062.30000000000000000000","time":"1566750690362767182","type":"done"}}
2019/08/25 18:31:30 [Info] received msg: {"id":"","type":"message","sn":"","topic":"/market/level3:BTC-USDT","subject":"trade.l3done","data":{"sequence":"1556573506678","symbol":"BTC-USDT","reason":"canceled","side":"buy","size":"0.10097012","orderId":"5d62b7e2054b4671f3c83bd8","price":"10057.40000000000000000000","time":"1566750690637812718","type":"done"}}
2019/08/25 18:31:30 [Info] received msg: {"id":"","type":"message","sn":"","topic":"/market/level3:BTC-USDT","subject":"trade.l3done","data":{"sequence":"1556573506679","symbol":"BTC-USDT","reason":"canceled","side":"sell","size":"0.00051068","orderId":"5d62b7e2cdaba42f8cfbc8ed","price":"10077.60000000000000000000","time":"1566750690637835624","type":"done"}}
2019/08/25 18:31:31 [Info] received msg: {"id":"","type":"message","sn":"","topic":"/market/level3:BTC-USDT","subject":"trade.l3done","data":{"sequence":"1556573506695","symbol":"BTC-USDT","reason":"canceled","side":"buy","orderId":"5d62b7e289fc844d237deb0b","time":"1566750690954939468","type":"done"}}
2019/08/25 18:31:31 [Info] received msg: {"id":"","type":"message","sn":"","topic":"/market/level3:BTC-USDT","subject":"trade.l3done","data":{"sequence":"1556573506702","symbol":"BTC-USDT","reason":"canceled","side":"sell","size":"0.1125","orderId":"5d62b7e2c788c64261a574fc","price":"10066.40000000000000000000","time":"1566750691427685528","type":"done"}}
2019/08/25 18:31:32 [Info] received msg: {"id":"","type":"message","sn":"","topic":"/market/level3:BTC-USDT","subject":"trade.l3done","data":{"sequence":"1556573506715","symbol":"BTC-USDT","reason":"canceled","side":"buy","size":"0.24919","orderId":"5d62b7ad0bad4556c808c263","price":"10045.30000000000000000000","time":"1566750692110935366","type":"done"}}
2019/08/25 18:31:32 [Info] received msg: {"id":"","type":"message","sn":"","topic":"/market/level3:BTC-USDT","subject":"trade.l3done","data":{"sequence":"1556573506716","symbol":"BTC-USDT","reason":"canceled","side":"buy","size":"0.00783990","orderId":"5d62b770c788c64261a512e3","price":"9969.20000000000000000000","time":"1566750692132941152","type":"done"}}
2019/08/25 18:31:32 [Info] received msg: {"id":"","type":"message","sn":"","topic":"/market/level3:BTC-USDT","subject":"trade.l3done","data":{"sequence":"1556573506719","symbol":"BTC-USDT","reason":"canceled","side":"buy","size":"0.010238","orderId":"5d62b7e0cdaba42f8cfbc7a9","price":"10063.30000000000000000000","time":"1566750692289527440","type":"done"}}
2019/08/25 18:31:32 [Info] received msg: {"id":"","type":"message","sn":"","topic":"/market/level3:BTC-USDT","subject":"trade.l3done","data":{"sequence":"1556573506734","symbol":"BTC-USDT","reason":"canceled","side":"buy","size":"0.29888217","orderId":"5d62b7e2054b4671f3c83c8f","price":"10037.40000000000000000000","time":"1566750692611062682","type":"done"}}
2019/08/25 18:31:33 [Info] received msg: {"id":"","type":"message","sn":"","topic":"/market/level3:BTC-USDT","subject":"trade.l3done","data":{"sequence":"1556573506737","symbol":"BTC-USDT","reason":"canceled","side":"buy","size":"0.125","orderId":"5d62b7e15137b940c51e264c","price":"10019.50000000000000000000","time":"1566750692959887732","type":"done"}}
2019/08/25 18:31:33 [Info] received msg: {"id":"","type":"message","sn":"","topic":"/market/level3:BTC-USDT","subject":"trade.l3done","data":{"sequence":"1556573506738","symbol":"BTC-USDT","reason":"canceled","side":"sell","size":"0.0467","orderId":"5d62b7e10bad4556c808eeea","price":"10109.10000000000000000000","time":"1566750692970677943","type":"done"}}
2019/08/25 18:31:33 [Info] received msg: {"id":"","type":"message","sn":"","topic":"/market/level3:BTC-USDT","subject":"trade.l3done","data":{"sequence":"1556573506741","symbol":"BTC-USDT","reason":"canceled","side":"sell","size":"0.50000997","orderId":"5d62b7e35137b940c51e283a","price":"10070.60000000000000000000","time":"1566750693108985858","type":"done"}}
2019/08/25 18:31:33 [Info] received msg: {"id":"","type":"message","sn":"","topic":"/market/level3:BTC-USDT","subject":"trade.l3done","data":{"sequence":"1556573506742","symbol":"BTC-USDT","reason":"canceled","side":"buy","size":"0.49727978","orderId":"5d62b7e3c788c64261a57586","price":"10054.50000000000000000000","time":"1566750693109078220","type":"done"}}
2019/08/25 18:31:33 [Info] received msg: {"id":"","type":"message","sn":"","topic":"/market/level3:BTC-USDT","subject":"trade.l3done","data":{"sequence":"1556573506747","symbol":"BTC-USDT","reason":"canceled","side":"buy","size":"0.00004001","orderId":"5d62b7d84c06876f06c44594","price":"10058.60000000000000000000","time":"1566750693161486605","type":"done"}}
2019/08/25 18:31:33 [Info] received msg: {"id":"","type":"message","sn":"","topic":"/market/level3:BTC-USDT","subject":"trade.l3done","data":{"sequence":"1556573506748","symbol":"BTC-USDT","reason":"canceled","side":"buy","size":"0.1077","orderId":"5d62b7e40bad4556c808f19e","price":"10059.70000000000000000000","time":"1566750693171887026","type":"done"}}
2019/08/25 18:31:33 [Info] received msg: {"id":"","type":"message","sn":"","topic":"/market/level3:BTC-USDT","subject":"trade.l3done","data":{"sequence":"1556573506749","symbol":"BTC-USDT","reason":"canceled","side":"sell","size":"0.1125","orderId":"5d62b7e4054b4671f3c83d8c","price":"10066.40000000000000000000","time":"1566750693171972780","type":"done"}}
2019/08/25 18:31:34 [Info] received msg: {"id":"","type":"message","sn":"","topic":"/market/level3:BTC-USDT","subject":"trade.l3done","data":{"sequence":"1556573506770","symbol":"BTC-USDT","reason":"canceled","side":"sell","size":"0.025","orderId":"5d62b7e50bad4556c808f260","price":"10086.20000000000000000000","time":"1566750694286274332","type":"done"}}
2019/08/25 18:31:35 [Info] received msg: {"id":"","type":"message","sn":"","topic":"/market/level3:BTC-USDT","subject":"trade.l3done","data":{"sequence":"1556573506784","symbol":"BTC-USDT","reason":"canceled","side":"buy","orderId":"5d62b7e64c06876f06c45245","time":"1566750694799734681","type":"done"}}
2019/08/25 18:31:35 [Info] received msg: {"id":"","type":"message","sn":"","topic":"/market/level3:BTC-USDT","subject":"trade.l3done","data":{"sequence":"1556573506785","symbol":"BTC-USDT","reason":"canceled","side":"sell","size":"0.00051068","orderId":"5d62b7e2c788c64261a57516","price":"10076.90000000000000000000","time":"1566750694810261266","type":"done"}}
2019/08/25 18:31:35 [Info] received msg: {"id":"","type":"message","sn":"","topic":"/market/level3:BTC-USDT","subject":"trade.l3done","data":{"sequence":"1556573506786","symbol":"BTC-USDT","reason":"canceled","side":"buy","size":"0.09600599","orderId":"5d62b7e25137b940c51e27a7","price":"10056.80000000000000000000","time":"1566750694810348638","type":"done"}}
2019/08/25 18:31:35 [Info] received msg: {"id":"","type":"message","sn":"","topic":"/market/level3:BTC-USDT","subject":"trade.l3done","data":{"sequence":"1556573506787","symbol":"BTC-USDT","reason":"canceled","side":"buy","size":"0.11116702","orderId":"5d62b7e2c788c64261a57528","price":"10063.00000000000000000000","time":"1566750694821213508","type":"done"}}
2019/08/25 18:31:35 [Info] received msg: {"id":"","type":"message","sn":"","topic":"/market/level3:BTC-USDT","subject":"trade.l3done","data":{"sequence":"1556573506796","symbol":"BTC-USDT","reason":"canceled","side":"sell","size":"0.1125","orderId":"5d62b7e689fc844d237dedae","price":"10066.40000000000000000000","time":"1566750695172204541","type":"done"}}
2019/08/25 18:31:35 [Info] received msg: {"id":"","type":"message","sn":"","topic":"/market/level3:BTC-USDT","subject":"trade.l3done","data":{"sequence":"1556573506803","symbol":"BTC-USDT","reason":"canceled","side":"buy","size":"0.1003854","orderId":"5d62b7e6cdaba42f8cfbcc49","price":"10055.70000000000000000000","time":"1566750695351211360","type":"done"}}
2019/08/25 18:31:35 [Info] received msg: {"id":"","type":"message","sn":"","topic":"/market/level3:BTC-USDT","subject":"trade.l3done","data":{"sequence":"1556573506804","symbol":"BTC-USDT","reason":"canceled","side":"sell","size":"0.00051068","orderId":"5d62b7e6c788c64261a57885","price":"10075.90000000000000000000","time":"1566750695362513213","type":"done"}}
2019/08/25 18:31:35 [Info] received msg: {"id":"","type":"message","sn":"","topic":"/market/level3:BTC-USDT","subject":"trade.l3done","data":{"sequence":"1556573506814","symbol":"BTC-USDT","reason":"canceled","side":"buy","orderId":"5d62b7e789fc844d237deee6","time":"1566750695564307573","type":"done"}}
2019/08/25 18:31:36 [Info] received msg: {"id":"","type":"message","sn":"","topic":"/market/level3:BTC-USDT","subject":"trade.l3done","data":{"sequence":"1556573506827","symbol":"BTC-USDT","reason":"canceled","side":"buy","size":"0.00004001","orderId":"5d62b7e50bad4556c808f2a6","price":"10056.90000000000000000000","time":"1566750696369431117","type":"done"}}
2019/08/25 18:31:36 [Info] received msg: {"id":"","type":"message","sn":"","topic":"/market/level3:BTC-USDT","subject":"trade.l3done","data":{"sequence":"1556573506836","symbol":"BTC-USDT","reason":"canceled","side":"buy","size":"0.29887324","orderId":"5d62b7e689fc844d237dee4a","price":"10037.70000000000000000000","time":"1566750696665938084","type":"done"}}
2019/08/25 18:31:37 [Info] received msg: {"id":"","type":"message","sn":"","topic":"/market/level3:BTC-USDT","subject":"trade.l3done","data":{"sequence":"1556573506845","symbol":"BTC-USDT","reason":"canceled","side":"buy","size":"0.125","orderId":"5d62b7e40bad4556c808f221","price":"10019.60000000000000000000","time":"1566750696926706707","type":"done"}}
2019/08/25 18:31:37 [Info] received msg: {"id":"","type":"message","sn":"","topic":"/market/level3:BTC-USDT","subject":"trade.l3done","data":{"sequence":"1556573506846","symbol":"BTC-USDT","reason":"canceled","side":"buy","size":"0.40079","orderId":"5d62b7df5137b940c51e24ff","price":"10056.30000000000000000000","time":"1566750696926803366","type":"done"}}
2019/08/25 18:31:37 [Info] received msg: {"id":"","type":"message","sn":"","topic":"/market/level3:BTC-USDT","subject":"trade.l3done","data":{"sequence":"1556573506847","symbol":"BTC-USDT","reason":"canceled","side":"sell","size":"0.0467","orderId":"5d62b7e5cdaba42f8cfbcb17","price":"10109.60000000000000000000","time":"1566750696926825083","type":"done"}}
2019/08/25 18:31:37 [Info] received msg: {"id":"","type":"message","sn":"","topic":"/market/level3:BTC-USDT","subject":"trade.l3done","data":{"sequence":"1556573506848","symbol":"BTC-USDT","reason":"canceled","side":"buy","size":"1.60339","orderId":"5d62b7df054b4671f3c839a2","price":"10044.30000000000000000000","time":"1566750696937370807","type":"done"}}
2019/08/25 18:31:37 [Info] received msg: {"id":"","type":"message","sn":"","topic":"/market/level3:BTC-USDT","subject":"trade.l3done","data":{"sequence":"1556573506849","symbol":"BTC-USDT","reason":"canceled","side":"sell","size":"0.40079","orderId":"5d62b7df054b4671f3c83983","price":"10066.50000000000000000000","time":"1566750696937471728","type":"done"}}
2019/08/25 18:31:37 [Info] received msg: {"id":"","type":"message","sn":"","topic":"/market/level3:BTC-USDT","subject":"trade.l3done","data":{"sequence":"1556573506850","symbol":"BTC-USDT","reason":"canceled","side":"buy","size":"1.60339","orderId":"5d62b7df89fc844d237de829","price":"10036.30000000000000000000","time":"1566750696948080864","type":"done"}}
2019/08/25 18:31:37 [Info] received msg: {"id":"","type":"message","sn":"","topic":"/market/level3:BTC-USDT","subject":"trade.l3done","data":{"sequence":"1556573506863","symbol":"BTC-USDT","reason":"canceled","side":"sell","size":"0.09983318","orderId":"5d62b7d889fc844d237de16e","price":"10068.40000000000000000000","time":"1566750697055401860","type":"done"}}
2019/08/25 18:31:37 [Info] received msg: {"id":"","type":"message","sn":"","topic":"/market/level3:BTC-USDT","subject":"trade.l3done","data":{"sequence":"1556573506864","symbol":"BTC-USDT","reason":"canceled","side":"sell","size":"0.09518096","orderId":"5d62b7d8cdaba42f8cfbc0c7","price":"10068.50000000000000000000","time":"1566750697098994006","type":"done"}}
2019/08/25 18:31:37 [Info] received msg: {"id":"","type":"message","sn":"","topic":"/market/level3:BTC-USDT","subject":"trade.l3done","data":{"sequence":"1556573506869","symbol":"BTC-USDT","reason":"canceled","side":"buy","size":"0.1077","orderId":"5d62b7e8c788c64261a579a3","price":"10057.70000000000000000000","time":"1566750697302602988","type":"done"}}
2019/08/25 18:31:37 [Info] received msg: {"id":"","type":"message","sn":"","topic":"/market/level3:BTC-USDT","subject":"trade.l3done","data":{"sequence":"1556573506870","symbol":"BTC-USDT","reason":"canceled","side":"sell","size":"0.025","orderId":"5d62b7e8c788c64261a5798f","price":"10085.70000000000000000000","time":"1566750697302697913","type":"done"}}
2019/08/25 18:31:37 [Info] received msg: {"id":"","type":"message","sn":"","topic":"/market/level3:BTC-USDT","subject":"trade.l3done","data":{"sequence":"1556573506871","symbol":"BTC-USDT","reason":"canceled","side":"sell","size":"0.1125","orderId":"5d62b7e80bad4556c808f4f8","price":"10066.30000000000000000000","time":"1566750697302724590","type":"done"}}
2019/08/25 18:31:37 [Info] received msg: {"id":"","type":"message","sn":"","topic":"/market/level3:BTC-USDT","subject":"trade.l3done","data":{"sequence":"1556573506886","symbol":"BTC-USDT","reason":"canceled","side":"buy","size":"0.49726494","orderId":"5d62b7e85137b940c51e2c2f","price":"10054.80000000000000000000","time":"1566750697739255931","type":"done"}}
2019/08/25 18:31:37 [Info] received msg: {"id":"","type":"message","sn":"","topic":"/market/level3:BTC-USDT","subject":"trade.l3done","data":{"sequence":"1556573506887","symbol":"BTC-USDT","reason":"canceled","side":"sell","size":"0.50000997","orderId":"5d62b7e85137b940c51e2c4a","price":"10070.90000000000000000000","time":"1566750697739372418","type":"done"}}
2019/08/25 18:31:38 [Info] received msg: {"id":"","type":"message","sn":"","topic":"/market/level3:BTC-USDT","subject":"trade.l3done","data":{"sequence":"1556573506888","symbol":"BTC-USDT","reason":"canceled","side":"buy","size":"0.11116796","orderId":"5d62b7e74c06876f06c45280","price":"10062.30000000000000000000","time":"1566750697955959149","type":"done"}}
2019/08/25 18:31:38 [Info] received msg: {"id":"","type":"message","sn":"","topic":"/market/level3:BTC-USDT","subject":"trade.l3done","data":{"sequence":"1556573506891","symbol":"BTC-USDT","reason":"canceled","side":"sell","size":"0.025","orderId":"5d62b7e989fc844d237df0a7","price":"10084.80000000000000000000","time":"1566750698280813911","type":"done"}}
2019/08/25 18:31:38 [Info] received msg: {"id":"","type":"message","sn":"","topic":"/market/level3:BTC-USDT","subject":"trade.l3done","data":{"sequence":"1556573506892","symbol":"BTC-USDT","reason":"canceled","side":"sell","size":"0.025","orderId":"5d62b7e94c06876f06c4546e","price":"10084.80000000000000000000","time":"1566750698280907929","type":"done"}}
2019/08/25 18:31:38 [Info] received msg: {"id":"","type":"message","sn":"","topic":"/market/level3:BTC-USDT","subject":"trade.l3done","data":{"sequence":"1556573506899","symbol":"BTC-USDT","reason":"canceled","side":"sell","size":"0.02319491","orderId":"5d62b7ce5137b940c51e157e","price":"10071.40000000000000000000","time":"1566750698424906928","type":"done"}}
2019/08/25 18:31:38 [Info] received msg: {"id":"","type":"message","sn":"","topic":"/market/level3:BTC-USDT","subject":"trade.l3done","data":{"sequence":"1556573506902","symbol":"BTC-USDT","reason":"canceled","side":"buy","size":"0.17585988","orderId":"5d62b7cf89fc844d237dd811","price":"10047.50000000000000000000","time":"1566750698489209096","type":"done"}}
2019/08/25 18:31:38 [Info] received msg: {"id":"","type":"message","sn":"","topic":"/market/level3:BTC-USDT","subject":"trade.l3done","data":{"sequence":"1556573506907","symbol":"BTC-USDT","reason":"canceled","side":"sell","size":"0.09899999","orderId":"5d62b7cf5137b940c51e15bc","price":"10083.30000000000000000000","time":"1566750698701426182","type":"done"}}
2019/08/25 18:31:38 [Info] received msg: {"id":"","type":"message","sn":"","topic":"/market/level3:BTC-USDT","subject":"trade.l3done","data":{"sequence":"1556573506910","symbol":"BTC-USDT","reason":"canceled","side":"buy","size":"0.19901471","orderId":"5d62b7cf89fc844d237dd849","price":"10049.50000000000000000000","time":"1566750698768825719","type":"done"}}
2019/08/25 18:31:38 [Info] received msg: {"id":"","type":"message","sn":"","topic":"/market/level3:BTC-USDT","subject":"trade.l3done","data":{"sequence":"1556573506911","symbol":"BTC-USDT","reason":"canceled","side":"buy","size":"0.029","orderId":"5d62b7e10bad4556c808ef60","price":"10049.50000000000000000000","time":"1566750698768911414","type":"done"}}
2019/08/25 18:31:38 [Info] received msg: {"id":"","type":"message","sn":"","topic":"/market/level3:BTC-USDT","subject":"trade.l3done","data":{"sequence":"1556573506913","symbol":"BTC-USDT","reason":"canceled","side":"buy","orderId":"5d62b7ea5137b940c51e2ec1","time":"1566750698769001932","type":"done"}}
2019/08/25 18:31:39 [Info] received msg: {"id":"","type":"message","sn":"","topic":"/market/level3:BTC-USDT","subject":"trade.l3done","data":{"sequence":"1556573506921","symbol":"BTC-USDT","reason":"canceled","side":"buy","orderId":"5d62b7eb5137b940c51e2f1b","time":"1566750699175599660","type":"done"}}
2019/08/25 18:31:39 [Info] received msg: {"id":"","type":"message","sn":"","topic":"/market/level3:BTC-USDT","subject":"trade.l3done","data":{"sequence":"1556573506939","symbol":"BTC-USDT","reason":"canceled","side":"buy","orderId":"5d62b7eb5137b940c51e2f4d","time":"1566750699465673988","type":"done"}}
2019/08/25 18:31:39 [Info] received msg: {"id":"","type":"message","sn":"","topic":"/market/level3:BTC-USDT","subject":"trade.l3done","data":{"sequence":"1556573506940","symbol":"BTC-USDT","reason":"canceled","side":"buy","size":"0.22221918","orderId":"5d62b79789fc844d237da7cc","price":"10052.60000000000000000000","time":"1566750699581875470","type":"done"}}
2019/08/25 18:31:39 [Info] received msg: {"id":"","type":"message","sn":"","topic":"/market/level3:BTC-USDT","subject":"trade.l3done","data":{"sequence":"1556573506943","symbol":"BTC-USDT","reason":"canceled","side":"buy","size":"0.029","orderId":"5d62b7eacdaba42f8cfbcf85","price":"10048.70000000000000000000","time":"1566750699709774182","type":"done"}}
2019/08/25 18:31:39 [Info] received msg: {"id":"","type":"message","sn":"","topic":"/market/level3:BTC-USDT","subject":"trade.l3done","data":{"sequence":"1556573506945","symbol":"BTC-USDT","reason":"canceled","side":"buy","orderId":"5d62b7ebcdaba42f8cfbd042","time":"1566750699730198294","type":"done"}}
2019/08/25 18:31:39 [Info] received msg: {"id":"","type":"message","sn":"","topic":"/market/level3:BTC-USDT","subject":"trade.l3done","data":{"sequence":"1556573506946","symbol":"BTC-USDT","reason":"canceled","side":"buy","size":"0.00004001","orderId":"5d62b7e889fc844d237df015","price":"10056.40000000000000000000","time":"1566750699806994377","type":"done"}}
2019/08/25 18:31:40 [Info] received msg: {"id":"","type":"message","sn":"","topic":"/market/level3:BTC-USDT","subject":"trade.l3done","data":{"sequence":"1556573506947","symbol":"BTC-USDT","reason":"canceled","side":"sell","size":"0.47555309","orderId":"5d62b7c5054b4671f3c8212b","price":"10096.30000000000000000000","time":"1566750699914934273","type":"done"}}
2019/08/25 18:31:40 [Info] received msg: {"id":"","type":"message","sn":"","topic":"/market/level3:BTC-USDT","subject":"trade.l3done","data":{"sequence":"1556573506954","symbol":"BTC-USDT","reason":"canceled","side":"buy","size":"0.29890302","orderId":"5d62b7ea054b4671f3c84326","price":"10036.70000000000000000000","time":"1566750700513755970","type":"done"}}
2019/08/25 18:31:41 [Info] received msg: {"id":"","type":"message","sn":"","topic":"/market/level3:BTC-USDT","subject":"trade.l3done","data":{"sequence":"1556573506973","symbol":"BTC-USDT","reason":"canceled","side":"sell","size":"0.0467","orderId":"5d62b7e84c06876f06c45436","price":"10109.50000000000000000000","time":"1566750700946774373","type":"done"}}
2019/08/25 18:31:41 [Info] received msg: {"id":"","type":"message","sn":"","topic":"/market/level3:BTC-USDT","subject":"trade.l3done","data":{"sequence":"1556573506976","symbol":"BTC-USDT","reason":"canceled","side":"buy","size":"0.125","orderId":"5d62b7e8cdaba42f8cfbce17","price":"10019.50000000000000000000","time":"1566750701098743401","type":"done"}}
2019/08/25 18:31:41 [Info] received msg: {"id":"","type":"message","sn":"","topic":"/market/level3:BTC-USDT","subject":"trade.l3done","data":{"sequence":"1556573506979","symbol":"BTC-USDT","reason":"canceled","side":"buy","size":"0.1077","orderId":"5d62b7ea89fc844d237df1bf","price":"10057.70000000000000000000","time":"1566750701310996760","type":"done"}}
2019/08/25 18:31:41 [Info] received msg: {"id":"","type":"message","sn":"","topic":"/market/level3:BTC-USDT","subject":"trade.l3done","data":{"sequence":"1556573506988","symbol":"BTC-USDT","reason":"canceled","side":"sell","size":"0.00051068","orderId":"5d62b7e75137b940c51e2bb2","price":"10072.30000000000000000000","time":"1566750701674923287","type":"done"}}
2019/08/25 18:31:41 [Info] received msg: {"id":"","type":"message","sn":"","topic":"/market/level3:BTC-USDT","subject":"trade.l3done","data":{"sequence":"1556573506989","symbol":"BTC-USDT","reason":"canceled","side":"buy","size":"0.10589462","orderId":"5d62b7e74c06876f06c452f2","price":"10052.20000000000000000000","time":"1566750701685646276","type":"done"}}
2019/08/25 18:31:42 [Info] received msg: {"id":"","type":"message","sn":"","topic":"/market/level3:BTC-USDT","subject":"trade.l3done","data":{"sequence":"1556573506998","symbol":"BTC-USDT","reason":"canceled","side":"buy","size":"0.4973144","orderId":"5d62b7ecc788c64261a57d54","price":"10053.80000000000000000000","time":"1566750702226959769","type":"done"}}
2019/08/25 18:31:42 [Info] received msg: {"id":"","type":"message","sn":"","topic":"/market/level3:BTC-USDT","subject":"trade.l3done","data":{"sequence":"1556573506999","symbol":"BTC-USDT","reason":"canceled","side":"sell","size":"0.50000997","orderId":"5d62b7ecc788c64261a57d63","price":"10069.90000000000000000000","time":"1566750702227061224","type":"done"}}
2019/08/25 18:31:42 [Info] received msg: {"id":"","type":"message","sn":"","topic":"/market/level3:BTC-USDT","subject":"trade.l3done","data":{"sequence":"1556573507002","symbol":"BTC-USDT","reason":"canceled","side":"buy","size":"0.09674861","orderId":"5d62b7ed054b4671f3c84588","price":"10052.20000000000000000000","time":"1566750702269016745","type":"done"}}
2019/08/25 18:31:42 [Info] received msg: {"id":"","type":"message","sn":"","topic":"/market/level3:BTC-USDT","subject":"trade.l3done","data":{"sequence":"1556573507003","symbol":"BTC-USDT","reason":"canceled","side":"sell","size":"0.00051068","orderId":"5d62b7ed5137b940c51e318b","price":"10072.30000000000000000000","time":"1566750702279248892","type":"done"}}
2019/08/25 18:31:43 [Info] received msg: {"id":"","type":"message","sn":"","topic":"/market/level3:BTC-USDT","subject":"trade.l3done","data":{"sequence":"1556573507022","symbol":"BTC-USDT","reason":"canceled","side":"sell","size":"1.72993","orderId":"5d62b7df054b4671f3c8399e","price":"10079.50000000000000000000","time":"1566750703006766636","type":"done"}}
2019/08/25 18:31:43 [Info] received msg: {"id":"","type":"message","sn":"","topic":"/market/level3:BTC-USDT","subject":"trade.l3done","data":{"sequence":"1556573507023","symbol":"BTC-USDT","reason":"canceled","side":"sell","size":"1.72993","orderId":"5d62b7df5137b940c51e2518","price":"10088.20000000000000000000","time":"1566750703040201036","type":"done"}}
2019/08/25 18:31:43 [Info] received msg: {"id":"","type":"message","sn":"","topic":"/market/level3:BTC-USDT","subject":"trade.l3done","data":{"sequence":"1556573507030","symbol":"BTC-USDT","reason":"canceled","side":"buy","size":"0.00004001","orderId":"5d62b7ec5137b940c51e3013","price":"10057.80000000000000000000","time":"1566750703309775182","type":"done"}}
2019/08/25 18:31:44 [Info] received msg: {"id":"","type":"message","sn":"","topic":"/market/level3:BTC-USDT","subject":"trade.l3done","data":{"sequence":"1556573507049","symbol":"BTC-USDT","reason":"canceled","side":"sell","size":"0.09983318","orderId":"5d62b7e9c788c64261a57ad2","price":"10063.80000000000000000000","time":"1566750704225500913","type":"done"}}
2019/08/25 18:31:44 [Info] received msg: {"id":"","type":"message","sn":"","topic":"/market/level3:BTC-USDT","subject":"trade.l3done","data":{"sequence":"1556573507056","symbol":"BTC-USDT","reason":"canceled","side":"buy","size":"0.29890302","orderId":"5d62b7ee89fc844d237df57a","price":"10036.70000000000000000000","time":"1566750704447386747","type":"done"}}
2019/08/25 18:31:45 [Info] received msg: {"id":"","type":"message","sn":"","topic":"/market/level3:BTC-USDT","subject":"trade.l3done","data":{"sequence":"1556573507063","symbol":"BTC-USDT","reason":"canceled","side":"sell","size":"0.0467","orderId":"5d62b7ec89fc844d237df3ed","price":"10109.40000000000000000000","time":"1566750705013902179","type":"done"}}
2019/08/25 18:31:45 [Info] received msg: {"id":"","type":"message","sn":"","topic":"/market/level3:BTC-USDT","subject":"trade.l3done","data":{"sequence":"1556573507064","symbol":"BTC-USDT","reason":"canceled","side":"buy","size":"0.125","orderId":"5d62b7ed89fc844d237df423","price":"10019.60000000000000000000","time":"1566750705198509032","type":"done"}}
2019/08/25 18:31:46 [Info] received msg: {"id":"","type":"message","sn":"","topic":"/market/level3:BTC-USDT","subject":"trade.l3done","data":{"sequence":"1556573507071","symbol":"BTC-USDT","reason":"canceled","side":"sell","size":"0.50000997","orderId":"5d62b7f05137b940c51e33e6","price":"10070.10000000000000000000","time":"1566750706472709384","type":"done"}}
2019/08/25 18:31:46 [Info] received msg: {"id":"","type":"message","sn":"","topic":"/market/level3:BTC-USDT","subject":"trade.l3done","data":{"sequence":"1556573507072","symbol":"BTC-USDT","reason":"canceled","side":"buy","size":"0.49730451","orderId":"5d62b7f04c06876f06c45a83","price":"10054.00000000000000000000","time":"1566750706483501757","type":"done"}}
2019/08/25 18:31:47 [Info] received msg: {"id":"","type":"message","sn":"","topic":"/market/level3:BTC-USDT","subject":"trade.l3done","data":{"sequence":"1556573507075","symbol":"BTC-USDT","reason":"canceled","side":"buy","size":"1","orderId":"5d62b7e8c788c64261a579c1","price":"5.00000000000000000000","time":"1566750707373698628","type":"done"}}
2019/08/25 18:31:47 [Info] received msg: {"id":"","type":"message","sn":"","topic":"/market/level3:BTC-USDT","subject":"trade.l3done","data":{"sequence":"1556573507076","symbol":"BTC-USDT","reason":"canceled","side":"sell","size":"0.30000000","orderId":"5d62b7e4cdaba42f8cfbcab6","price":"10068.20000000000000000000","time":"1566750707678781313","type":"done"}}
2019/08/25 18:31:48 [Info] received msg: {"id":"","type":"message","sn":"","topic":"/market/level3:BTC-USDT","subject":"trade.l3done","data":{"sequence":"1556573507077","symbol":"BTC-USDT","reason":"canceled","side":"buy","size":"0.1077","orderId":"5d62b7eec788c64261a57ee4","price":"10058.50000000000000000000","time":"1566750708211162740","type":"done"}}
2019/08/25 18:31:49 [Info] received msg: {"id":"","type":"message","sn":"","topic":"/market/level3:BTC-USDT","subject":"trade.l3done","data":{"sequence":"1556573507078","symbol":"BTC-USDT","reason":"canceled","side":"buy","size":"0.29889706","orderId":"5d62b7f25137b940c51e3598","price":"10036.90000000000000000000","time":"1566750708652462374","type":"done"}}
2019/08/25 18:31:49 [Info] received msg: {"id":"","type":"message","sn":"","topic":"/market/level3:BTC-USDT","subject":"trade.l3done","data":{"sequence":"1556573507079","symbol":"BTC-USDT","reason":"canceled","side":"sell","size":"0.0467","orderId":"5d62b7f1054b4671f3c84887","price":"10109.30000000000000000000","time":"1566750708983428393","type":"done"}}
2019/08/25 18:31:49 [Info] received msg: {"id":"","type":"message","sn":"","topic":"/market/level3:BTC-USDT","subject":"trade.l3done","data":{"sequence":"1556573507086","symbol":"BTC-USDT","reason":"canceled","side":"buy","size":"0.125","orderId":"5d62b7f14c06876f06c45b0d","price":"10019.50000000000000000000","time":"1566750709122504017","type":"done"}}
2019/08/25 18:31:49 [Info] received msg: {"id":"","type":"message","sn":"","topic":"/market/level3:BTC-USDT","subject":"trade.l3done","data":{"sequence":"1556573507091","symbol":"BTC-USDT","reason":"canceled","side":"buy","size":"0.00004001","orderId":"5d62b7ef5137b940c51e32f4","price":"10058.60000000000000000000","time":"1566750709725060209","type":"done"}}
2019/08/25 18:31:51 [Info] received msg: {"id":"","type":"message","sn":"","topic":"/market/level3:BTC-USDT","subject":"trade.l3done","data":{"sequence":"1556573507094","symbol":"BTC-USDT","reason":"canceled","side":"sell","size":"0.10682853","orderId":"5d62b7e1c788c64261a5742d","price":"10071.30000000000000000000","time":"1566750710853444078","type":"done"}}
2019/08/25 18:31:51 [Info] received msg: {"id":"","type":"message","sn":"","topic":"/market/level3:BTC-USDT","subject":"trade.l3done","data":{"sequence":"1556573507097","symbol":"BTC-USDT","reason":"canceled","side":"buy","size":"0.04126938","orderId":"5d62b7e10bad4556c808ef71","price":"10055.20000000000000000000","time":"1566750710929480645","type":"done"}}
2019/08/25 18:31:51 [Info] received msg: {"id":"","type":"message","sn":"","topic":"/market/level3:BTC-USDT","subject":"trade.l3done","data":{"sequence":"1556573507100","symbol":"BTC-USDT","reason":"canceled","side":"sell","size":"0.50000997","orderId":"5d62b7f50bad4556c808ff62","price":"10069.50000000000000000000","time":"1566750711089741729","type":"done"}}
2019/08/25 18:31:51 [Info] received msg: {"id":"","type":"message","sn":"","topic":"/market/level3:BTC-USDT","subject":"trade.l3done","data":{"sequence":"1556573507101","symbol":"BTC-USDT","reason":"canceled","side":"buy","size":"0.49733419","orderId":"5d62b7f489fc844d237dfa2c","price":"10053.40000000000000000000","time":"1566750711089834960","type":"done"}}
2019/08/25 18:31:51 [Info] received msg: {"id":"","type":"message","sn":"","topic":"/market/level3:BTC-USDT","subject":"trade.l3done","data":{"sequence":"1556573507102","symbol":"BTC-USDT","reason":"canceled","side":"buy","size":"0.1077","orderId":"5d62b7f54c06876f06c45e76","price":"10058.60000000000000000000","time":"1566750711233510599","type":"done"}}
2019/08/25 18:31:52 [Info] received msg: {"id":"","type":"message","sn":"","topic":"/market/level3:BTC-USDT","subject":"trade.l3done","data":{"sequence":"1556573507109","symbol":"BTC-USDT","reason":"canceled","side":"sell","size":"0.0467","orderId":"5d62b7f4c788c64261a58422","price":"10109.10000000000000000000","time":"1566750712341154471","type":"done"}}
2019/08/25 18:31:52 [Info] received msg: {"id":"","type":"message","sn":"","topic":"/market/level3:BTC-USDT","subject":"trade.l3done","data":{"sequence":"1556573507110","symbol":"BTC-USDT","reason":"canceled","side":"buy","size":"0.125","orderId":"5d62b7f489fc844d237dfa24","price":"10019.60000000000000000000","time":"1566750712351936594","type":"done"}}
2019/08/25 18:31:52 [Info] received msg: {"id":"","type":"message","sn":"","topic":"/market/level3:BTC-USDT","subject":"trade.l3done","data":{"sequence":"1556573507113","symbol":"BTC-USDT","reason":"canceled","side":"buy","size":"0.29896259","orderId":"5d62b7f6c788c64261a58583","price":"10034.70000000000000000000","time":"1566750712477006321","type":"done"}}
2019/08/25 18:31:53 [Info] received msg: {"id":"","type":"message","sn":"","topic":"/market/level3:BTC-USDT","subject":"trade.l3done","data":{"sequence":"1556573507114","symbol":"BTC-USDT","reason":"canceled","side":"buy","size":"0.00247265","orderId":"5d62b6cc89fc844d237cf35c","price":"10016.00000000000000000000","time":"1566750712942798882","type":"done"}}
2019/08/25 18:31:53 [Info] received msg: {"id":"","type":"message","sn":"","topic":"/market/level3:BTC-USDT","subject":"trade.l3done","data":{"sequence":"1556573507115","symbol":"BTC-USDT","reason":"canceled","side":"sell","size":"0.00247265","orderId":"5d62b6cc0bad4556c807f7b1","price":"10125.30000000000000000000","time":"1566750712953936862","type":"done"}}
2019/08/25 18:31:53 [Info] received msg: {"id":"","type":"message","sn":"","topic":"/market/level3:BTC-USDT","subject":"trade.l3done","data":{"sequence":"1556573507117","symbol":"BTC-USDT","reason":"canceled","side":"buy","orderId":"5d62b7f9054b4671f3c84ea5","time":"1566750713063197659","type":"done"}}
2019/08/25 18:31:53 [Info] received msg: {"id":"","type":"message","sn":"","topic":"/market/level3:BTC-USDT","subject":"trade.l3done","data":{"sequence":"1556573507118","symbol":"BTC-USDT","reason":"canceled","side":"buy","size":"0.00004001","orderId":"5d62b7f64c06876f06c45ee9","price":"10055.30000000000000000000","time":"1566750713131724170","type":"done"}}
2019/08/25 18:31:54 [Info] received msg: {"id":"","type":"message","sn":"","topic":"/market/level3:BTC-USDT","subject":"trade.l3done","data":{"sequence":"1556573507125","symbol":"BTC-USDT","reason":"canceled","side":"buy","size":"0.11110959","orderId":"5d62b7974c06876f06c40ce1","price":"9800.10000000000000000000","time":"1566750713813702346","type":"done"}}
2019/08/25 18:31:54 [Info] received msg: {"id":"","type":"message","sn":"","topic":"/market/level3:BTC-USDT","subject":"trade.l3done","data":{"sequence":"1556573507126","symbol":"BTC-USDT","reason":"canceled","side":"sell","size":"0.23731825","orderId":"5d62b7974c06876f06c40d02","price":"10469.20000000000000000000","time":"1566750714073844915","type":"done"}}
2019/08/25 18:31:54 [Info] received msg: {"id":"","type":"message","sn":"","topic":"/market/level3:BTC-USDT","subject":"trade.l3done","data":{"sequence":"1556573507132","symbol":"BTC-USDT","reason":"canceled","side":"buy","size":"0.00016714","orderId":"5d62b7f0054b4671f3c847d2","price":"10063.80000000000000000000","time":"1566750714573079165","type":"done"}}
2019/08/25 18:31:55 [Info] received msg: {"id":"","type":"message","sn":"","topic":"/market/level3:BTC-USDT","subject":"trade.l3done","data":{"sequence":"1556573507147","symbol":"BTC-USDT","reason":"canceled","side":"sell","size":"0.1125","orderId":"5d62b7f1054b4671f3c848f5","price":"10063.90000000000000000000","time":"1566750715393100742","type":"done"}}
2019/08/25 18:31:55 [Info] received msg: {"id":"","type":"message","sn":"","topic":"/market/level3:BTC-USDT","subject":"trade.l3done","data":{"sequence":"1556573507148","symbol":"BTC-USDT","reason":"canceled","side":"buy","size":"0.49735398","orderId":"5d62b7f94c06876f06c461fc","price":"10053.00000000000000000000","time":"1566750715403854818","type":"done"}}
2019/08/25 18:31:55 [Info] received msg: {"id":"","type":"message","sn":"","topic":"/market/level3:BTC-USDT","subject":"trade.l3done","data":{"sequence":"1556573507149","symbol":"BTC-USDT","reason":"canceled","side":"sell","size":"0.50000997","orderId":"5d62b7f9cdaba42f8cfbdae5","price":"10069.10000000000000000000","time":"1566750715403940161","type":"done"}}
2019/08/25 18:31:56 [Info] received msg: {"id":"","type":"message","sn":"","topic":"/market/level3:BTC-USDT","subject":"trade.l3done","data":{"sequence":"1556573507158","symbol":"BTC-USDT","reason":"canceled","side":"buy","size":"0.029","orderId":"5d62b7eb0bad4556c808f7c2","price":"10046.10000000000000000000","time":"1566750715675103908","type":"done"}}
2019/08/25 18:31:56 [Info] received msg: {"id":"","type":"message","sn":"","topic":"/market/level3:BTC-USDT","subject":"trade.l3done","data":{"sequence":"1556573507165","symbol":"BTC-USDT","reason":"canceled","side":"buy","size":"0.29892089","orderId":"5d62b7fa054b4671f3c84feb","price":"10036.10000000000000000000","time":"1566750716315486058","type":"done"}}
2019/08/25 18:31:56 [Info] received msg: {"id":"","type":"message","sn":"","topic":"/market/level3:BTC-USDT","subject":"trade.l3done","data":{"sequence":"1556573507175","symbol":"BTC-USDT","reason":"canceled","side":"sell","size":"0.0467","orderId":"5d62b7f889fc844d237dfd05","price":"10109.60000000000000000000","time":"1566750716754162822","type":"done"}}
2019/08/25 18:31:56 [Info] received msg: {"id":"","type":"message","sn":"","topic":"/market/level3:BTC-USDT","subject":"trade.l3done","data":{"sequence":"1556573507176","symbol":"BTC-USDT","reason":"canceled","side":"buy","size":"0.125","orderId":"5d62b7f8c788c64261a586be","price":"10019.50000000000000000000","time":"1566750716765895968","type":"done"}}
2019/08/25 18:31:58 [Info] received msg: {"id":"","type":"message","sn":"","topic":"/market/level3:BTC-USDT","subject":"trade.l3done","data":{"sequence":"1556573507187","symbol":"BTC-USDT","reason":"canceled","side":"buy","size":"0.00016680","orderId":"5d62b7fbcdaba42f8cfbdc23","price":"10063.00000000000000000000","time":"1566750717856170232","type":"done"}}
2019/08/25 18:31:58 [Info] received msg: {"id":"","type":"message","sn":"","topic":"/market/level3:BTC-USDT","subject":"trade.l3done","data":{"sequence":"1556573507188","symbol":"BTC-USDT","reason":"canceled","side":"sell","size":"0.09969062","orderId":"5d62b7fa054b4671f3c84fd7","price":"10063.80000000000000000000","time":"1566750717866757251","type":"done"}}
2019/08/25 18:31:58 [Info] received msg: {"id":"","type":"message","sn":"","topic":"/market/level3:BTC-USDT","subject":"trade.l3done","data":{"sequence":"1556573507197","symbol":"BTC-USDT","reason":"canceled","side":"buy","size":"0.029","orderId":"5d62b7fbc788c64261a5893f","price":"10048.70000000000000000000","time":"1566750718096133957","type":"done"}}
2019/08/25 18:31:59 [Info] received msg: {"id":"","type":"message","sn":"","topic":"/market/level3:BTC-USDT","subject":"trade.l3done","data":{"sequence":"1556573507220","symbol":"BTC-USDT","reason":"canceled","side":"sell","size":"0.1125","orderId":"5d62b7fe054b4671f3c852d9","price":"10063.80000000000000000000","time":"1566750719169779575","type":"done"}}
2019/08/25 18:31:59 [Info] received msg: {"id":"","type":"message","sn":"","topic":"/market/level3:BTC-USDT","subject":"trade.l3done","data":{"sequence":"1556573507221","symbol":"BTC-USDT","reason":"canceled","side":"buy","size":"0.00030936","orderId":"5d62b7fe89fc844d237e01a3","price":"10063.10000000000000000000","time":"1566750719213139292","type":"done"}}
2019/08/25 18:32:00 [Info] received msg: {"id":"","type":"message","sn":"","topic":"/market/level3:BTC-USDT","subject":"trade.l3done","data":{"sequence":"1556573507236","symbol":"BTC-USDT","reason":"canceled","side":"buy","size":"0.029","orderId":"5d62b7fd4c06876f06c465b2","price":"10046.10000000000000000000","time":"1566750719931494893","type":"done"}}
2019/08/25 18:32:00 [Info] received msg: {"id":"","type":"message","sn":"","topic":"/market/level3:BTC-USDT","subject":"trade.l3done","data":{"sequence":"1556573507237","symbol":"BTC-USDT","reason":"canceled","side":"sell","size":"0.50000997","orderId":"5d62b7fe0bad4556c80906c6","price":"10070.70000000000000000000","time":"1566750720137144337","type":"done"}}
2019/08/25 18:32:00 [Info] received msg: {"id":"","type":"message","sn":"","topic":"/market/level3:BTC-USDT","subject":"trade.l3done","data":{"sequence":"1556573507238","symbol":"BTC-USDT","reason":"canceled","side":"buy","size":"0.49727483","orderId":"5d62b7fe5137b940c51e3e24","price":"10054.60000000000000000000","time":"1566750720137244576","type":"done"}}
2019/08/25 18:32:00 [Info] received msg: {"id":"","type":"message","sn":"","topic":"/market/level3:BTC-USDT","subject":"trade.l3done","data":{"sequence":"1556573507239","symbol":"BTC-USDT","reason":"canceled","side":"buy","size":"0.29888217","orderId":"5d62b7fe054b4671f3c85359","price":"10037.40000000000000000000","time":"1566750720280781267","type":"done"}}
2019/08/25 18:32:00 [Info] received msg: {"id":"","type":"message","sn":"","topic":"/market/level3:BTC-USDT","subject":"trade.l3done","data":{"sequence":"1556573507243","symbol":"BTC-USDT","reason":"canceled","side":"buy","orderId":"5d62b8005137b940c51e401c","time":"1566750720421811429","type":"done"}}
2019/08/25 18:32:00 [Info] received msg: {"id":"","type":"message","sn":"","topic":"/market/level3:BTC-USDT","subject":"trade.l3done","data":{"sequence":"1556573507244","symbol":"BTC-USDT","reason":"canceled","side":"sell","size":"0.30000000","orderId":"5d62b7f65137b940c51e3887","price":"10066.70000000000000000000","time":"1566750720421952277","type":"done"}}
2019/08/25 18:32:00 [Info] received msg: {"id":"","type":"message","sn":"","topic":"/market/level3:BTC-USDT","subject":"trade.l3done","data":{"sequence":"1556573507249","symbol":"BTC-USDT","reason":"canceled","side":"buy","size":"0.125","orderId":"5d62b7fccdaba42f8cfbdd66","price":"10019.60000000000000000000","time":"1566750720463384761","type":"done"}}
2019/08/25 18:32:00 [Info] received msg: {"id":"","type":"message","sn":"","topic":"/market/level3:BTC-USDT","subject":"trade.l3done","data":{"sequence":"1556573507250","symbol":"BTC-USDT","reason":"canceled","side":"sell","size":"0.0467","orderId":"5d62b7fccdaba42f8cfbdd69","price":"10109.50000000000000000000","time":"1566750720473261526","type":"done"}}
2019/08/25 18:32:01 [Info] received msg: {"id":"","type":"message","sn":"","topic":"/market/level3:BTC-USDT","subject":"trade.l3done","data":{"sequence":"1556573507265","symbol":"BTC-USDT","reason":"canceled","side":"sell","size":"0.1125","orderId":"5d62b8004c06876f06c467e1","price":"10063.80000000000000000000","time":"1566750721240061810","type":"done"}}
2019/08/25 18:32:02 [Info] received msg: {"id":"","type":"message","sn":"","topic":"/market/level3:BTC-USDT","subject":"trade.l3done","data":{"sequence":"1556573507278","symbol":"BTC-USDT","reason":"canceled","side":"sell","size":"0.10682853","orderId":"5d62b7f789fc844d237dfc05","price":"10067.90000000000000000000","time":"1566750721911561294","type":"done"}}
2019/08/25 18:32:02 [Info] received msg: {"id":"","type":"message","sn":"","topic":"/market/level3:BTC-USDT","subject":"trade.l3done","data":{"sequence":"1556573507279","symbol":"BTC-USDT","reason":"canceled","side":"buy","size":"0.04131995","orderId":"5d62b7f789fc844d237dfc35","price":"10051.80000000000000000000","time":"1566750721987780822","type":"done"}}
2019/08/25 18:32:02 [Info] received msg: {"id":"","type":"message","sn":"","topic":"/market/level3:BTC-USDT","subject":"trade.l3done","data":{"sequence":"1556573507298","symbol":"BTC-USDT","reason":"canceled","side":"buy","size":"0.00030936","orderId":"5d62b8010bad4556c809096f","price":"10063.00000000000000000000","time":"1566750722377341560","type":"done"}}
2019/08/25 18:32:03 [Info] received msg: {"id":"","type":"message","sn":"","topic":"/market/level3:BTC-USDT","subject":"trade.l3done","data":{"sequence":"1556573507311","symbol":"BTC-USDT","reason":"canceled","side":"sell","size":"0.1125","orderId":"5d62b802cdaba42f8cfbe1be","price":"10063.80000000000000000000","time":"1566750723299662925","type":"done"}}
2019/08/25 18:32:03 [Info] received msg: {"id":"","type":"message","sn":"","topic":"/market/level3:BTC-USDT","subject":"trade.l3done","data":{"sequence":"1556573507312","symbol":"BTC-USDT","reason":"canceled","side":"buy","size":"0.1077","orderId":"5d62b8024c06876f06c46940","price":"10057.70000000000000000000","time":"1566750723310459950","type":"done"}}
2019/08/25 18:32:03 [Info] received msg: {"id":"","type":"message","sn":"","topic":"/market/level3:BTC-USDT","subject":"trade.l3done","data":{"sequence":"1556573507315","symbol":"BTC-USDT","reason":"canceled","side":"buy","size":"0.00004001","orderId":"5d62b7f9054b4671f3c84f06","price":"10055.10000000000000000000","time":"1566750723362435879","type":"done"}}
2019/08/25 18:32:04 [Info] received msg: {"id":"","type":"message","sn":"","topic":"/market/level3:BTC-USDT","subject":"trade.l3done","data":{"sequence":"1556573507322","symbol":"BTC-USDT","reason":"canceled","side":"buy","size":"0.49724516","orderId":"5d62b8024c06876f06c46917","price":"10055.20000000000000000000","time":"1566750723862168167","type":"done"}}
2019/08/25 18:32:04 [Info] received msg: {"id":"","type":"message","sn":"","topic":"/market/level3:BTC-USDT","subject":"trade.l3done","data":{"sequence":"1556573507323","symbol":"BTC-USDT","reason":"canceled","side":"sell","size":"0.50000997","orderId":"5d62b802c788c64261a58ec2","price":"10071.30000000000000000000","time":"1566750723862256612","type":"done"}}
2019/08/25 18:32:04 [Info] received msg: {"id":"","type":"message","sn":"","topic":"/market/level3:BTC-USDT","subject":"trade.l3done","data":{"sequence":"1556573507338","symbol":"BTC-USDT","reason":"canceled","side":"buy","size":"0.00030936","orderId":"5d62b803054b4671f3c8572e","price":"10063.00000000000000000000","time":"1566750724379076471","type":"done"}}
2019/08/25 18:32:05 [Info] received msg: {"id":"","type":"message","sn":"","topic":"/market/level3:BTC-USDT","subject":"trade.l3done","data":{"sequence":"1556573507341","symbol":"BTC-USDT","reason":"canceled","side":"sell","size":"0.0467","orderId":"5d62b800054b4671f3c854ce","price":"10109.40000000000000000000","time":"1566750724801539422","type":"done"}}
2019/08/25 18:32:05 [Info] received msg: {"id":"","type":"message","sn":"","topic":"/market/level3:BTC-USDT","subject":"trade.l3done","data":{"sequence":"1556573507342","symbol":"BTC-USDT","reason":"canceled","side":"buy","size":"0.125","orderId":"5d62b8004c06876f06c467c0","price":"10019.50000000000000000000","time":"1566750724801641623","type":"done"}}
2019/08/25 18:32:05 [Info] received msg: {"id":"","type":"message","sn":"","topic":"/market/level3:BTC-USDT","subject":"trade.l3done","data":{"sequence":"1556573507359","symbol":"BTC-USDT","reason":"canceled","side":"buy","size":"0.29886728","orderId":"5d62b8035137b940c51e42c5","price":"10037.90000000000000000000","time":"1566750725251474959","type":"done"}}
2019/08/25 18:32:05 [Info] received msg: {"id":"","type":"message","sn":"","topic":"/market/level3:BTC-USDT","subject":"trade.l3done","data":{"sequence":"1556573507360","symbol":"BTC-USDT","reason":"canceled","side":"sell","size":"0.1125","orderId":"5d62b8040bad4556c8090c1f","price":"10063.80000000000000000000","time":"1566750725389419647","type":"done"}}
2019/08/25 18:32:06 [Info] received msg: {"id":"","type":"message","sn":"","topic":"/market/level3:BTC-USDT","subject":"trade.l3done","data":{"sequence":"1556573507375","symbol":"BTC-USDT","reason":"canceled","side":"sell","size":"0.09969062","orderId":"5d62b804c788c64261a5909f","price":"10063.70000000000000000000","time":"1566750726381590593","type":"done"}}
2019/08/25 18:32:06 [Info] received msg: {"id":"","type":"message","sn":"","topic":"/market/level3:BTC-USDT","subject":"trade.l3done","data":{"sequence":"1556573507380","symbol":"BTC-USDT","reason":"canceled","side":"buy","size":"0.00004001","orderId":"5d62b803c788c64261a58ffc","price":"10057.80000000000000000000","time":"1566750726769487529","type":"done"}}
2019/08/25 18:32:07 [Info] received msg: {"id":"","type":"message","sn":"","topic":"/market/level3:BTC-USDT","subject":"trade.l3done","data":{"sequence":"1556573507383","symbol":"BTC-USDT","reason":"canceled","side":"sell","size":"0.1125","orderId":"5d62b8065137b940c51e4550","price":"10063.60000000000000000000","time":"1566750727260296917","type":"done"}}
2019/08/25 18:32:08 [Info] received msg: {"id":"","type":"message","sn":"","topic":"/market/level3:BTC-USDT","subject":"trade.l3done","data":{"sequence":"1556573507403","symbol":"BTC-USDT","reason":"canceled","side":"buy","size":"0.10259628","orderId":"5d62b7eec788c64261a57f19","price":"10052.60000000000000000000","time":"1566750728271373371","type":"done"}}
2019/08/25 18:32:08 [Info] received msg: {"id":"","type":"message","sn":"","topic":"/market/level3:BTC-USDT","subject":"trade.l3done","data":{"sequence":"1556573507404","symbol":"BTC-USDT","reason":"canceled","side":"sell","size":"0.00051068","orderId":"5d62b7ee5137b940c51e31ec","price":"10072.70000000000000000000","time":"1566750728271476962","type":"done"}}
2019/08/25 18:32:08 [Info] received msg: {"id":"","type":"message","sn":"","topic":"/market/level3:BTC-USDT","subject":"trade.l3done","data":{"sequence":"1556573507405","symbol":"BTC-USDT","reason":"canceled","side":"sell","size":"0.50000997","orderId":"5d62b806cdaba42f8cfbe502","price":"10071.00000000000000000000","time":"1566750728291960114","type":"done"}}
2019/08/25 18:32:08 [Info] received msg: {"id":"","type":"message","sn":"","topic":"/market/level3:BTC-USDT","subject":"trade.l3done","data":{"sequence":"1556573507406","symbol":"BTC-USDT","reason":"canceled","side":"buy","size":"0.49726","orderId":"5d62b806054b4671f3c859d4","price":"10054.90000000000000000000","time":"1566750728292050032","type":"done"}}
2019/08/25 18:32:08 [Info] received msg: {"id":"","type":"message","sn":"","topic":"/market/level3:BTC-USDT","subject":"trade.l3done","data":{"sequence":"1556573507425","symbol":"BTC-USDT","reason":"canceled","side":"buy","size":"0.09797906","orderId":"5d62b808c788c64261a593ae","price":"10053.00000000000000000000","time":"1566750728813269042","type":"done"}}
2019/08/25 18:32:09 [Info] received msg: {"id":"","type":"message","sn":"","topic":"/market/level3:BTC-USDT","subject":"trade.l3done","data":{"sequence":"1556573507426","symbol":"BTC-USDT","reason":"canceled","side":"sell","size":"0.00051068","orderId":"5d62b808054b4671f3c85b49","price":"10073.10000000000000000000","time":"1566750728823075542","type":"done"}}
2019/08/25 18:32:09 [Info] received msg: {"id":"","type":"message","sn":"","topic":"/market/level3:BTC-USDT","subject":"trade.l3done","data":{"sequence":"1556573507427","symbol":"BTC-USDT","reason":"canceled","side":"sell","size":"0.0467","orderId":"5d62b8044c06876f06c46bc9","price":"10098.00000000000000000000","time":"1566750728876669317","type":"done"}}
2019/08/25 18:32:09 [Info] received msg: {"id":"","type":"message","sn":"","topic":"/market/level3:BTC-USDT","subject":"trade.l3done","data":{"sequence":"1556573507434","symbol":"BTC-USDT","reason":"canceled","side":"buy","size":"0.1252","orderId":"5d62b804cdaba42f8cfbe3a3","price":"10005.30000000000000000000","time":"1566750729035768011","type":"done"}}
2019/08/25 18:32:09 [Info] received msg: {"id":"","type":"message","sn":"","topic":"/market/level3:BTC-USDT","subject":"trade.l3done","data":{"sequence":"1556573507441","symbol":"BTC-USDT","reason":"canceled","side":"buy","size":"0.1077","orderId":"5d62b80889fc844d237e0a58","price":"10058.70000000000000000000","time":"1566750729230932456","type":"done"}}
2019/08/25 18:32:09 [Info] received msg: {"id":"","type":"message","sn":"","topic":"/market/level3:BTC-USDT","subject":"trade.l3done","data":{"sequence":"1556573507442","symbol":"BTC-USDT","reason":"canceled","side":"buy","size":"0.29887324","orderId":"5d62b807cdaba42f8cfbe5cd","price":"10037.70000000000000000000","time":"1566750729251062413","type":"done"}}
2019/08/25 18:32:09 [Info] received msg: {"id":"","type":"message","sn":"","topic":"/market/level3:BTC-USDT","subject":"trade.l3done","data":{"sequence":"1556573507445","symbol":"BTC-USDT","reason":"canceled","side":"buy","size":"0.10152878","orderId":"5d62b8080bad4556c8090fb8","price":"10053.20000000000000000000","time":"1566750729356123806","type":"done"}}
2019/08/25 18:32:09 [Info] received msg: {"id":"","type":"message","sn":"","topic":"/market/level3:BTC-USDT","subject":"trade.l3done","data":{"sequence":"1556573507450","symbol":"BTC-USDT","reason":"canceled","side":"buy","size":"0.00862706","orderId":"5d62b796054b4671f3c7f8f5","price":"9969.20000000000000000000","time":"1566750729506058092","type":"done"}}
2019/08/25 18:32:11 [Info] received msg: {"id":"","type":"message","sn":"","topic":"/market/level3:BTC-USDT","subject":"trade.l3done","data":{"sequence":"1556573507474","symbol":"BTC-USDT","reason":"canceled","side":"buy","orderId":"5d62b80b054b4671f3c85d4a","time":"1566750731364553931","type":"done"}}
2019/08/25 18:32:12 [Info] received msg: {"id":"","type":"message","sn":"","topic":"/market/level3:BTC-USDT","subject":"trade.l3done","data":{"sequence":"1556573507491","symbol":"BTC-USDT","reason":"canceled","side":"sell","size":"0.07965691","orderId":"5d62b807c788c64261a592e3","price":"10063.80000000000000000000","time":"1566750732073225973","type":"done"}}
2019/08/25 18:32:12 [Info] received msg: {"id":"","type":"message","sn":"","topic":"/market/level3:BTC-USDT","subject":"trade.l3done","data":{"sequence":"1556573507494","symbol":"BTC-USDT","reason":"canceled","side":"buy","size":"0.1077","orderId":"5d62b80b054b4671f3c85d36","price":"10059.60000000000000000000","time":"1566750732250642536","type":"done"}}
2019/08/25 18:32:12 [Info] received msg: {"id":"","type":"message","sn":"","topic":"/market/level3:BTC-USDT","subject":"trade.l3done","data":{"sequence":"1556573507497","symbol":"BTC-USDT","reason":"canceled","side":"sell","size":"0.0467","orderId":"5d62b8080bad4556c8090fa9","price":"10097.90000000000000000000","time":"1566750732360889389","type":"done"}}
2019/08/25 18:32:12 [Info] received msg: {"id":"","type":"message","sn":"","topic":"/market/level3:BTC-USDT","subject":"trade.l3done","data":{"sequence":"1556573507510","symbol":"BTC-USDT","reason":"canceled","side":"buy","size":"0.49726989","orderId":"5d62b80a89fc844d237e0c57","price":"10054.70000000000000000000","time":"1566750732769434229","type":"done"}}
2019/08/25 18:32:12 [Info] received msg: {"id":"","type":"message","sn":"","topic":"/market/level3:BTC-USDT","subject":"trade.l3done","data":{"sequence":"1556573507511","symbol":"BTC-USDT","reason":"canceled","side":"sell","size":"0.50000997","orderId":"5d62b80b054b4671f3c85d21","price":"10070.80000000000000000000","time":"1566750732769548112","type":"done"}}
2019/08/25 18:32:13 [Info] received msg: {"id":"","type":"message","sn":"","topic":"/market/level3:BTC-USDT","subject":"trade.l3done","data":{"sequence":"1556573507512","symbol":"BTC-USDT","reason":"canceled","side":"buy","size":"0.29887919","orderId":"5d62b80bcdaba42f8cfbe87d","price":"10037.50000000000000000000","time":"1566750733289580212","type":"done"}}
2019/08/25 18:32:14 [Info] received msg: {"id":"","type":"message","sn":"","topic":"/market/level3:BTC-USDT","subject":"trade.l3done","data":{"sequence":"1556573507525","symbol":"BTC-USDT","reason":"canceled","side":"buy","size":"0.029","orderId":"5d62b7ffcdaba42f8cfbdfbb","price":"10048.70000000000000000000","time":"1566750733965074520","type":"done"}}
2019/08/25 18:32:14 [Info] received msg: {"id":"","type":"message","sn":"","topic":"/market/level3:BTC-USDT","subject":"trade.l3done","data":{"sequence":"1556573507526","symbol":"BTC-USDT","reason":"canceled","side":"sell","size":"0.1125","orderId":"5d62b80d5137b940c51e4aac","price":"10063.30000000000000000000","time":"1566750734286301121","type":"done"}}
2019/08/25 18:32:14 [Info] received msg: {"id":"","type":"message","sn":"","topic":"/market/level3:BTC-USDT","subject":"trade.l3done","data":{"sequence":"1556573507533","symbol":"BTC-USDT","reason":"canceled","side":"sell","size":"0.00001","orderId":"5d62b80cc788c64261a59700","price":"10063.40000000000000000000","time":"1566750734585509991","type":"done"}}
2019/08/25 18:32:15 [Info] received msg: {"id":"","type":"message","sn":"","topic":"/market/level3:BTC-USDT","subject":"trade.l3done","data":{"sequence":"1556573507550","symbol":"BTC-USDT","reason":"canceled","side":"sell","size":"0.07965691","orderId":"5d62b80d0bad4556c809132d","price":"10063.20000000000000000000","time":"1566750735397620140","type":"done"}}
2019/08/25 18:32:15 [Info] received msg: {"id":"","type":"message","sn":"","topic":"/market/level3:BTC-USDT","subject":"trade.l3done","data":{"sequence":"1556573507561","symbol":"BTC-USDT","reason":"canceled","side":"sell","size":"0.00362789","orderId":"5d62b7d8054b4671f3c8327a","price":"10068.60000000000000000000","time":"1566750735793976072","type":"done"}}
2019/08/25 18:32:16 [Info] received msg: {"id":"","type":"message","sn":"","topic":"/market/level3:BTC-USDT","subject":"trade.l3done","data":{"sequence":"1556573507573","symbol":"BTC-USDT","reason":"canceled","side":"sell","size":"0.1125","orderId":"5d62b80fcdaba42f8cfbebc4","price":"10063.10000000000000000000","time":"1566750736312239134","type":"done"}}
2019/08/25 18:32:17 [Info] received msg: {"id":"","type":"message","sn":"","topic":"/market/level3:BTC-USDT","subject":"trade.l3done","data":{"sequence":"1556573507581","symbol":"BTC-USDT","reason":"canceled","side":"sell","size":"0.0467","orderId":"5d62b80c89fc844d237e0d35","price":"10097.80000000000000000000","time":"1566750736921979895","type":"done"}}
2019/08/25 18:32:17 [Info] received msg: {"id":"","type":"message","sn":"","topic":"/market/level3:BTC-USDT","subject":"trade.l3done","data":{"sequence":"1556573507582","symbol":"BTC-USDT","reason":"canceled","side":"buy","size":"0.1252","orderId":"5d62b8084c06876f06c46ef8","price":"10005.90000000000000000000","time":"1566750736932671567","type":"done"}}
2019/08/25 18:32:17 [Info] received msg: {"id":"","type":"message","sn":"","topic":"/market/level3:BTC-USDT","subject":"trade.l3done","data":{"sequence":"1556573507583","symbol":"BTC-USDT","reason":"canceled","side":"sell","size":"0.50000997","orderId":"5d62b80fcdaba42f8cfbeb73","price":"10069.10000000000000000000","time":"1566750736943493407","type":"done"}}
2019/08/25 18:32:17 [Info] received msg: {"id":"","type":"message","sn":"","topic":"/market/level3:BTC-USDT","subject":"trade.l3done","data":{"sequence":"1556573507584","symbol":"BTC-USDT","reason":"canceled","side":"buy","size":"0.49735398","orderId":"5d62b80f4c06876f06c47428","price":"10053.00000000000000000000","time":"1566750736943572597","type":"done"}}
2019/08/25 18:32:17 [Info] received msg: {"id":"","type":"message","sn":"","topic":"/market/level3:BTC-USDT","subject":"trade.l3done","data":{"sequence":"1556573507585","symbol":"BTC-USDT","reason":"canceled","side":"buy","size":"0.29892386","orderId":"5d62b80f054b4671f3c860d3","price":"10036.00000000000000000000","time":"1566750737286540451","type":"done"}}
2019/08/25 18:32:17 [Info] received msg: {"id":"","type":"message","sn":"","topic":"/market/level3:BTC-USDT","subject":"trade.l3done","data":{"sequence":"1556573507587","symbol":"BTC-USDT","reason":"canceled","side":"sell","orderId":"5d62b811054b4671f3c86231","time":"1566750737413335441","type":"done"}}
2019/08/25 18:32:18 [Info] received msg: {"id":"","type":"message","sn":"","topic":"/market/level3:BTC-USDT","subject":"trade.l3done","data":{"sequence":"1556573507595","symbol":"BTC-USDT","reason":"canceled","side":"sell","size":"0.30000000","orderId":"5d62b8020bad4556c8090ae8","price":"10066.70000000000000000000","time":"1566750738008857978","type":"done"}}
2019/08/25 18:32:18 [Info] received msg: {"id":"","type":"message","sn":"","topic":"/market/level3:BTC-USDT","subject":"trade.l3done","data":{"sequence":"1556573507596","symbol":"BTC-USDT","reason":"canceled","side":"buy","size":"0.01977345","orderId":"5d62b81089fc844d237e1041","price":"10062.90000000000000000000","time":"1566750738227486836","type":"done"}}
2019/08/25 18:32:18 [Info] received msg: {"id":"","type":"message","sn":"","topic":"/market/level3:BTC-USDT","subject":"trade.l3done","data":{"sequence":"1556573507599","symbol":"BTC-USDT","reason":"canceled","side":"sell","size":"0.07965691","orderId":"5d62b80f054b4671f3c860f9","price":"10063.00000000000000000000","time":"1566750738270314285","type":"done"}}
2019/08/25 18:32:18 [Info] received msg: {"id":"","type":"message","sn":"","topic":"/market/level3:BTC-USDT","subject":"trade.l3done","data":{"sequence":"1556573507600","symbol":"BTC-USDT","reason":"canceled","side":"buy","size":"0.00001","orderId":"5d62b810cdaba42f8cfbec2e","price":"10062.60000000000000000000","time":"1566750738280184097","type":"done"}}
2019/08/25 18:32:19 [Info] received msg: {"id":"","type":"message","sn":"","topic":"/market/level3:BTC-USDT","subject":"trade.l3done","data":{"sequence":"1556573507612","symbol":"BTC-USDT","reason":"canceled","side":"sell","size":"0.025","orderId":"5d62b81189fc844d237e11d6","price":"10087.40000000000000000000","time":"1566750738965357600","type":"done"}}
2019/08/25 18:32:19 [Info] received msg: {"id":"","type":"message","sn":"","topic":"/market/level3:BTC-USDT","subject":"trade.l3done","data":{"sequence":"1556573507613","symbol":"BTC-USDT","reason":"canceled","side":"sell","size":"0.10682853","orderId":"5d62b802054b4671f3c85642","price":"10071.30000000000000000000","time":"1566750739149832349","type":"done"}}
2019/08/25 18:32:19 [Info] received msg: {"id":"","type":"message","sn":"","topic":"/market/level3:BTC-USDT","subject":"trade.l3done","data":{"sequence":"1556573507614","symbol":"BTC-USDT","reason":"canceled","side":"buy","size":"0.04126864","orderId":"5d62b8025137b940c51e41c6","price":"10055.20000000000000000000","time":"1566750739239082678","type":"done"}}
2019/08/25 18:32:19 [Info] received msg: {"id":"","type":"message","sn":"","topic":"/market/level3:BTC-USDT","subject":"trade.l3done","data":{"sequence":"1556573507617","symbol":"BTC-USDT","reason":"canceled","side":"sell","size":"0.09272655","orderId":"5d62b81289fc844d237e124a","price":"10062.90000000000000000000","time":"1566750739392809542","type":"done"}}
2019/08/25 18:32:19 [Info] received msg: {"id":"","type":"message","sn":"","topic":"/market/level3:BTC-USDT","subject":"trade.l3done","data":{"sequence":"1556573507618","symbol":"BTC-USDT","reason":"canceled","side":"buy","size":"0.1077","orderId":"5d62b8125137b940c51e4ec8","price":"10059.70000000000000000000","time":"1566750739403561840","type":"done"}}
2019/08/25 18:32:20 [Info] received msg: {"id":"","type":"message","sn":"","topic":"/market/level3:BTC-USDT","subject":"trade.l3done","data":{"sequence":"1556573507640","symbol":"BTC-USDT","reason":"canceled","side":"buy","size":"0.00004001","orderId":"5d62b807054b4671f3c85a52","price":"10055.30000000000000000000","time":"1566750740590607003","type":"done"}}
2019/08/25 18:32:22 [Info] received msg: {"id":"","type":"message","sn":"","topic":"/market/level3:BTC-USDT","subject":"trade.l3done","data":{"sequence":"1556573507643","symbol":"BTC-USDT","reason":"canceled","side":"sell","size":"0.0467","orderId":"5d62b81089fc844d237e1102","price":"10097.60000000000000000000","time":"1566750741176396266","type":"done"}}
2019/08/25 18:32:22 [Info] received msg: {"id":"","type":"message","sn":"","topic":"/market/level3:BTC-USDT","subject":"trade.l3done","data":{"sequence":"1556573507644","symbol":"BTC-USDT","reason":"canceled","side":"buy","size":"0.29896259","orderId":"5d62b81389fc844d237e1361","price":"10034.70000000000000000000","time":"1566750741197990325","type":"done"}}
2019/08/25 18:32:22 [Info] received msg: {"id":"","type":"message","sn":"","topic":"/market/level3:BTC-USDT","subject":"trade.l3done","data":{"sequence":"1556573507645","symbol":"BTC-USDT","reason":"canceled","side":"buy","size":"0.1252","orderId":"5d62b81089fc844d237e10ee","price":"10002.90000000000000000000","time":"1566750741198085634","type":"done"}}
2019/08/25 18:32:22 [Info] received msg: {"id":"","type":"message","sn":"","topic":"/market/level3:BTC-USDT","subject":"trade.l3done","data":{"sequence":"1556573507650","symbol":"BTC-USDT","reason":"canceled","side":"buy","size":"0.00001000","orderId":"5d62b8135137b940c51e4f9b","price":"10062.50000000000000000000","time":"1566750741514744380","type":"done"}}
2019/08/25 18:32:22 [Info] received msg: {"id":"","type":"message","sn":"","topic":"/market/level3:BTC-USDT","subject":"trade.l3done","data":{"sequence":"1556573507651","symbol":"BTC-USDT","reason":"canceled","side":"buy","size":"0.49741336","orderId":"5d62b813054b4671f3c86437","price":"10051.80000000000000000000","time":"1566750741514744380","type":"done"}}
2019/08/25 18:32:22 [Info] received msg: {"id":"","type":"message","sn":"","topic":"/market/level3:BTC-USDT","subject":"trade.l3done","data":{"sequence":"1556573507652","symbol":"BTC-USDT","reason":"canceled","side":"sell","size":"0.50000997","orderId":"5d62b8130bad4556c80918bb","price":"10067.90000000000000000000","time":"1566750741514864473","type":"done"}}
2019/08/25 18:32:23 [Info] received msg: {"id":"","type":"message","sn":"","topic":"/market/level3:BTC-USDT","subject":"trade.l3done","data":{"sequence":"1556573507662","symbol":"BTC-USDT","reason":"canceled","side":"sell","size":"6.06702","orderId":"5d62b6cacdaba42f8cfade98","price":"10153.50000000000000000000","time":"1566750742903339706","type":"done"}}
2019/08/25 18:32:23 [Info] received msg: {"id":"","type":"message","sn":"","topic":"/market/level3:BTC-USDT","subject":"trade.l3done","data":{"sequence":"1556573507664","symbol":"BTC-USDT","reason":"canceled","side":"buy","orderId":"5d62b81689fc844d237e1642","time":"1566750742957360567","type":"done"}}
2019/08/25 18:32:23 [Info] received msg: {"id":"","type":"message","sn":"","topic":"/market/level3:BTC-USDT","subject":"trade.l3done","data":{"sequence":"1556573507665","symbol":"BTC-USDT","reason":"canceled","side":"sell","size":"0.1125","orderId":"5d62b8164c06876f06c47a24","price":"10062.90000000000000000000","time":"1566750743317350282","type":"done"}}
2019/08/25 18:32:24 [Info] received msg: {"id":"","type":"message","sn":"","topic":"/market/level3:BTC-USDT","subject":"trade.l3done","data":{"sequence":"1556573507676","symbol":"BTC-USDT","reason":"canceled","side":"sell","size":"0.0467","orderId":"5d62b815c788c64261a59df0","price":"10097.50000000000000000000","time":"1566750744384071697","type":"done"}}
2019/08/25 18:32:24 [Info] received msg: {"id":"","type":"message","sn":"","topic":"/market/level3:BTC-USDT","subject":"trade.l3done","data":{"sequence":"1556573507679","symbol":"BTC-USDT","reason":"canceled","side":"buy","size":"0.1252","orderId":"5d62b815cdaba42f8cfbefe0","price":"10003.00000000000000000000","time":"1566750744533570048","type":"done"}}
2019/08/25 18:32:25 [Info] received msg: {"id":"","type":"message","sn":"","topic":"/market/level3:BTC-USDT","subject":"trade.l3done","data":{"sequence":"1556573507684","symbol":"BTC-USDT","reason":"canceled","side":"sell","size":"0.1125","orderId":"5d62b818cdaba42f8cfbf20a","price":"10062.90000000000000000000","time":"1566750745164796183","type":"done"}}
2019/08/25 18:32:25 [Info] received msg: {"id":"","type":"message","sn":"","topic":"/market/level3:BTC-USDT","subject":"trade.l3done","data":{"sequence":"1556573507685","symbol":"BTC-USDT","reason":"canceled","side":"buy","size":"0.29896259","orderId":"5d62b817c788c64261a59fff","price":"10034.70000000000000000000","time":"1566750745250001033","type":"done"}}
2019/08/25 18:32:25 [Info] received msg: {"id":"","type":"message","sn":"","topic":"/market/level3:BTC-USDT","subject":"trade.l3done","data":{"sequence":"1556573507686","symbol":"BTC-USDT","reason":"canceled","side":"sell","size":"0.025","orderId":"5d62b8185137b940c51e53aa","price":"10086.30000000000000000000","time":"1566750745271650798","type":"done"}}
2019/08/25 18:32:26 [Info] received msg: {"id":"","type":"message","sn":"","topic":"/market/level3:BTC-USDT","subject":"trade.l3done","data":{"sequence":"1556573507689","symbol":"BTC-USDT","reason":"canceled","side":"buy","size":"0.49742325","orderId":"5d62b818c788c64261a5a06c","price":"10051.60000000000000000000","time":"1566750746269866973","type":"done"}}
2019/08/25 18:32:26 [Info] received msg: {"id":"","type":"message","sn":"","topic":"/market/level3:BTC-USDT","subject":"trade.l3done","data":{"sequence":"1556573507690","symbol":"BTC-USDT","reason":"canceled","side":"sell","size":"0.50000997","orderId":"5d62b8184c06876f06c47bd5","price":"10067.70000000000000000000","time":"1566750746269997948","type":"done"}}
2019/08/25 18:32:27 [Info] received msg: {"id":"","type":"message","sn":"","topic":"/market/level3:BTC-USDT","subject":"trade.l3done","data":{"sequence":"1556573507693","symbol":"BTC-USDT","reason":"canceled","side":"sell","size":"0.1125","orderId":"5d62b81a054b4671f3c869c1","price":"10062.90000000000000000000","time":"1566750747171492058","type":"done"}}
2019/08/25 18:32:27 [Info] received msg: {"id":"","type":"message","sn":"","topic":"/market/level3:BTC-USDT","subject":"trade.l3done","data":{"sequence":"1556573507696","symbol":"BTC-USDT","reason":"canceled","side":"buy","size":"0.029","orderId":"5d62b80d054b4671f3c85f59","price":"10046.10000000000000000000","time":"1566750747318685092","type":"done"}}
2019/08/25 18:32:30 [Info] received msg: {"id":"","type":"message","sn":"","topic":"/market/level3:BTC-USDT","subject":"trade.l3done","data":{"sequence":"1556573507699","symbol":"BTC-USDT","reason":"canceled","side":"buy","size":"0.0929438","orderId":"5d62b80989fc844d237e0b57","price":"10053.40000000000000000000","time":"1566750748041985087","type":"done"}}
2019/08/25 18:32:30 [Info] received msg: {"id":"","type":"message","sn":"","topic":"/market/level3:BTC-USDT","subject":"trade.l3done","data":{"sequence":"1556573507700","symbol":"BTC-USDT","reason":"canceled","side":"sell","size":"0.00051068","orderId":"5d62b809c788c64261a594a7","price":"10073.50000000000000000000","time":"1566750748054072087","type":"done"}}
2019/08/25 18:32:30 [Info] received msg: {"id":"","type":"message","sn":"","topic":"/market/level3:BTC-USDT","subject":"trade.l3done","data":{"sequence":"1556573507705","symbol":"BTC-USDT","reason":"canceled","side":"buy","size":"0.1109","orderId":"5d62b8140bad4556c8091919","price":"10060.00000000000000000000","time":"1566750748357931654","type":"done"}}
2019/08/25 18:32:31 [Info] received msg: {"id":"","type":"message","sn":"","topic":"/market/level3:BTC-USDT","subject":"trade.l3done","data":{"sequence":"1556573507708","symbol":"BTC-USDT","reason":"canceled","side":"sell","size":"0.00051068","orderId":"5d62b81c5137b940c51e5719","price":"10072.70000000000000000000","time":"1566750748677028044","type":"done"}}
2019/08/25 18:32:31 [Info] received msg: {"id":"","type":"message","sn":"","topic":"/market/level3:BTC-USDT","subject":"trade.l3done","data":{"sequence":"1556573507709","symbol":"BTC-USDT","reason":"canceled","side":"buy","size":"0.09174088","orderId":"5d62b81c5137b940c51e5701","price":"10052.60000000000000000000","time":"1566750748677160623","type":"done"}}
2019/08/25 18:32:31 [Info] received msg: {"id":"","type":"message","sn":"","topic":"/market/level3:BTC-USDT","subject":"trade.l3done","data":{"sequence":"1556573507710","symbol":"BTC-USDT","reason":"canceled","side":"sell","size":"0.00095405","orderId":"5d62b7e1054b4671f3c83b82","price":"10072.70000000000000000000","time":"1566750748751153187","type":"done"}}
2019/08/25 18:32:31 [Info] received msg: {"id":"","type":"message","sn":"","topic":"/market/level3:BTC-USDT","subject":"trade.l3done","data":{"sequence":"1556573507714","symbol":"BTC-USDT","reason":"canceled","side":"buy","size":"0.04004655","orderId":"5d62b7e14c06876f06c44e46","price":"10052.50000000000000000000","time":"1566750748814590500","type":"done"}}
2019/08/25 18:32:31 [Info] received msg: {"id":"","type":"message","sn":"","topic":"/market/level3:BTC-USDT","subject":"trade.l3done","data":{"sequence":"1556573507719","symbol":"BTC-USDT","reason":"canceled","side":"sell","size":"0.0467","orderId":"5d62b8184c06876f06c47bba","price":"10097.40000000000000000000","time":"1566750749165426267","type":"done"}}
2019/08/25 18:32:31 [Info] received msg: {"id":"","type":"message","sn":"","topic":"/market/level3:BTC-USDT","subject":"trade.l3done","data":{"sequence":"1556573507720","symbol":"BTC-USDT","reason":"canceled","side":"buy","size":"0.29899239","orderId":"5d62b81b89fc844d237e19db","price":"10033.70000000000000000000","time":"1566750749174950750","type":"done"}}
2019/08/25 18:32:31 [Info] received msg: {"id":"","type":"message","sn":"","topic":"/market/level3:BTC-USDT","subject":"trade.l3done","data":{"sequence":"1556573507723","symbol":"BTC-USDT","reason":"canceled","side":"sell","size":"0.1125","orderId":"5d62b81c0bad4556c8091fd0","price":"10063.10000000000000000000","time":"1566750749226254130","type":"done"}}
2019/08/25 18:32:31 [Info] received msg: {"id":"","type":"message","sn":"","topic":"/market/level3:BTC-USDT","subject":"trade.l3done","data":{"sequence":"1556573507726","symbol":"BTC-USDT","reason":"canceled","side":"buy","size":"0.1252","orderId":"5d62b8180bad4556c8091c6a","price":"10003.10000000000000000000","time":"1566750749258226847","type":"done"}}
2019/08/25 18:32:31 [Info] received msg: {"id":"","type":"message","sn":"","topic":"/market/level3:BTC-USDT","subject":"trade.l3done","data":{"sequence":"1556573507739","symbol":"BTC-USDT","reason":"canceled","side":"buy","size":"0.10013406","orderId":"5d62b81ccdaba42f8cfbf5be","price":"10051.80000000000000000000","time":"1566750749818215617","type":"done"}}
2019/08/25 18:32:31 [Info] received msg: {"id":"","type":"message","sn":"","topic":"/market/level3:BTC-USDT","subject":"trade.l3done","data":{"sequence":"1556573507740","symbol":"BTC-USDT","reason":"canceled","side":"sell","size":"0.00051068","orderId":"5d62b81c5137b940c51e5793","price":"10072.00000000000000000000","time":"1566750749818320705","type":"done"}}
2019/08/25 18:32:32 [Info] received msg: {"id":"","type":"message","sn":"","topic":"/market/level3:BTC-USDT","subject":"trade.l3done","data":{"sequence":"1556573507745","symbol":"BTC-USDT","reason":"canceled","side":"sell","size":"0.025","orderId":"5d62b81d5137b940c51e57e3","price":"10086.30000000000000000000","time":"1566750750161332503","type":"done"}}
2019/08/25 18:32:32 [Info] received msg: {"id":"","type":"message","sn":"","topic":"/market/level3:BTC-USDT","subject":"trade.l3done","data":{"sequence":"1556573507750","symbol":"BTC-USDT","reason":"canceled","side":"sell","size":"0.07965691","orderId":"5d62b813c788c64261a59c56","price":"10063.30000000000000000000","time":"1566750750889081186","type":"done"}}
2019/08/25 18:32:32 [Info] received msg: {"id":"","type":"message","sn":"","topic":"/market/level3:BTC-USDT","subject":"trade.l3done","data":{"sequence":"1556573507751","symbol":"BTC-USDT","reason":"canceled","side":"sell","size":"0.09518096","orderId":"5d62b81a054b4671f3c86a06","price":"10062.80000000000000000000","time":"1566750750889183071","type":"done"}}
2019/08/25 18:32:32 [Info] received msg: {"id":"","type":"message","sn":"","topic":"/market/level3:BTC-USDT","subject":"trade.l3done","data":{"sequence":"1556573507754","symbol":"BTC-USDT","reason":"canceled","side":"sell","size":"0.00362789","orderId":"5d62b815cdaba42f8cfbf02f","price":"10063.00000000000000000000","time":"1566750751135515628","type":"done"}}
2019/08/25 18:32:32 [Info] received msg: {"id":"","type":"message","sn":"","topic":"/market/level3:BTC-USDT","subject":"trade.l3done","data":{"sequence":"1556573507758","symbol":"BTC-USDT","reason":"canceled","side":"sell","size":"0.025","orderId":"5d62b81e4c06876f06c48085","price":"10086.30000000000000000000","time":"1566750751227420421","type":"done"}}
2019/08/25 18:32:32 [Info] received msg: {"id":"","type":"message","sn":"","topic":"/market/level3:BTC-USDT","subject":"trade.l3done","data":{"sequence":"1556573507759","symbol":"BTC-USDT","reason":"canceled","side":"sell","size":"0.1125","orderId":"5d62b81ec788c64261a5a57c","price":"10063.00000000000000000000","time":"1566750751313945670","type":"done"}}
2019/08/25 18:32:32 [Info] received msg: {"id":"","type":"message","sn":"","topic":"/market/level3:BTC-USDT","subject":"trade.l3done","data":{"sequence":"1556573507760","symbol":"BTC-USDT","reason":"canceled","side":"buy","size":"0.49746285","orderId":"5d62b81d89fc844d237e1b41","price":"10050.80000000000000000000","time":"1566750751324607061","type":"done"}}
2019/08/25 18:32:32 [Info] received msg: {"id":"","type":"message","sn":"","topic":"/market/level3:BTC-USDT","subject":"trade.l3done","data":{"sequence":"1556573507761","symbol":"BTC-USDT","reason":"canceled","side":"sell","size":"0.50000997","orderId":"5d62b81d0bad4556c80920b4","price":"10066.90000000000000000000","time":"1566750751324690041","type":"done"}}
2019/08/25 18:32:32 [Info] received msg: {"id":"","type":"message","sn":"","topic":"/market/level3:BTC-USDT","subject":"trade.l3done","data":{"sequence":"1556573507762","symbol":"BTC-USDT","reason":"canceled","side":"buy","size":"0.1109","orderId":"5d62b81d054b4671f3c86bff","price":"10059.10000000000000000000","time":"1566750751324716111","type":"done"}}
2019/08/25 18:32:32 [Info] received msg: {"id":"","type":"message","sn":"","topic":"/market/level3:BTC-USDT","subject":"trade.l3done","data":{"sequence":"1556573507765","symbol":"BTC-USDT","reason":"canceled","side":"buy","size":"0.03","orderId":"5d62b7d1c788c64261a564e3","price":"9967.10000000000000000000","time":"1566750751625705273","type":"done"}}
2019/08/25 18:32:32 [Info] received msg: {"id":"","type":"message","sn":"","topic":"/market/level3:BTC-USDT","subject":"trade.l3done","data":{"sequence":"1556573507775","symbol":"BTC-USDT","reason":"canceled","side":"buy","size":"0.029","orderId":"5d62b81bcdaba42f8cfbf456","price":"10045.00000000000000000000","time":"1566750752047495731","type":"done"}}
2019/08/25 18:32:32 [Info] received msg: {"id":"","type":"message","sn":"","topic":"/market/level3:BTC-USDT","subject":"trade.l3done","data":{"sequence":"1556573507780","symbol":"BTC-USDT","reason":"canceled","side":"sell","size":"0.0467","orderId":"5d62b81d5137b940c51e57d1","price":"10097.30000000000000000000","time":"1566750752359473642","type":"done"}}
2019/08/25 18:32:32 [Info] received msg: {"id":"","type":"message","sn":"","topic":"/market/level3:BTC-USDT","subject":"trade.l3done","data":{"sequence":"1556573507783","symbol":"BTC-USDT","reason":"canceled","side":"buy","size":"0.1252","orderId":"5d62b81dc788c64261a5a46f","price":"10003.30000000000000000000","time":"1566750752527239404","type":"done"}}
2019/08/25 18:32:32 [Info] received msg: {"id":"","type":"message","sn":"","topic":"/market/level3:BTC-USDT","subject":"trade.l3done","data":{"sequence":"1556573507787","symbol":"BTC-USDT","reason":"canceled","side":"buy","orderId":"5d62b820c788c64261a5a745","time":"1566750752579974015","type":"done"}}
2019/08/25 18:32:32 [Info] received msg: {"id":"","type":"message","sn":"","topic":"/market/level3:BTC-USDT","subject":"trade.l3done","data":{"sequence":"1556573507788","symbol":"BTC-USDT","reason":"canceled","side":"sell","size":"0.03","orderId":"5d62b7d10bad4556c808dfeb","price":"10150.60000000000000000000","time":"1566750752752221123","type":"done"}}
2019/08/25 18:32:33 [Info] received msg: {"id":"","type":"message","sn":"","topic":"/market/level3:BTC-USDT","subject":"trade.l3done","data":{"sequence":"1556573507790","symbol":"BTC-USDT","reason":"canceled","side":"buy","orderId":"5d62b820054b4671f3c86f76","time":"1566750752958917869","type":"done"}}
2019/08/25 18:32:33 [Info] received msg: {"id":"","type":"message","sn":"","topic":"/market/level3:BTC-USDT","subject":"trade.l3done","data":{"sequence":"1556573507793","symbol":"BTC-USDT","reason":"canceled","side":"buy","size":"0.29897451","orderId":"5d62b81f4c06876f06c481af","price":"10034.30000000000000000000","time":"1566750753092300804","type":"done"}}
2019/08/25 18:32:33 [Info] received msg: {"id":"","type":"message","sn":"","topic":"/market/level3:BTC-USDT","subject":"trade.l3done","data":{"sequence":"1556573507794","symbol":"BTC-USDT","reason":"canceled","side":"buy","size":"0.029","orderId":"5d62b82089fc844d237e1daf","price":"10046.10000000000000000000","time":"1566750753102821472","type":"done"}}
2019/08/25 18:32:33 [Info] received msg: {"id":"","type":"message","sn":"","topic":"/market/level3:BTC-USDT","subject":"trade.l3done","data":{"sequence":"1556573507795","symbol":"BTC-USDT","reason":"canceled","side":"sell","size":"0.1125","orderId":"5d62b820054b4671f3c86eb3","price":"10063.80000000000000000000","time":"1566750753223720401","type":"done"}}
2019/08/25 18:32:33 [Info] received msg: {"id":"","type":"message","sn":"","topic":"/market/level3:BTC-USDT","subject":"trade.l3done","data":{"sequence":"1556573507796","symbol":"BTC-USDT","reason":"canceled","side":"sell","size":"0.00095405","orderId":"5d62b81dcdaba42f8cfbf5fd","price":"10068.90000000000000000000","time":"1566750753634412381","type":"done"}}
2019/08/25 18:32:33 [Info] received msg: {"id":"","type":"message","sn":"","topic":"/market/level3:BTC-USDT","subject":"trade.l3done","data":{"sequence":"1556573507797","symbol":"BTC-USDT","reason":"canceled","side":"buy","size":"0.14830851","orderId":"5d62b81d054b4671f3c86c2f","price":"10048.80000000000000000000","time":"1566750753708941082","type":"done"}}
2019/08/25 18:32:33 [Info] received msg: {"id":"","type":"message","sn":"","topic":"/market/level3:BTC-USDT","subject":"trade.l3done","data":{"sequence":"1556573507800","symbol":"BTC-USDT","reason":"canceled","side":"buy","size":"0.029","orderId":"5d62b820c788c64261a5a7ae","price":"10048.70000000000000000000","time":"1566750753775446470","type":"done"}}
2019/08/25 18:32:34 [Info] received msg: {"id":"","type":"message","sn":"","topic":"/market/level3:BTC-USDT","subject":"trade.l3done","data":{"sequence":"1556573507805","symbol":"BTC-USDT","reason":"canceled","side":"sell","size":"0.30908586","orderId":"5d62b7e80bad4556c808f593","price":"10063.90000000000000000000","time":"1566750754183131502","type":"done"}}
2019/08/25 18:32:34 [Info] received msg: {"id":"","type":"message","sn":"","topic":"/market/level3:BTC-USDT","subject":"trade.l3done","data":{"sequence":"1556573507806","symbol":"BTC-USDT","reason":"canceled","side":"buy","size":"0.40079","orderId":"5d62b7e8c788c64261a57a75","price":"10053.80000000000000000000","time":"1566750754183225889","type":"done"}}
2019/08/25 18:32:35 [Info] received msg: {"id":"","type":"message","sn":"","topic":"/market/level3:BTC-USDT","subject":"trade.l3done","data":{"sequence":"1556573507819","symbol":"BTC-USDT","reason":"canceled","side":"sell","size":"0.10682853","orderId":"5d62b813054b4671f3c86414","price":"10067.90000000000000000000","time":"1566750754759434563","type":"done"}}
2019/08/25 18:32:35 [Info] received msg: {"id":"","type":"message","sn":"","topic":"/market/level3:BTC-USDT","subject":"trade.l3done","data":{"sequence":"1556573507820","symbol":"BTC-USDT","reason":"canceled","side":"buy","size":"0.04131958","orderId":"5d62b81389fc844d237e137a","price":"10051.80000000000000000000","time":"1566750754993231103","type":"done"}}
2019/08/25 18:32:35 [Info] received msg: {"id":"","type":"message","sn":"","topic":"/market/level3:BTC-USDT","subject":"trade.l3done","data":{"sequence":"1556573507823","symbol":"BTC-USDT","reason":"canceled","side":"buy","size":"0.1109","orderId":"5d62b8225137b940c51e5c23","price":"10061.10000000000000000000","time":"1566750755194836377","type":"done"}}
2019/08/25 18:32:36 [Info] received msg: {"id":"","type":"message","sn":"","topic":"/market/level3:BTC-USDT","subject":"trade.l3done","data":{"sequence":"1556573507832","symbol":"BTC-USDT","reason":"canceled","side":"sell","size":"0.50000997","orderId":"5d62b8225137b940c51e5c2d","price":"10071.20000000000000000000","time":"1566750756002854107","type":"done"}}
2019/08/25 18:32:36 [Info] received msg: {"id":"","type":"message","sn":"","topic":"/market/level3:BTC-USDT","subject":"trade.l3done","data":{"sequence":"1556573507833","symbol":"BTC-USDT","reason":"canceled","side":"buy","size":"0.49725011","orderId":"5d62b8220bad4556c8092451","price":"10055.10000000000000000000","time":"1566750756014666270","type":"done"}}
2019/08/25 18:32:36 [Info] received msg: {"id":"","type":"message","sn":"","topic":"/market/level3:BTC-USDT","subject":"trade.l3done","data":{"sequence":"1556573507836","symbol":"BTC-USDT","reason":"canceled","side":"buy","size":"0.1252","orderId":"5d62b82089fc844d237e1e22","price":"10003.40000000000000000000","time":"1566750756380702480","type":"done"}}
2019/08/25 18:32:36 [Info] received msg: {"id":"","type":"message","sn":"","topic":"/market/level3:BTC-USDT","subject":"trade.l3done","data":{"sequence":"1556573507837","symbol":"BTC-USDT","reason":"canceled","side":"buy","size":"0.00004001","orderId":"5d62b81489fc844d237e1484","price":"10055.10000000000000000000","time":"1566750756494950892","type":"done"}}
2019/08/25 18:32:36 [Info] received msg: {"id":"","type":"message","sn":"","topic":"/market/level3:BTC-USDT","subject":"trade.l3done","data":{"sequence":"1556573507840","symbol":"BTC-USDT","reason":"canceled","side":"sell","size":"0.0467","orderId":"5d62b820054b4671f3c86edf","price":"10097.10000000000000000000","time":"1566750756570730227","type":"done"}}
2019/08/25 18:32:36 [Info] received msg: {"id":"","type":"message","sn":"","topic":"/market/level3:BTC-USDT","subject":"trade.l3done","data":{"sequence":"1556573507845","symbol":"BTC-USDT","reason":"canceled","side":"buy","size":"0.029","orderId":"5d62b8210bad4556c8092404","price":"10048.80000000000000000000","time":"1566750756611198134","type":"done"}}
2019/08/25 18:32:37 [Info] received msg: {"id":"","type":"message","sn":"","topic":"/market/level3:BTC-USDT","subject":"trade.l3done","data":{"sequence":"1556573507850","symbol":"BTC-USDT","reason":"canceled","side":"buy","size":"0.29883454","orderId":"5d62b8235137b940c51e5d08","price":"10039.00000000000000000000","time":"1566750757014892721","type":"done"}}
2019/08/25 18:32:37 [Info] received msg: {"id":"","type":"message","sn":"","topic":"/market/level3:BTC-USDT","subject":"trade.l3done","data":{"sequence":"1556573507851","symbol":"BTC-USDT","reason":"canceled","side":"buy","size":"0.1109","orderId":"5d62b82489fc844d237e216a","price":"10061.60000000000000000000","time":"1566750757138503583","type":"done"}}
2019/08/25 18:32:37 [Info] received msg: {"id":"","type":"message","sn":"","topic":"/market/level3:BTC-USDT","subject":"trade.l3done","data":{"sequence":"1556573507852","symbol":"BTC-USDT","reason":"canceled","side":"sell","size":"0.60966","orderId":"5d62b6c95137b940c51d309b","price":"10116.30000000000000000000","time":"1566750757519861952","type":"done"}}
2019/08/25 18:32:38 [Info] received msg: {"id":"","type":"message","sn":"","topic":"/market/level3:BTC-USDT","subject":"trade.l3done","data":{"sequence":"1556573507859","symbol":"BTC-USDT","reason":"canceled","side":"sell","size":"0.1125","orderId":"5d62b8224c06876f06c48463","price":"10066.70000000000000000000","time":"1566750758220308609","type":"done"}}
2019/08/25 18:32:39 [Info] received msg: {"id":"","type":"message","sn":"","topic":"/market/level3:BTC-USDT","subject":"trade.l3done","data":{"sequence":"1556573507860","symbol":"BTC-USDT","reason":"canceled","side":"buy","size":"0.22235035","orderId":"5d62b7ec5137b940c51e3046","price":"10043.60000000000000000000","time":"1566750759044506529","type":"done"}}
2019/08/25 18:32:39 [Info] received msg: {"id":"","type":"message","sn":"","topic":"/market/level3:BTC-USDT","subject":"trade.l3done","data":{"sequence":"1556573507861","symbol":"BTC-USDT","reason":"canceled","side":"sell","size":"0.47602439","orderId":"5d62b7ec4c06876f06c456f8","price":"10089.10000000000000000000","time":"1566750759065117450","type":"done"}}
2019/08/25 18:32:39 [Info] received msg: {"id":"","type":"message","sn":"","topic":"/market/level3:BTC-USDT","subject":"trade.l3done","data":{"sequence":"1556573507867","symbol":"BTC-USDT","reason":"canceled","side":"sell","size":"0.08445536","orderId":"5d62b824c788c64261a5aabf","price":"10066.00000000000000000000","time":"1566750759287493064","type":"done"}}
2019/08/25 18:32:39 [Info] received msg: {"id":"","type":"message","sn":"","topic":"/market/level3:BTC-USDT","subject":"trade.l3done","data":{"sequence":"1556573507872","symbol":"BTC-USDT","reason":"canceled","side":"buy","size":"0.49722538","orderId":"5d62b8250bad4556c8092729","price":"10055.60000000000000000000","time":"1566750759632491652","type":"done"}}
2019/08/25 18:32:39 [Info] received msg: {"id":"","type":"message","sn":"","topic":"/market/level3:BTC-USDT","subject":"trade.l3done","data":{"sequence":"1556573507873","symbol":"BTC-USDT","reason":"canceled","side":"sell","size":"0.50000997","orderId":"5d62b825cdaba42f8cfbfce4","price":"10071.70000000000000000000","time":"1566750759643293836","type":"done"}}
2019/09/15 14:03:01 [Info] received msg: {"id":"","type":"message","sn":"","topic":"/market/level3:BTC-USDT","subject":"trade.l3done","data":{"sequence":"1568195936286","symbol":"BTC-USDT","reason":"canceled","side":"sell","size":"0.126215","orderId":"5d7e287489fc841fb854e4a5","price":"10299.90000000000000000000","time":"1568548981098902212","type":"done"}}
2019/09/15 14:03:01 [Info] received msg: {"id":"","type":"message","sn":"","topic":"/market/level3:BTC-USDT","subject":"trade.l3done","data":{"sequence":"1568195936287","symbol":"BTC-USDT","reason":"canceled","side":"sell","size":"0.126232","orderId":"5d7e28744c06871bb99ca44e","price":"10298.50000000000000000000","time":"1568548981109542073","type":"done"}}
2019/09/15 14:03:01 [Info] received msg: {"id":"","type":"message","sn":"","topic":"/market/level3:BTC-USDT","subject":"trade.l3done","data":{"sequence":"1568195936292","symbol":"BTC-USDT","reason":"canceled","side":"buy","size":"0.04700000","orderId":"5d7e286dcdaba4537ecf71ef","price":"10293.10000000000000000000","time":"1568548981451180840","type":"done"}}
2019/09/15 14:03:01 [Info] received msg: {"id":"","type":"message","sn":"","topic":"/market/level3:BTC-USDT","subject":"trade.l3done","data":{"sequence":"1568195936294","symbol":"BTC-USDT","reason":"canceled","side":"sell","orderId":"5d7e2875c788c65e51a4868d","time":"1568548981492568721","type":"done"}}
2019/09/15 14:03:02 [Info] received msg: {"id":"","type":"message","sn":"","topic":"/market/level3:BTC-USDT","subject":"trade.l3done","data":{"sequence":"1568195936299","symbol":"BTC-USDT","reason":"canceled","side":"sell","size":"0.02092447","orderId":"5d7e2873054b463451bb3ff4","price":"10301.40000000000000000000","time":"1568548982361495774","type":"done"}}
2019/09/15 14:03:03 [Info] received msg: {"id":"","type":"message","sn":"","topic":"/market/level3:BTC-USDT","subject":"trade.l3done","data":{"sequence":"1568195936301","symbol":"BTC-USDT","reason":"canceled","side":"sell","orderId":"5d7e28764c06871bb99ca626","time":"1568548982837626364","type":"done"}}
2019/09/15 14:03:03 [Info] received msg: {"id":"","type":"message","sn":"","topic":"/market/level3:BTC-USDT","subject":"trade.l3done","data":{"sequence":"1568195936304","symbol":"BTC-USDT","reason":"canceled","side":"sell","orderId":"5d7e28765137b97a21658eb1","time":"1568548982910501769","type":"done"}}
2019/09/15 14:03:03 [Info] received msg: {"id":"","type":"message","sn":"","topic":"/market/level3:BTC-USDT","subject":"trade.l3done","data":{"sequence":"1568195936309","symbol":"BTC-USDT","reason":"canceled","side":"buy","size":"0.04700000","orderId":"5d7e28750bad454644a70b1a","price":"10294.10000000000000000000","time":"1568548983065247763","type":"done"}}
2019/09/15 14:03:03 [Info] received msg: {"id":"","type":"message","sn":"","topic":"/market/level3:BTC-USDT","subject":"trade.l3done","data":{"sequence":"1568195936313","symbol":"BTC-USDT","reason":"canceled","side":"sell","orderId":"5d7e28775137b97a21658eef","time":"1568548983201166701","type":"done"}}
2019/09/15 14:03:03 [Info] received msg: {"id":"","type":"message","sn":"","topic":"/market/level3:BTC-USDT","subject":"trade.l3done","data":{"sequence":"1568195936314","symbol":"BTC-USDT","reason":"canceled","side":"sell","size":"0.02092447","orderId":"5d7e2875cdaba4537ecf776c","price":"10301.20000000000000000000","time":"1568548983232077833","type":"done"}}
